Workbook

Sheet List of Township
B1: List of Township
A2: 1 | B2: =' Insein'!A1 -> Yangon Region,North District, Insein Township
A3: 2 | B3: ='Mingaladon '!A1 -> Yangon Region,North District, Mingaladon Township
A4: 3 | B4: ='Hmawby '!A1 -> Yangon Region,North District, Hmawby Township
A5: 4 | B5: ='Hlegu '!A1 -> Yangon Region,North District, Hlegu Township
A6: 5 | B6: ='Taikkyi '!A1 -> Yangon Region,North District, Taikkyi Township
A7: 6 | B7: ='Htantabin '!A1 -> Yangon Region,North District, Htantabin Township
A8: 7 | B8: ='Shwepyitha '!A1 -> Yangon Region,North District, Shwepyitha Township
A9: 8 | B9: =Hlinethaya!A1 -> Yangon Region,North District, Hlinethaya Township
A10: 9 | B10: =Thingangyun!A1 -> Yangon Region,East District, Thingangyun Township
A11: 10 | B11: =' Yankin'!A1 -> Yangon Region,East District,Yankin Township
A12: 11 | B12: =' South Okkalapa'!A1 -> Yangon Region,East District,South Okkalapa Township
A13: 12 | B13: =' North Okkalapa'!A1 -> Yangon Region,East District,North Okkalapa Township
A14: 13 | B14: =Thakayta!A1 -> Yangon Region,East District,Thakayta Township
A15: 14 | B15: =Dawbon!A1 -> Yangon Region,East District,Dawbon Township
A16: 15 | B16: =Tamwe!A1 -> Yangon Region,East District,Tamwe Township
A17: 16 | B17: =Pazuntaung!A1 -> Yangon Region,East District,Pazuntaung Township
A18: 17 | B18: =Botahtaung!A1 -> Yangon Region,East District,Botahtaung Township
A19: 18 | B19: ='Dagon Myothit(South)'!A1 -> Yangon Region,East District, Dagon Myothit(South) Township
A20: 19 | B20: =' Dagon Myothit(North)'!A1 -> Yangon Region,East District, Dagon Myothit(Norht) Township
A21: 20 | B21: ='Dagon Myothit(East)'!A1 -> Yangon Region,East District, Dagon Myothit(East) Township
A22: 21 | B22: ='Dagon Myothit(Seikkan) '!A1 -> Yangon Region, East District, Dagon Myothit(Seikkan)Township
A23: 22 | B23: ='Mingala Taungnyunt '!A1 -> Yangon Region, East District, Mingala Taungnyunt Township
A24: 23 | B24: ='Thanlyin '!A1 -> Yangon Region, South District, Thanlyin Township
A25: 24 | B25: ='Kyauktan '!A1 -> Yangon Region, South District, Kyauktan Township
A26: 25 | B26: ='Thongwa '!A1 -> Yangon Region, South District, Thongwa Township
A27: 26 | B27: ='Khayan '!A1 -> Yangon Region, South District, Khayan Township
A28: 27 | B28: =Twantay!A1 -> Yangon Region, South District, Twantay Township
A29: 28 | B29: ='Kawhmu '!A1 -> Yangon Region, South District, Kawhmu Township
A30: 29 | B30: ='Kungyangon '!A1 -> Yangon Region, South District, Kungyangon Township
A31: 30 | B31: ='Dala '!A1 -> Yangon Region, South District, Dala Township
A32: 31 | B32: ='Seikkyi- Khanaungto '!A1 -> Yangon Region, South District, Seikkyi/ Khanaungto Township
A33: 32 | B33: ='Cocogyun '!A1 -> Yangon Region, South District, Cocogyun Township
A34: 33 | B34: ='Tada (Sub- Tsp)'!A1 -> Yangon Region, South District, Tada (Sub- Township)
A35: 34 | B35: ='Kyauktada '!A1 -> Yangon Region, West District, KyauktadaTownship
A36: 35 | B36: ='Pabedan '!A1 -> Yangon Region, West District, Pabedan Township
A37: 36 | B37: ='Lanmadaw '!A1 -> Yangon Region, West District, LanmadawTownship
A38: 37 | B38: ='Latha '!A1 -> Yangon Region, West District, Latha Township
A39: 38 | B39: ='Ahlon '!A1 -> Yangon Region, West District, Ahlon Township
A40: 39 | B40: ='Kyimyindine '!A1 -> Yangon Region, West District, Kyimyindine Township
...

Sheet  Insein
A1: Yangon Region,North District, Insein Township
E2: 29-3-2014
A3: Sr | B3: Ward/Village Tract | C3: Population
C4: Total | D4: Male | E4: Female
B5: Total | C5: 305283 | D5: 146158 | E5: 159125
B7: Ward | C7: =SUM(C8:C28) -> 305283 | D7: =SUM(D8:D28) -> 146158 | E7: =SUM(E8:E28) -> 159125
A8: 1 | B8: Kan Nar (West)(W) | C8: 9476 | D8: 4582 | E8: 4894
A9: 2 | B9: Kan Nar (Middle)(W) | C9: 15390 | D9: 7320 | E9: 8070
A10: 3 | B10: Kwet Thit(W) | C10: 2449 | D10: 1131 | E10: 1318
A11: 4 | B11: Pauk Taw(W) | C11: 4876 | D11: 2141 | E11: 2735
A12: 5 | B12: Zay Kone (West)(W) | C12: 2101 | D12: 981 | E12: 1120
A13: 6 | B13: Zay Kone (East)(W) | C13: 9327 | D13: 4571 | E13: 4756
A14: 7 | B14: Pein Hne Kone(W) | C14: 8233 | D14: 3702 | E14: 4531
A15: 8 | B15: Myo Thit ((Ka)/Kha)(W) | C15: 18491 | D15: 8788 | E15: 9703
A16: 9 | B16: Myo Thit (Ga)(W) | C16: 7869 | D16: 3804 | E16: 4065
A17: 10 | B17: Kyo Kone (West)(W) | C17: 12256 | D17: 5872 | E17: 6384
A18: 11 | B18: Kyo Kone (East)(W) | C18: 16270 | D18: 7774 | E18: 8496
A19: 12 | B19: Saw Bwar Gyi Kone(W) | C19: 20811 | D19: 10042 | E19: 10769
... A28: 21 | B28: Da Nyin Kone/Ta Nyin Kone (W) | C28: 22688 | D28: 11129 | E28: 11559

Sheet Mingaladon 
A1: Yangon Region,North District, Mingaladon Township
E2: 29-3-2014
A3: Sr | B3: Ward/Village Tract | C3: Population
C4: Total | D4: Male | E4: Female
B5: Total | C5: =C7+C35 -> 331586 | D5: =D7+D35 -> 158259 | E5: =E7+E35 -> 173327
B7: Ward | C7: =SUM(C8:C34) -> 198396 | D7: =SUM(D8:D34) -> 95814 | E7: =SUM(E8:E34) -> 102582
A8: 1 | B8: Htauk Kyant (Taung Paing)(W) | C8: 3562 | D8: 1671 | E8: 1891
A9: 2 | B9: Htauk Kyant (Myauk Paing)(W) | C9: 7935 | D9: 3816 | E9: 4119
A10: 3 | B10: Pa-San Pya(W) | C10: 567 | D10: 237 | E10: 330
A11: 4 | B11: Du-San Pya(W) | C11: 2173 | D11: 959 | E11: 1214
A12: 5 | B12: Ye Su (South)(W) | C12: 8537 | D12: 4006 | E12: 4531
A13: 6 | B13: Baw Lone Kwin(W) | C13: 1711 | D13: 782 | E13: 929
A14: 7 | B14: Aye Ka Rit(W) | C14: 2468 | D14: 1208 | E14: 1260
A15: 8 | B15: Bago Lan(W) | C15: 1379 | D15: 676 | E15: 703
A16: 9 | B16: Ti Law Kar Yon(W) | C16: 3243 | D16: 1481 | E16: 1762
A17: 10 | B17: Lan Son Paing(W) | C17: 562 | D17: 226 | E17: 336
A18: 11 | B18: Zay Paing(W) | C18: 1037 | D18: 496 | E18: 541
A19: 12 | B19: Ywar Ma Paing(W) | C19: 6071 | D19: 2873 | E19: 3198
... A34: 27 | B34: Taw Taik(W) | C34: 5465 | D34: 2515 | E34: 2950
B35: Village Tract | C35: =SUM(C36:C40) -> 133190 | D35: =SUM(D36:D40) -> 62445 | E35: =SUM(E36:E40) -> 70745
A36: 1 | B36: Nwe Khway(VT) | C36: 14159 | D36: 6805 | E36: 7354
A37: 2 | B37: Kone Ta La Paung(VT) | C37: 22667 | D37: 9977 | E37: 12690
A38: 3 | B38: Shwe Nant Thar(VT) | C38: 39989 | D38: 19371 | E38: 20618
A39: 4 | B39: Pyin Ma Pin(VT) | C39: 14025 | D39: 7042 | E39: 6983
A40: 5 | B40: Thin Gan Kyun Gyi(VT) | C40: 42350 | D40: 19250 | E40: 23100

Sheet Hmawby 
A1: Yangon Region,North District, Hmawby Township
E2: 29-3-2014
A3: Sr | B3: Ward/Village Tract | C3: Population
C4: Total | D4: Male | E4: Female
B5: Total | C5: =C7+C13 -> 244607 | D5: =D7+D13 -> 120931 | E5: =E7+E13 -> 123676
B7: Ward | C7: =SUM(C8:C11) -> 25960 | D7: =SUM(D8:D11) -> 12285 | E7: =SUM(E8:E11) -> 13675
A8: 1 | B8: No(1)(W) | C8: 5107 | D8: 2469 | E8: 2638
A9: 2 | B9: No(2)(W) | C9: 8782 | D9: 4142 | E9: 4640
A10: 3 | B10: No(3)(W) | C10: 2588 | D10: 1199 | E10: 1389
A11: 4 | B11: No(4)(W) | C11: 9483 | D11: 4475 | E11: 5008
B13: Village Tract | C13: =SUM(C14:C52) -> 218647 | D13: =SUM(D14:D52) -> 108646 | E13: =SUM(E14:E52) -> 110001
A14: 1 | B14: Tat Gyi Kone(VT) | C14: 14265 | D14: 6802 | E14: 7463
A15: 2 | B15: Hla Pa Dar(VT) | C15: 5032 | D15: 2468 | E15: 2564
A16: 3 | B16: Min(VT) | C16: 4495 | D16: 2259 | E16: 2236
A17: 4 | B17: Pet Tan(VT) | C17: 3165 | D17: 1579 | E17: 1586
A18: 5 | B18: Shwe Hlay Gyi(VT) | C18: 1426 | D18: 701 | E18: 725
A19: 6 | B19: Pa Thi(VT) | C19: 1498 | D19: 715 | E19: 783
A20: 7 | B20: Chaung Wa(VT) | C20: 1353 | D20: 686 | E20: 667
A21: 8 | B21: Hmaw Bi Chaung Wa(VT) | C21: 3429 | D21: 1661 | E21: 1768
A22: 9 | B22: Hnaw Kone(VT) | C22: 4107 | D22: 1968 | E22: 2139
A23: 10 | B23: Bant Bway Kone(VT) | C23: 4685 | D23: 2257 | E23: 2428
A24: 11 | B24: Hle Ngoke Chaung(VT) | C24: 8297 | D24: 4028 | E24: 4269
A25: 12 | B25: Hpu Gyi(VT) | C25: 8544 | D25: 4374 | E25: 4170
... A52: 39 | B52: Sat Thwar Taw(VT) | C52: 21094 | D52: 10280 | E52: 10814

Sheet Hlegu 
A1: Yangon Region,North District, Hlegu Township
E2: 29-3-2014
A3: Sr | B3: Ward/Village Tract | C3: Population
C4: Total | D4: Male | E4: Female
B5: Total | C5: =C7+C14 -> 270741 | D5: =D7+D14 -> 134087 | E5: =E7+E14 -> 136654
B7: Ward | C7: =SUM(C8:C12) -> 40078 | D7: =SUM(D8:D12) -> 18906 | E7: =SUM(E8:E12) -> 21172
A8: 1 | B8: Aung Min Ga Lar(W) | C8: 10486 | D8: 4926 | E8: 5560
A9: 2 | B9: Pyi Taw Thar(W) | C9: 8311 | D9: 3969 | E9: 4342
A10: 3 | B10: Thar Tha Na Yeik Thar(W) | C10: 12614 | D10: 6007 | E10: 6607
A11: 4 | B11: Zay Paing(W) | C11: 1269 | D11: 560 | E11: 709
A12: 5 | B12: Myo Ma(W) | C12: 7398 | D12: 3444 | E12: 3954
B14: Village Tract | C14: =SUM(C15:C66) -> 230663 | D14: =SUM(D15:D66) -> 115181 | E14: =SUM(E15:E66) -> 115482
A15: 1 | B15: Hpaung Gyi (East)(VT) | C15: 13129 | D15: 6516 | E15: 6613
A16: 2 | B16: Hpaung Gyi (West)(VT) | C16: 7216 | D16: 3546 | E16: 3670
A17: 3 | B17: Poke Thin Nyo(VT) | C17: 2660 | D17: 1422 | E17: 1238
A18: 4 | B18: Gway Tauk Aing(VT) | C18: 4814 | D18: 2532 | E18: 2282
A19: 5 | B19: Kyun Ka Lay(VT) | C19: 9411 | D19: 4571 | E19: 4840
A20: 6 | B20: Thar Yar Kone(VT) | C20: 4777 | D20: 2353 | E20: 2424
A21: 7 | B21: Kyar Inn (West)(VT) | C21: 11402 | D21: 5807 | E21: 5595
A22: 8 | B22: Kyauk Ka Din(VT) | C22: 3102 | D22: 1605 | E22: 1497
A23: 9 | B23: Ka Li Htaw (West)(VT) | C23: 2493 | D23: 1255 | E23: 1238
A24: 10 | B24: Ka Li Htaw (East)(VT) | C24: 2725 | D24: 1336 | E24: 1389
A25: 11 | B25: Haing Ku(VT) | C25: 9093 | D25: 4475 | E25: 4618
A26: 12 | B26: Sa Khan Gyi(VT) | C26: 2140 | D26: 1109 | E26: 1031
... A66: 52 | B66: Ngwe Nant Thar(VT) | C66: 1744 | D66: 904 | E66: 840

Sheet Taikkyi 
A1: Yangon Region,North District, Taikkyi Township
E2: 29-3-2014
A3: Sr | B3: Ward/Village Tract | C3: Population
C4: Total | D4: Male | E4: Female
B5: Total | C5: =C7+C29 -> 277268 | D5: =D7+D29 -> 134714 | E5: =E7+E29 -> 142554
B7: Ward | C7: =SUM(C8:C27) -> 88000 | D7: =SUM(D8:D27) -> 42161 | E7: =SUM(E8:E27) -> 45839
A8: 1 | B8: In Ga Lar(Inn ka Lar)(W) | C8: 3514 | D8: 1679 | E8: 1835
A9: 2 | B9: Oe Tan(W) | C9: 8287 | D9: 3942 | E9: 4345
A10: 3 | B10: Zay(W) | C10: 2817 | D10: 1265 | E10: 1552
A11: 4 | B11: Baw Di Kone(W) | C11: 4613 | D11: 2159 | E11: 2454
A12: 5 | B12: Bu Tar(W) | C12: 3445 | D12: 1649 | E12: 1796
A13: 6 | B13: Oke Pon Su(W) | C13: 9764 | D13: 4820 | E13: 4944
A14: 7 | B14: Shan Su(W) | C14: 11022 | D14: 5329 | E14: 5693
A15: 8 | B15: Min Ga Lar(W) | C15: 14392 | D15: 7137 | E15: 7255
A16: 9 | B16: Kyan Sit Thar(W) | C16: 1782 | D16: 848 | E16: 934
A17: 10 | B17: U Aung Zay Ya(W) | C17: 1652 | D17: 759 | E17: 893
A18: 11 | B18: Ah Naw Ra Htar(W) | C18: 3167 | D18: 1467 | E18: 1700
A19: 12 | B19: Ban Du La(W) | C19: 3486 | D19: 1635 | E19: 1851
... A27: 20 | B27: No(4)(W) | C27: 2943 | D27: 1375 | E27: 1568
B29: Village Tract | C29: =SUM(C30:C103) -> 189268 | D29: =SUM(D30:D103) -> 92553 | E29: =SUM(E30:E103) -> 96715
A30: 1 | B30: Tar Gwa(VT) | C30: 6420 | D30: 3199 | E30: 3221
A31: 2 | B31: Lauk Lay Chaung(VT) | C31: 3888 | D31: 1865 | E31: 2023
A32: 3 | B32: Tha Yet Chaung(VT) | C32: 3023 | D32: 1429 | E32: 1594
A33: 4 | B33: Kyaik Sa Kaing(VT) | C33: 1773 | D33: 847 | E33: 926
A34: 5 | B34: Gyoe Hpyu(VT) | C34: 7954 | D34: 3801 | E34: 4153
A35: 6 | B35: Yin Taik Kwin(VT) | C35: 2862 | D35: 1353 | E35: 1509
A36: 7 | B36: U To(VT) | C36: 3884 | D36: 1858 | E36: 2026
A37: 8 | B37: Tha Nat Chaung Bu Tar(VT) | C37: 4188 | D37: 2065 | E37: 2123
A38: 9 | B38: Oke Pon(VT) | C38: 3957 | D38: 1936 | E38: 2021
A39: 10 | B39: Hpa Lon Kan Kone(VT) | C39: 2233 | D39: 1058 | E39: 1175
A40: 11 | B40: Kyar Inn(VT) | C40: 1004 | D40: 477 | E40: 527
A41: 12 | B41: Sin Sa Kan(VT) | C41: 4699 | D41: 2364 | E41: 2335
... A103: 74 | B103: Ohn Pin Kwin(VT) | C103: 2601 | D103: 1266 | E103: 1335

Sheet Htantabin 
A1: Yangon Region,North District, Htantabin Township
E2: 29-3-2014
A3: Sr | B3: Ward/Village Tract | C3: Population
C4: Total | D4: Male | E4: Female
B5: Total | C5: =C7+C14 -> 145792 | D5: =D7+D14 -> 71807 | E5: =E7+E14 -> 73985
B7: Ward | C7: =SUM(C8:C12) -> 9019 | D7: =SUM(D8:D12) -> 4318 | E7: =SUM(E8:E12) -> 4701
A8: 1 | B8: No(1)(W) | C8: 2264 | D8: 1137 | E8: 1127
A9: 2 | B9: No(2)(W) | C9: 1827 | D9: 872 | E9: 955
A10: 3 | B10: No(3)(W) | C10: 3027 | D10: 1408 | E10: 1619
A11: 4 | B11: No(4)(W) | C11: 1335 | D11: 631 | E11: 704
A12: 5 | B12: No(5)(W) | C12: 566 | D12: 270 | E12: 296
B14: Village Tract | C14: =SUM(C15:C68) -> 136773 | D14: =SUM(D15:D68) -> 67489 | E14: =SUM(E15:E68) -> 69284
A15: 1 | B15: Htein Hnit Pin(VT) | C15: 5383 | D15: 2626 | E15: 2757
A16: 2 | B16: Than Pu Yar Khon(VT) | C16: 3050 | D16: 1499 | E16: 1551
A17: 3 | B17: Ka Lein(VT) | C17: 1989 | D17: 960 | E17: 1029
A18: 4 | B18: La Mu Tan Gyi(VT) | C18: 2834 | D18: 1379 | E18: 1455
A19: 5 | B19: Yoe Gwa(VT) | C19: 1017 | D19: 476 | E19: 541
A20: 6 | B20: Yae Paw Thaung(VT) | C20: 506 | D20: 262 | E20: 244
A21: 7 | B21: Yae Twin Kone(VT) | C21: 1664 | D21: 862 | E21: 802
A22: 8 | B22: Tha Bawt Chaung(VT) | C22: 1559 | D22: 771 | E22: 788
A23: 9 | B23: Daunt Gyi(VT) | C23: 1791 | D23: 912 | E23: 879
A24: 10 | B24: Ne Byaw(VT) | C24: 1181 | D24: 606 | E24: 575
A25: 11 | B25: Pet Inn Ka Lay(VT) | C25: 893 | D25: 451 | E25: 442
A26: 12 | B26: Kyar Hone(VT) | C26: 1168 | D26: 623 | E26: 545
... A68: 54 | B68: Ta Dar U(VT) | C68: 1142 | D68: 595 | E68: 547

Sheet Shwepyitha 
A1: Yangon Region,North District, Shwepyitha Township
E2: 29-3-2014
A3: Sr | B3: Ward/Village Tract | C3: Population
C4: Total | D4: Male | E4: Female
B5: Total | C5: =C7+C31 -> 343526 | D5: =D7+D31 -> 164264 | E5: =E7+E31 -> 179262
B7: Ward | C7: =SUM(C8:C30) -> 279795 | D7: =SUM(D8:D30) -> 133915 | E7: =SUM(E8:E30) -> 145880
A8: 1 | B8: No(1)(W) | C8: 20092 | D8: 10086 | E8: 10006
A9: 2 | B9: No(2)(W) | C9: 3683 | D9: 1517 | E9: 2166
A10: 3 | B10: No(3)(W) | C10: 4381 | D10: 2046 | E10: 2335
A11: 4 | B11: No(4)(W) | C11: 1877 | D11: 1095 | E11: 782
A12: 5 | B12: No(5)(W) | C12: 17764 | D12: 8137 | E12: 9627
A13: 6 | B13: No(6)(W) | C13: 18041 | D13: 8482 | E13: 9559
A14: 7 | B14: No(7)(W) | C14: 8153 | D14: 3880 | E14: 4273
A15: 8 | B15: No(8)(W) | C15: 17544 | D15: 8201 | E15: 9343
A16: 9 | B16: No(9)(W) | C16: 18690 | D16: 8997 | E16: 9693
A17: 10 | B17: No(10)(W) | C17: 27053 | D17: 12307 | E17: 14746
A18: 11 | B18: No(11)(W) | C18: 12318 | D18: 5679 | E18: 6639
A19: 12 | B19: No(12)(W) | C19: 8244 | D19: 4030 | E19: 4214
... A30: 23 | B30: No(23)(W) | C30: 5805 | D30: 2978 | E30: 2827
B31: Village Tract | C31: =SUM(C32:C35) -> 63731 | D31: =SUM(D32:D35) -> 30349 | E31: =SUM(E32:E35) -> 33382
A32: 1 | B32: Oke Hpo(VT) | C32: 17812 | D32: 8841 | E32: 8971
A33: 2 | B33: Zee Kone(VT) | C33: 24948 | D33: 10996 | E33: 13952
A34: 3 | B34: Kyaung Kone(VT) | C34: 6809 | D34: 3286 | E34: 3523
A35: 4 | B35: Hlaw Kar(VT) | C35: 14162 | D35: 7226 | E35: 6936

Sheet Hlinethaya
A1: Yangon Region,North District, Hlinethaya Township
E2: 29-3-2014
A3: Sr | B3: Ward/Village Tract | C3: Population
C4: Total | D4: Male | E4: Female
B5: Total | C5: =C7+C28 -> 687867 | D5: =D7+D28 -> 322862 | E5: =E7+E28 -> 365005
B7: Ward | C7: =SUM(C8:C27) -> 482128 | D7: =SUM(D8:D27) -> 223568 | E7: =SUM(E8:E27) -> 258560
A8: 1 | B8: No(1)(W) | C8: 29699 | D8: 13910 | E8: 15789
A9: 2 | B9: No(2)(W) | C9: 16800 | D9: 8028 | E9: 8772
A10: 3 | B10: No(3)(W) | C10: 28790 | D10: 13799 | E10: 14991
A11: 4 | B11: No(4)(W) | C11: 8445 | D11: 3794 | E11: 4651
A12: 5 | B12: No(5)(W) | C12: 48386 | D12: 22283 | E12: 26103
A13: 6 | B13: No(6)(W) | C13: 42319 | D13: 18109 | E13: 24210
A14: 7 | B14: No(7)(W) | C14: 46988 | D14: 21653 | E14: 25335
A15: 8 | B15: No(8)(W) | C15: 9913 | D15: 4644 | E15: 5269
A16: 9 | B16: No(9)(W) | C16: 21171 | D16: 9921 | E16: 11250
A17: 10 | B17: No(10)(W) | C17: 16171 | D17: 7649 | E17: 8522
A18: 11 | B18: No(11)(W) | C18: 23049 | D18: 10759 | E18: 12290
A19: 12 | B19: No(12)(W) | C19: 16733 | D19: 7604 | E19: 9129
... A27: 20 | B27: No(20)(W) | C27: 38728 | D27: 18170 | E27: 20558
B28: Village Tract | C28: =SUM(C29:C37) -> 205739 | D28: =SUM(D29:D37) -> 99294 | E28: =SUM(E29:E37) -> 106445
A29: 1 | B29: Ka Sin(VT) | C29: 13349 | D29: 6539 | E29: 6810
A30: 2 | B30: Shan Chaung(VT) | C30: 15934 | D30: 7895 | E30: 8039
A31: 3 | B31: Nyaung(VT) | C31: 43828 | D31: 21635 | E31: 22193
A32: 4 | B32: Ah Lel(VT) | C32: 23214 | D32: 10939 | E32: 12275
A33: 5 | B33: Oke Kan Thaung Kyar (Yae Oke Kan)(VT) | C33: 42201 | D33: 19100 | E33: 23101
A34: 6 | B34: Ah Pyin Pa Dan(VT) | C34: 10712 | D34: 5340 | E34: 5372
A35: 7 | B35: Ah Twin Pa Dan(VT) | C35: 12972 | D35: 6652 | E35: 6320
A36: 8 | B36: Ku Lar Gyi Su(VT) | C36: 14818 | D36: 7310 | E36: 7508
A37: 9 | B37: Shwe Lin Ban(VT) | C37: 28711 | D37: 13884 | E37: 14827

Sheet Thingangyun
A1: Yangon Region,East District, Thingangyun Township
E2: 29-3-2014
A3: Sr | B3: Ward/Village Tract | C3: Population
C4: Total | D4: Male | E4: Female
B5: Total | C5: =SUM(C8:C45) -> 209486 | D5: =SUM(D8:D45) -> 98698 | E5: =SUM(E8:E45) -> 110788
B7: Ward | C7: =SUM(C8:C45) -> 209486 | D7: =SUM(D8:D45) -> 98698 | E7: =SUM(E8:E45) -> 110788
A8: 1 | B8: Ka Ward(W) | C8: 17715 | D8: 8650 | E8: 9065
A9: 2 | B9: Kha Ward(W) | C9: 7974 | D9: 3974 | E9: 4000
A10: 3 | B10: Ga Ward(W) | C10: 6160 | D10: 2986 | E10: 3174
A11: 4 | B11: Ga Gyi Ward(W) | C11: 6792 | D11: 3247 | E11: 3545
A12: 5 | B12: Nga/Ka Ward(W) | C12: 16700 | D12: 7902 | E12: 8798
A13: 6 | B13: Nga/Kha (W) | C13: 3920 | D13: 1927 | E13: 1993
A14: 7 | B14: Bo Kan Nyunt (W) | C14: 2703 | D14: 1232 | E14: 1471
A15: 8 | B15: Bank Yeik Thar(W) | C15: 751 | D15: 316 | E15: 435
A16: 9 | B16: Yan Aung(W) | C16: 3852 | D16: 1812 | E16: 2040
A17: 10 | B17: U San Hpe(W) | C17: 3997 | D17: 1891 | E17: 2106
A18: 11 | B18: Thut Waing Gyi(W) | C18: 2592 | D18: 1233 | E18: 1359
A19: 12 | B19: Thu Min Ga Lar/Sa-Thu Min Ga Lar(W) | C19: 2400 | D19: 1115 | E19: 1285
... A45: 38 | B45: Sei Thein(W) | C45: 1358 | D45: 607 | E45: 751

Sheet  Yankin
A1: Yangon Region,East District,Yankin Township
E2: 29-3-2014
A3: Sr | B3: Ward/Village Tract | C3: Population
C4: Total | D4: Male | E4: Female
B5: Total | C5: =SUM(C8:C22) -> 70946 | D5: =SUM(D8:D22) -> 32724 | E5: =SUM(E8:E22) -> 38222
B7: Ward | C7: =SUM(C8:C22) -> 70946 | D7: =SUM(D8:D22) -> 32724 | E7: =SUM(E8:E22) -> 38222
A8: 1 | B8: No(1)(W) | C8: 2141 | D8: 988 | E8: 1153
A9: 2 | B9: No(2)(W) | C9: 4642 | D9: 1893 | E9: 2749
A10: 3 | B10: No(3)(W) | C10: 1772 | D10: 749 | E10: 1023
A11: 4 | B11: No(4)(W) | C11: 2035 | D11: 833 | E11: 1202
A12: 5 | B12: No(5)(W) | C12: 5930 | D12: 2466 | E12: 3464
A13: 6 | B13: No(6)(W) | C13: 2354 | D13: 1023 | E13: 1331
A14: 7 | B14: No(7)(W) | C14: 2581 | D14: 1170 | E14: 1411
A15: 8 | B15: No(8)(W) | C15: 6475 | D15: 3003 | E15: 3472
A16: 9 | B16: No(9)(W) | C16: 3564 | D16: 1632 | E16: 1932
A17: 10 | B17: No(11)(W) | C17: 8651 | D17: 4411 | E17: 4240
A18: 11 | B18: No(12)(W) | C18: 10897 | D18: 5039 | E18: 5858
A19: 12 | B19: No(13)(W) | C19: 5707 | D19: 2718 | E19: 2989
... A22: 15 | B22: No(16)(W) | C22: 7082 | D22: 3261 | E22: 3821

Sheet  South Okkalapa
A1: Yangon Region,East District,South Okkalapa Township
E2: 29-3-2014
A3: Sr | B3: Ward/Village Tract | C3: Population
C4: Total | D4: Male | E4: Female
B5: Total | C5: =SUM(C8:C20) -> 161126 | D5: =SUM(D8:D20) -> 75547 | E5: =SUM(E8:E20) -> 85579
B7: Ward | C7: =SUM(C8:C20) -> 161126 | D7: =SUM(D8:D20) -> 75547 | E7: =SUM(E8:E20) -> 85579
A8: 1 | B8: No(3)(W) | C8: 3588 | D8: 1597 | E8: 1991
A9: 2 | B9: No(4)(W) | C9: 17010 | D9: 8064 | E9: 8946
A10: 3 | B10: No(5)(W) | C10: 16883 | D10: 8470 | E10: 8413
A11: 4 | B11: No(6)(W) | C11: 10131 | D11: 4550 | E11: 5581
A12: 5 | B12: No(7)(W) | C12: 17599 | D12: 8133 | E12: 9466
A13: 6 | B13: No(8)(W) | C13: 2255 | D13: 1232 | E13: 1023
A14: 7 | B14: No(9)(W) | C14: 9919 | D14: 4382 | E14: 5537
A15: 8 | B15: No(10)(W) | C15: 13147 | D15: 6006 | E15: 7141
A16: 9 | B16: No(11)(W) | C16: 7242 | D16: 3320 | E16: 3922
A17: 10 | B17: No(12)(W) | C17: 13459 | D17: 6289 | E17: 7170
A18: 11 | B18: No(13)(W) | C18: 17901 | D18: 8178 | E18: 9723
A19: 12 | B19: No(14)(W) | C19: 23516 | D19: 10889 | E19: 12627
A20: 13 | B20: No(15)(W) | C20: 8476 | D20: 4437 | E20: 4039

Sheet  North Okkalapa
A1: Yangon Region,East District,North Okkalapa Township
E2: 29-3-2014
A3: Sr | B3: Ward/Village Tract | C3: Population
C4: Total | D4: Male | E4: Female
B5: Total | C5: =SUM(C8:C26) -> 333293 | D5: =SUM(D8:D26) -> 156340 | E5: =SUM(E8:E26) -> 176953
B7: Ward | C7: =SUM(C8:C26) -> 333293 | D7: =SUM(D8:D26) -> 156340 | E7: =SUM(E8:E26) -> 176953
A8: 1 | B8: No(1)(W) | C8: 11465 | D8: 5337 | E8: 6128
A9: 2 | B9: No(2)(W) | C9: 28571 | D9: 13758 | E9: 14813
A10: 3 | B10: (Ka)(W) | C10: 11248 | D10: 5272 | E10: 5976
A11: 4 | B11: (Kha)(W) | C11: 8329 | D11: 3865 | E11: 4464
A12: 5 | B12: (Ga)(W) | C12: 7139 | D12: 3267 | E12: 3872
A13: 6 | B13: (Ga Gyi)(W) | C13: 9211 | D13: 4279 | E13: 4932
A14: 7 | B14: (Nga)(W) | C14: 20767 | D14: 9931 | E14: 10836
A15: 8 | B15: (Sa)(W) | C15: 9346 | D15: 4446 | E15: 4900
A16: 9 | B16: (Saa)(W) | C16: 13213 | D16: 6080 | E16: 7133
A17: 10 | B17: (Za)(W) | C17: 9650 | D17: 4445 | E17: 5205
A18: 11 | B18: (Za Myin Zwe)(W) | C18: 15039 | D18: 7465 | E18: 7574
A19: 12 | B19: (Nya)(W) | C19: 22347 | D19: 10615 | E19: 11732
... A26: 19 | B26: Shwe Pauk Kan Myo Thit(W) | C26: 66531 | D26: 29749 | E26: 36782

Sheet Thakayta
A1: Yangon Region,East District,Thakayta Township
E2: 29-3-2014
A3: Sr | B3: Ward/Village Tract | C3: Population
C4: Total | D4: Male | E4: Female
B5: Total | C5: =SUM(C8:C26) -> 220556 | D5: =SUM(D8:D26) -> 107290 | E5: =SUM(E8:E26) -> 113266
B7: Ward | C7: =SUM(C8:C26) -> 220556 | D7: =SUM(D8:D26) -> 107290 | E7: =SUM(E8:E26) -> 113266
A8: 1 | B8: Set Hmu Let Hmu(W) | C8: 5751 | D8: 3225 | E8: 2526
A9: 2 | B9: No(1) Ah Naw Mar(W) | C9: 18176 | D9: 8505 | E9: 9671
A10: 3 | B10: No(1) Htu Par Yon(W) | C10: 11887 | D10: 5461 | E10: 6426
A11: 4 | B11: No(2) (South)(W) | C11: 7947 | D11: 3741 | E11: 4206
A12: 5 | B12: No(2) (North)(W) | C12: 13399 | D12: 6449 | E12: 6950
A13: 6 | B13: No(3) Yan Pyay(W) | C13: 14194 | D13: 6695 | E13: 7499
A14: 7 | B14: No(3) Man Pyay(W) | C14: 10247 | D14: 4692 | E14: 5555
A15: 8 | B15: No(4)(South)(W) | C15: 8056 | D15: 3801 | E15: 4255
A16: 9 | B16: No(4)(North)(W) | C16: 6446 | D16: 3001 | E16: 3445
A17: 10 | B17: No(5)(W) | C17: 7183 | D17: 3462 | E17: 3721
A18: 11 | B18: No(6) (East)(W) | C18: 8020 | D18: 3822 | E18: 4198
A19: 12 | B19: No(6) (West)(W) | C19: 9859 | D19: 4758 | E19: 5101
... A26: 19 | B26: Shu Khin Thar(W) | C26: 8112 | D26: 4557 | E26: 3555

Sheet Dawbon
A1: Yangon Region,East District,Dawbon Township
E2: 29-3-2014
A3: Sr | B3: Ward/Village Tract | C3: Population
C4: Total | D4: Male | E4: Female
B5: Total | C5: =SUM(C8:C21) -> 75325 | D5: =SUM(D8:D21) -> 36745 | E5: =SUM(E8:E21) -> 38580
B7: Ward | C7: =SUM(C8:C21) -> 75325 | D7: =SUM(D8:D21) -> 36745 | E7: =SUM(E8:E21) -> 38580
A8: 1 | B8: Nwe Aye(W) | C8: 18257 | D8: 9153 | E8: 9104
A9: 2 | B9: Bamar Aye(W) | C9: 5420 | D9: 2591 | E9: 2829
A10: 3 | B10: Bo Htun Zan(W) | C10: 8621 | D10: 4328 | E10: 4293
A11: 4 | B11: Kyi Su(W) | C11: 5703 | D11: 2761 | E11: 2942
A12: 5 | B12: Say Sat(W) | C12: 3022 | D12: 1488 | E12: 1534
A13: 6 | B13: Myo Thit(W) | C13: 2660 | D13: 1276 | E13: 1384
A14: 7 | B14: Pa Thein Myay(W) | C14: 2099 | D14: 979 | E14: 1120
A15: 8 | B15: War So(W) | C15: 2913 | D15: 1437 | E15: 1476
A16: 9 | B16: Aung Chan Thar(W) | C16: 1548 | D16: 727 | E16: 821
A17: 10 | B17: La Mu Tan(W) | C17: 1609 | D17: 786 | E17: 823
A18: 11 | B18: Ya Mon Nar(2)(W) | C18: 7689 | D18: 3634 | E18: 4055
A19: 12 | B19: Ya Mon Nar(1)(W) | C19: 5186 | D19: 2474 | E19: 2712
... A21: 14 | B21: Thin Baw Kyin(W) | C21: 6905 | D21: 3383 | E21: 3522

Sheet Tamwe
A1: Yangon Region,East District,Tamwe Township
E2: 29-3-2014
A3: Sr | B3: Ward/Village Tract | C3: Population
C4: Total | D4: Male | E4: Female
B5: Total | C5: =SUM(C8:C27) -> 165313 | D5: =SUM(D8:D27) -> 74662 | E5: =SUM(E8:E27) -> 90651
B7: Ward | C7: =SUM(C8:C27) -> 165313 | D7: =SUM(D8:D27) -> 74662 | E7: =SUM(E8:E27) -> 90651
A8: 1 | B8: Ma Au Kone(W) | C8: 12977 | D8: 5949 | E8: 7028
A9: 2 | B9: Pon Nar Kone(W) | C9: 4164 | D9: 2004 | E9: 2160
A10: 3 | B10: Ah Yoe Kone(W) | C10: 8504 | D10: 3831 | E10: 4673
A11: 4 | B11: Pyar Yay Kone(W) | C11: 2861 | D11: 1238 | E11: 1623
A12: 5 | B12: Nat Mauk(W) | C12: 3818 | D12: 1946 | E12: 1872
A13: 6 | B13: Bo Lein Aung Min Ga Lar(W) | C13: 4970 | D13: 2345 | E13: 2625
A14: 7 | B14: Kyauk Myaung Gyi(W) | C14: 13051 | D14: 5545 | E14: 7506
A15: 8 | B15: Kyauk Myaung Ah Htet(W) | C15: 4239 | D15: 1775 | E15: 2464
A16: 9 | B16: Kyauk Myaung (East)(W) | C16: 6350 | D16: 2700 | E16: 3650
A17: 10 | B17: Pa Thein Nyunt(W) | C17: 9264 | D17: 3993 | E17: 5271
A18: 11 | B18: Kyar Kwet Thit(W) | C18: 10016 | D18: 4285 | E18: 5731
A19: 12 | B19: Byaing Yay OeZin Kwet Thit(W) | C19: 4552 | D19: 2030 | E19: 2522
... A27: 20 | B27: Man Aung Ward(W) | C27: 2313 | D27: 1070 | E27: 1243

Sheet Pazuntaung
A1: Yangon Region,East District,Pazuntaung Township
E2: 29-3-2014
A3: Sr | B3: Ward/Village Tract | C3: Population
C4: Total | D4: Male | E4: Female
B5: Total | C5: =SUM(C8:C17) -> 48455 | D5: =SUM(D8:D17) -> 22131 | E5: =SUM(E8:E17) -> 26324
B7: Ward | C7: =SUM(C8:C17) -> 48455 | D7: =SUM(D8:D17) -> 22131 | E7: =SUM(E8:E17) -> 26324
A8: 1 | B8: No(1)(W) | C8: 5986 | D8: 2597 | E8: 3389
A9: 2 | B9: No(2)(W) | C9: 13172 | D9: 6305 | E9: 6867
A10: 3 | B10: No(3)/No (3)/(4)(W) | C10: 3738 | D10: 1728 | E10: 2010
A11: 4 | B11: No(4)(W) | C11: 1140 | D11: 675 | E11: 465
A12: 5 | B12: No(5)(W) | C12: 2989 | D12: 1411 | E12: 1578
A13: 6 | B13: No(6)(W) | C13: 1492 | D13: 674 | E13: 818
A14: 7 | B14: No(7)(W) | C14: 7277 | D14: 3201 | E14: 4076
A15: 8 | B15: No(8)(W) | C15: 3568 | D15: 1460 | E15: 2108
A16: 9 | B16: No(9)(W) | C16: 4800 | D16: 2022 | E16: 2778
A17: 10 | B17: No(10)(W) | C17: 4293 | D17: 2058 | E17: 2235

Sheet Botahtaung
A1: Yangon Region,East District,Botahtaung Township
E2: 29-3-2014
A3: Sr | B3: Ward/Village Tract | C3: Population
C4: Total | D4: Male | E4: Female
B5: Total | C5: =SUM(C8:C17) -> 40995 | D5: =SUM(D8:D17) -> 19416 | E5: =SUM(E8:E17) -> 21579
B7: Ward | C7: =SUM(C8:C17) -> 40995 | D7: =SUM(D8:D17) -> 19416 | E7: =SUM(E8:E17) -> 21579
A8: 1 | B8: No(1)(W) | C8: 1393 | D8: 644 | E8: 749
A9: 2 | B9: No(2)(W) | C9: 6727 | D9: 3591 | E9: 3136
A10: 3 | B10: No(3)(W) | C10: 3481 | D10: 1666 | E10: 1815
A11: 4 | B11: No(4)(W) | C11: 4593 | D11: 2090 | E11: 2503
A12: 5 | B12: No(5)(W) | C12: 3066 | D12: 1350 | E12: 1716
A13: 6 | B13: No(6)(W) | C13: 4127 | D13: 1910 | E13: 2217
A14: 7 | B14: No(7)(W) | C14: 3431 | D14: 1634 | E14: 1797
A15: 8 | B15: No(8)(W) | C15: 3949 | D15: 1701 | E15: 2248
A16: 9 | B16: No(9)(W) | C16: 2866 | D16: 1327 | E16: 1539
A17: 10 | B17: No(10)(W) | C17: 7362 | D17: 3503 | E17: 3859

Sheet Dagon Myothit(South)
A1: Yangon Region,East District, Dagon Myothit(South) Township
E2: 29-3-2014
A3: Sr | B3: Ward/Village Tract | C3: Population
C4: Total | D4: Male | E4: Female
B5: Total | C5: =SUM(C8:C39) -> 371646 | D5: =SUM(D8:D39) -> 181140 | E5: =SUM(E8:E39) -> 190506
B7: Ward | C7: =SUM(C8:C39) -> 371646 | D7: =SUM(D8:D39) -> 181140 | E7: =SUM(E8:E39) -> 190506
A8: 1 | B8: No(17)(South)/ No (17)(W) | C8: 13668 | D8: 6890 | E8: 6778
A9: 2 | B9: No(18)(W) | C9: 18440 | D9: 8722 | E9: 9718
A10: 3 | B10: No(19)(W) | C10: 16777 | D10: 7820 | E10: 8957
A11: 4 | B11: No(20)(W) | C11: 17026 | D11: 8323 | E11: 8703
A12: 5 | B12: No(21)(W) | C12: 15872 | D12: 7775 | E12: 8097
A13: 6 | B13: No(22)(W) | C13: 17968 | D13: 8809 | E13: 9159
A14: 7 | B14: No(23)(W) | C14: 10882 | D14: 5733 | E14: 5149
A15: 8 | B15: No(24)(W) | C15: 9211 | D15: 4379 | E15: 4832
A16: 9 | B16: No(25)(W) | C16: 7765 | D16: 3643 | E16: 4122
A17: 10 | B17: No(26)(W) | C17: 13058 | D17: 6443 | E17: 6615
A18: 11 | B18: No(53)(W) | C18: 12281 | D18: 5765 | E18: 6516
A19: 12 | B19: No(54)(W) | C19: 16240 | D19: 7919 | E19: 8321
... A39: 32 | B39: Shan Te Gyi(South)/Shan Te Gyi(W) | C39: 2688 | D39: 1314 | E39: 1374

Sheet  Dagon Myothit(North)
A1: Yangon Region,East District, Dagon Myothit(Norht) Township
E2: 29-3-2014
A3: Sr | B3: Ward/Village Tract | C3: Population
C4: Total | D4: Male | E4: Female
B5: Total | C5: =SUM(C8:C34) -> 203948 | D5: 96388 | E5: =SUM(E8:E34) -> 107560
B7: Ward | C7: =SUM(C8:C34) -> 203948 | D7: =SUM(D8:D34) -> 96388 | E7: =SUM(E8:E34) -> 107560
A8: 1 | B8: No(16)(W) | C8: 3387 | D8: 1650 | E8: 1737
A9: 2 | B9: No(27)(W) | C9: 4082 | D9: 1875 | E9: 2207
A10: 3 | B10: No(28)(W) | C10: 4786 | D10: 2162 | E10: 2624
A11: 4 | B11: No(29)(W) | C11: 7068 | D11: 3290 | E11: 3778
A12: 5 | B12: No(30)(W) | C12: 5859 | D12: 2628 | E12: 3231
A13: 6 | B13: No(31)(W) | C13: 6294 | D13: 2934 | E13: 3360
A14: 7 | B14: No(32)(W) | C14: 10634 | D14: 4994 | E14: 5640
A15: 8 | B15: No(33)(W) | C15: 12108 | D15: 6067 | E15: 6041
A16: 9 | B16: No(34)(W) | C16: 6790 | D16: 3295 | E16: 3495
A17: 10 | B17: No(35)(W) | C17: 6855 | D17: 3082 | E17: 3773
A18: 11 | B18: No(36)(W) | C18: 4936 | D18: 2287 | E18: 2649
A19: 12 | B19: No(37)(W) | C19: 6776 | D19: 3109 | E19: 3667
... A34: 27 | B34: No(51)(W) | C34: 11110 | D34: 5466 | E34: 5644

Sheet Dagon Myothit(East)
A1: Yangon Region,East District, Dagon Myothit(East) Township
E2: 29-3-2014
A3: Sr | B3: Ward/Village Tract | C3: Population
C4: Total | D4: Male | E4: Female
B5: Total | C5: =C7+C37 -> 165628 | D5: =D7+D37 -> 80861 | E5: =E7+E37 -> 84767
B7: Ward | C7: =SUM(C8:C35) -> 156244 | D7: =SUM(D8:D35) -> 76015 | E7: =SUM(E8:E35) -> 80229
A8: 1 | B8: No(1)(W) | C8: 9352 | D8: 4678 | E8: 4674
A9: 2 | B9: No(2)(W) | C9: 3374 | D9: 1620 | E9: 1754
A10: 3 | B10: No(3)(W) | C10: 3910 | D10: 1839 | E10: 2071
A11: 4 | B11: No(4)(W) | C11: 3721 | D11: 1752 | E11: 1969
A12: 5 | B12: No(5)(W) | C12: 8168 | D12: 3826 | E12: 4342
A13: 6 | B13: No(6)(W) | C13: 7942 | D13: 3941 | E13: 4001
A14: 7 | B14: No(7)(W) | C14: 12810 | D14: 6141 | E14: 6669
A15: 8 | B15: No(8)(W) | C15: 10920 | D15: 5138 | E15: 5782
A16: 9 | B16: No(9)(W) | C16: 3659 | D16: 1639 | E16: 2020
A17: 10 | B17: No(10)(W) | C17: 1287 | D17: 623 | E17: 664
A18: 11 | B18: No(11)(W) | C18: 5299 | D18: 2538 | E18: 2761
A19: 12 | B19: No(12)(W) | C19: 9379 | D19: 4633 | E19: 4746
... A35: 28 | B35: No(156)(W) | C35: 5132 | D35: 2522 | E35: 2610
B37: Village Tract | C37: =SUM(C38:C40) -> 9384 | D37: =SUM(D38:D40) -> 4846 | E37: =SUM(E38:E40) -> 4538
A38: 1 | B38: Shan Te Gyi (East)(VT) | C38: 1990 | D38: 1010 | E38: 980
A39: 2 | B39: Ma Lit(East)(VT) | C39: 5193 | D39: 2716 | E39: 2477
A40: 3 | B40: Lay Daunt Kan (East)(VT) | C40: 2201 | D40: 1120 | E40: 1081

Sheet Dagon Myothit(Seikkan) 
A1: Yangon Region, East District, Dagon Myothit(Seikkan)Township
E2: 29-3-2014
A3: Sr | B3: Ward/Village Tract | C3: Population
C4: Total | D4: Male | E4: Female
B5: Total | C5: =C7+C39 -> 167448 | D5: =D7+D39 -> 82697 | E5: =E7+E39 -> 84751
B7: Ward | C7: =SUM(C8:C37) -> 150076 | D7: =SUM(D8:D37) -> 73906 | E7: =SUM(E8:E37) -> 76170
A8: 1 | B8: No(58)(W) | C8: 2735 | D8: 1427 | E8: 1308
A9: 2 | B9: No(59)(W) | C9: 277 | D9: 146 | E9: 131
A10: 3 | B10: No(60)(W) | C10: 5187 | D10: 2597 | E10: 2590
A11: 4 | B11: No(61)(W) | C11: 1295 | D11: 941 | E11: 354
A12: 5 | B12: No(67)(W) | C12: 11834 | D12: 6266 | E12: 5568
A13: 6 | B13: No(68)(W) | C13: 3650 | D13: 1813 | E13: 1837
A14: 7 | B14: No(69)(W) | C14: 9689 | D14: 4787 | E14: 4902
A15: 8 | B15: No(73)(W) | C15: 672 | D15: 317 | E15: 355
A16: 9 | B16: No(75)(W) | C16: 498 | D16: 244 | E16: 254
A17: 10 | B17: No(76)(W) | C17: 51 | D17: 25 | E17: 26
A18: 11 | B18: No(77)(W) | C18: 584 | D18: 311 | E18: 273
A19: 12 | B19: No(78)(W) | C19: 1527 | D19: 856 | E19: 671
... A37: 30 | B37: No(168)(W) | C37: 9869 | D37: 4809 | E37: 5060
B39: Village Tract | C39: =SUM(C40:C43) -> 17372 | D39: =SUM(D40:D43) -> 8791 | E39: =SUM(E40:E43) -> 8581
A40: 1 | B40: Kyi Su(East)(VT) | C40: 2986 | D40: 1487 | E40: 1499
A41: 2 | B41: Nyaung Pin(VT) | C41: 10465 | D41: 5238 | E41: 5227
A42: 3 | B42: Tha Yet Pin Chaung(VT) | C42: 2871 | D42: 1520 | E42: 1351
A43: 4 | B43: Da La Ban(VT) | C43: 1050 | D43: 546 | E43: 504

Sheet Mingala Taungnyunt 
A1: Yangon Region, East District, Mingala Taungnyunt Township
E2: 29-3-2014
A3: Sr | B3: Ward/Village Tract | C3: Population
C4: Total | D4: Male | E4: Female
B5: Total | C5: 132494 | D5: 62530 | E5: 69964
B7: Ward | C7: =SUM(C8:C27) -> 132494 | D7: =SUM(D8:D27) -> 62530 | E7: =SUM(E8:E27) -> 69964
A8: 1 | B8: U Yin(W) | C8: 1216 | D8: 626 | E8: 590
A9: 2 | B9: San Pya Hpa Sa Pa La(W) | C9: 7666 | D9: 3527 | E9: 4139
A10: 3 | B10: Kan Taw Ka Lay (North)(W) | C10: 5392 | D10: 2681 | E10: 2711
A11: 4 | B11: Kan Taw Ka Lay (West)(W) | C11: 8610 | D11: 3890 | E11: 4720
A12: 5 | B12: Kan Taw Ka Lay (East)(W) | C12: 7677 | D12: 3300 | E12: 4377
A13: 6 | B13: Kan Taw Ka Lay (South)(W) | C13: 10684 | D13: 4908 | E13: 5776
A14: 7 | B14: Thein Hpyu Mee Ya Htar(W) | C14: 5544 | D14: 2868 | E14: 2676
A15: 8 | B15: Lut Lat Yay(W) | C15: 4038 | D15: 1911 | E15: 2127
A16: 9 | B16: Hpoet Myay(W) | C16: 6886 | D16: 3161 | E16: 3725
A17: 10 | B17: Taung Nyunt Mee Ya Htar(W) | C17: 3251 | D17: 1578 | E17: 1673
A18: 11 | B18: Min Ga Lar Taung Nyunt(W) | C18: 10095 | D18: 4831 | E18: 5264
A19: 12 | B19: Kyee Taw(W) | C19: 4869 | D19: 2204 | E19: 2665
... A27: 20 | B27: Ku Toet Seik(W) | C27: 4166 | D27: 2195 | E27: 1971

Sheet Thanlyin 
A1: Yangon Region, South District, Thanlyin Township
E2: 29-3-2014
A3: Sr | B3: Ward/Village Tract | C3: Population
C4: Total | D4: Male | E4: Female
B5: Total | C5: =C7+C26 -> 268063 | D5: =D7+D26 -> 130537 | E5: =E7+E26 -> 137526
B7: Ward | C7: =SUM(C8:C24) -> 86065 | D7: =SUM(D8:D24) -> 41110 | E7: =SUM(E8:E24) -> 44955
A8: 1 | B8: Myo Haung (West)(W) | C8: 6082 | D8: 3340 | E8: 2742
A9: 2 | B9: Myo Haung (Middle)(W) | C9: 4098 | D9: 2119 | E9: 1979
A10: 3 | B10: Myo Haung (East)(W) | C10: 12914 | D10: 6112 | E10: 6802
A11: 4 | B11: Thauk Taw Kwin(W) | C11: 5449 | D11: 2575 | E11: 2874
A12: 5 | B12: Oke Hpo Su(W) | C12: 5657 | D12: 2683 | E12: 2974
A13: 6 | B13: Ah Mhu Htan(W) | C13: 12009 | D13: 5701 | E13: 6308
A14: 7 | B14: Bago Su(W) | C14: 5315 | D14: 2460 | E14: 2855
A15: 8 | B15: Htan Pin Kone(W) | C15: 3318 | D15: 1479 | E15: 1839
A16: 9 | B16: Myo Thit (East)(W) | C16: 1381 | D16: 691 | E16: 690
A17: 10 | B17: Myo Thit (Middle)(W) | C17: 860 | D17: 480 | E17: 380
A18: 11 | B18: Myo Thit (West)(W) | C18: 579 | D18: 283 | E18: 296
A19: 12 | B19: Myo Ma (South)(W) | C19: 5244 | D19: 2333 | E19: 2911
... A24: 17 | B24: Aung Chan Thar(W) | C24: 10403 | D24: 4818 | E24: 5585
B26: Village Tract | C26: =SUM(C27:C54) -> 181998 | D26: =SUM(D27:D54) -> 89427 | E26: =SUM(E27:E54) -> 92571
A27: 1 | B27: Win Kha Nee(VT) | C27: 1179 | D27: 570 | E27: 609
A28: 2 | B28: Hpar Ku (East)(VT) | C28: 3995 | D28: 1950 | E28: 2045
A29: 3 | B29: Hpar Ku (West)(VT) | C29: 1996 | D29: 971 | E29: 1025
A30: 4 | B30: Day Zat(VT) | C30: 2154 | D30: 1048 | E30: 1106
A31: 5 | B31: Yone Tha Pyay Kan(VT) | C31: 2588 | D31: 1270 | E31: 1318
A32: 6 | B32: Min Ga Lun(VT) | C32: 4146 | D32: 2015 | E32: 2131
A33: 7 | B33: Baw Tha Pyay Kan(VT) | C33: 4392 | D33: 2079 | E33: 2313
A34: 8 | B34: Kayin Seik(VT) | C34: 4272 | D34: 2053 | E34: 2219
A35: 9 | B35: Tha Pyay Kone(VT) | C35: 2525 | D35: 1213 | E35: 1312
A36: 10 | B36: Bagan Taung(VT) | C36: 2714 | D36: 1317 | E36: 1397
A37: 11 | B37: Ah Lun Soke(VT) | C37: 6885 | D37: 3361 | E37: 3524
A38: 12 | B38: Kyaung Kone Seik Gyi/Gya Mar(VT) | C38: 8953 | D38: 5453 | E38: 3500
... A54: 28 | B54: Chaung Sauk(VT) | C54: 1319 | D54: 639 | E54: 680

Sheet Kyauktan 
A1: Yangon Region, South District, Kyauktan Township
E2: 29-3-2014
A3: Sr | B3: Ward/Village Tract | C3: Population
C4: Total | D4: Male | E4: Female
B5: Total | C5: =C7+C18 -> 132765 | D5: =D7+D18 -> 64378 | E5: =E7+E18 -> 68387
B7: Ward | C7: =SUM(C8:C16) -> 42778 | D7: =SUM(D8:D16) -> 20541 | E7: =SUM(E8:E16) -> 22237
A8: 1 | B8: Ah Shey Paing(W) | C8: 3013 | D8: 1483 | E8: 1530
A9: 2 | B9: Ah Lel Paing(W) | C9: 1451 | D9: 675 | E9: 776
A10: 3 | B10: Ah Nauk Paing(W) | C10: 4947 | D10: 2271 | E10: 2676
A11: 4 | B11: Sin Kan(W) | C11: 6962 | D11: 3252 | E11: 3710
A12: 5 | B12: Shwe Kone(W) | C12: 9489 | D12: 4383 | E12: 5106
A13: 6 | B13: San Chein Hmi(W) | C13: 7223 | D13: 3374 | E13: 3849
A14: 7 | B14: Thi Tar Myaing(W) | C14: 3809 | D14: 1942 | E14: 1867
A15: 8 | B15: Shwe Pyi Thar Yar(W) | C15: 3716 | D15: 1885 | E15: 1831
A16: 9 | B16: Aye Mya Thi Dar(W) | C16: 2168 | D16: 1276 | E16: 892
B18: Village Tract | C18: =SUM(C19:C50) -> 89987 | D18: =SUM(D19:D50) -> 43837 | E18: =SUM(E19:E50) -> 46150
A19: 1 | B19: Kan Pyaung(VT) | C19: 3531 | D19: 1747 | E19: 1784
A20: 2 | B20: Pi La Khat(VT) | C20: 1358 | D20: 668 | E20: 690
A21: 3 | B21: Kyon Kan(VT) | C21: 2059 | D21: 1040 | E21: 1019
A22: 4 | B22: Wea Gyi(VT) | C22: 2214 | D22: 1076 | E22: 1138
A23: 5 | B23: Ywar Thit Gyi(VT) | C23: 1619 | D23: 791 | E23: 828
A24: 6 | B24: Kyan Pin(VT) | C24: 1766 | D24: 868 | E24: 898
A25: 7 | B25: Thaung Gyi(VT) | C25: 816 | D25: 388 | E25: 428
A26: 8 | B26: Kayin Chaung(VT) | C26: 1415 | D26: 693 | E26: 722
A27: 9 | B27: Kwe Ka Nar(VT) | C27: 2200 | D27: 1075 | E27: 1125
A28: 10 | B28: Ah Se(VT) | C28: 2766 | D28: 1335 | E28: 1431
A29: 11 | B29: Min Ga Lun(VT) | C29: 5273 | D29: 2464 | E29: 2809
A30: 12 | B30: Na Ywe Chaung(VT) | C30: 1756 | D30: 863 | E30: 893
... A50: 32 | B50: Kha Naung(VT) | C50: 3532 | D50: 1701 | E50: 1831

Sheet Thongwa 
A1: Yangon Region, South District, Thongwa Township
E2: 29-3-2014
A3: Sr | B3: Ward/Village Tract | C3: Population
C4: Total | D4: Male | E4: Female
B5: Total | C5: =C7+C21 -> 157876 | D5: =D7+D21 -> 75492 | E5: =E7+E21 -> 82384
B7: Ward | C7: =SUM(C8:C19) -> 28018 | D7: =SUM(D8:D19) -> 13194 | E7: =SUM(E8:E19) -> 14824
A8: 1 | B8: No(1)(W) | C8: 4155 | D8: 1937 | E8: 2218
A9: 2 | B9: No(2)(W) | C9: 2950 | D9: 1388 | E9: 1562
A10: 3 | B10: No(3)(W) | C10: 2721 | D10: 1301 | E10: 1420
A11: 4 | B11: No(4)(W) | C11: 1325 | D11: 584 | E11: 741
A12: 5 | B12: No(5)(W) | C12: 2207 | D12: 1060 | E12: 1147
A13: 6 | B13: No(6)(W) | C13: 704 | D13: 298 | E13: 406
A14: 7 | B14: No(7)(W) | C14: 2218 | D14: 1029 | E14: 1189
A15: 8 | B15: No(8)(W) | C15: 1051 | D15: 538 | E15: 513
A16: 9 | B16: No(9)(W) | C16: 7423 | D16: 3526 | E16: 3897
A17: 10 | B17: No(10)(W) | C17: 1213 | D17: 578 | E17: 635
A18: 11 | B18: No(11)(W) | C18: 744 | D18: 353 | E18: 391
A19: 12 | B19: No(12)(W) | C19: 1307 | D19: 602 | E19: 705
B21: Village Tract | C21: =SUM(C22:C85) -> 129858 | D21: =SUM(D22:D85) -> 62298 | E21: =SUM(E22:E85) -> 67560
A22: 1 | B22: Pale(VT) | C22: 5218 | D22: 2501 | E22: 2717
A23: 2 | B23: Nyaung Ni(VT) | C23: 4496 | D23: 2145 | E23: 2351
A24: 3 | B24: Ywar Thit(VT) | C24: 3344 | D24: 1630 | E24: 1714
A25: 4 | B25: Thaik Tu Kan(VT) | C25: 3984 | D25: 1886 | E25: 2098
A26: 5 | B26: Kan Myint(VT) | C26: 2152 | D26: 1042 | E26: 1110
A27: 6 | B27: Pyin Ma Kan(VT) | C27: 4352 | D27: 2100 | E27: 2252
A28: 7 | B28: Ye Nwet(VT) | C28: 2130 | D28: 968 | E28: 1162
A29: 8 | B29: Kyar Win(VT) | C29: 1130 | D29: 544 | E29: 586
A30: 9 | B30: Bant Bway(VT) | C30: 942 | D30: 474 | E30: 468
A31: 10 | B31: Min(VT) | C31: 2131 | D31: 1034 | E31: 1097
A32: 11 | B32: Eik Tha Ya(VT) | C32: 3112 | D32: 1474 | E32: 1638
A33: 12 | B33: Thongwa (West)(VT) | C33: 2554 | D33: 1220 | E33: 1334
... A85: 64 | B85: Yan Gyi Aung(VT) | C85: 797 | D85: 387 | E85: 410

Sheet Khayan 
A1: Yangon Region, South District, Khayan Township
E2: 29-3-2014
A3: Sr | B3: Ward/Village Tract | C3: Population
C4: Total | D4: Male | E4: Female
B5: Total | C5: =C7+C21 -> 158019 | D5: =D7+D21 -> 75510 | E5: =E7+E21 -> 82509
B7: Ward | C7: =SUM(C8:C19) -> 32977 | D7: =SUM(D8:D19) -> 15436 | E7: =SUM(E8:E19) -> 17541
A8: 1 | B8: No(1)(W) | C8: 2233 | D8: 999 | E8: 1234
A9: 2 | B9: No(2)(W) | C9: 2387 | D9: 1120 | E9: 1267
A10: 3 | B10: No(3)(W) | C10: 5358 | D10: 2499 | E10: 2859
A11: 4 | B11: No(4)(W) | C11: 692 | D11: 302 | E11: 390
A12: 5 | B12: No(5)(W) | C12: 2274 | D12: 1129 | E12: 1145
A13: 6 | B13: No(6)(W) | C13: 1801 | D13: 821 | E13: 980
A14: 7 | B14: No(7)(W) | C14: 4081 | D14: 1897 | E14: 2184
A15: 8 | B15: No(8)(W) | C15: 1761 | D15: 814 | E15: 947
A16: 9 | B16: No(9)(W) | C16: 3207 | D16: 1544 | E16: 1663
A17: 10 | B17: No(10)(W) | C17: 1769 | D17: 853 | E17: 916
A18: 11 | B18: No(11)(W) | C18: 3275 | D18: 1512 | E18: 1763
A19: 12 | B19: No(12)(W) | C19: 4139 | D19: 1946 | E19: 2193
B21: Village Tract | C21: =SUM(C22:C74) -> 125042 | D21: =SUM(D22:D74) -> 60074 | E21: =SUM(E22:E74) -> 64968
A22: 1 | B22: Pauk Pin(VT) | C22: 3081 | D22: 1440 | E22: 1641
A23: 2 | B23: Ka Mar Mat(VT) | C23: 3397 | D23: 1650 | E23: 1747
A24: 3 | B24: Met Ka Than(VT) | C24: 1141 | D24: 564 | E24: 577
A25: 4 | B25: Kyone Kyone Kya(VT) | C25: 2575 | D25: 1271 | E25: 1304
A26: 5 | B26: Oke Hpo(VT) | C26: 2521 | D26: 1235 | E26: 1286
A27: 6 | B27: Maung Ma(VT) | C27: 3845 | D27: 1864 | E27: 1981
A28: 7 | B28: Kyu Taw(VT) | C28: 2854 | D28: 1376 | E28: 1478
A29: 8 | B29: Ka Mar Chaik(VT) | C29: 2845 | D29: 1365 | E29: 1480
A30: 9 | B30: Ah Lel | C30: 2464 | D30: 1186 | E30: 1278
A31: 10 | B31: Aye Ywar(VT) | C31: 1767 | D31: 890 | E31: 877
A32: 11 | B32: Swei Ka Tawt(VT) | C32: 2365 | D32: 1143 | E32: 1222
A33: 12 | B33: Pein Kan | C33: 3118 | D33: 1481 | E33: 1637
... A74: 53 | B74: Kan Thar(VT) | C74: 1854 | D74: 914 | E74: 940

Sheet Twantay
A1: Yangon Region, South District, Twantay Township
E2: 29-3-2014
A3: Sr | B3: Ward/Village Tract | C3: Population
C4: Total | D4: Male | E4: Female
B5: Total | C5: =C7+C17 -> 226836 | D5: =D7+D17 -> 111251 | E5: =E7+E17 -> 115585
B7: Ward | C7: =SUM(C8:C15) -> 43092 | D7: =SUM(D8:D15) -> 20752 | E7: =SUM(E8:E15) -> 22340
A8: 1 | B8: Kun Chan(W) | C8: 9618 | D8: 4718 | E8: 4900
A9: 2 | B9: Zay Thit(W) | C9: 3521 | D9: 1602 | E9: 1919
A10: 3 | B10: Ohn Pin Su(W) | C10: 1786 | D10: 808 | E10: 978
A11: 4 | B11: Min Paing(W) | C11: 7143 | D11: 3431 | E11: 3712
A12: 5 | B12: Kyun Taw(W) | C12: 5558 | D12: 2616 | E12: 2942
A13: 6 | B13: Shwe San Taw(W) | C13: 5930 | D13: 2991 | E13: 2939
A14: 7 | B14: Oe Bo (East)(W) | C14: 4298 | D14: 2029 | E14: 2269
A15: 8 | B15: Oe Bo (West)(W) | C15: 5238 | D15: 2557 | E15: 2681
B17: Village Tract | C17: =SUM(C18:C82) -> 183744 | D17: =SUM(D18:D82) -> 90499 | E17: =SUM(E18:E82) -> 93245
A18: 1 | B18: Khat Hti Ya(VT) | C18: 4650 | D18: 2300 | E18: 2350
A19: 2 | B19: Ah Ka la(VT) | C19: 1761 | D19: 868 | E19: 893
A20: 3 | B20: Ka Tha Paung(VT) | C20: 924 | D20: 470 | E20: 454
A21: 4 | B21: Kywe Da Yut(VT) | C21: 2478 | D21: 1215 | E21: 1263
A22: 5 | B22: Kayin Chaung(VT) | C22: 490 | D22: 247 | E22: 243
A23: 6 | B23: Kha Naung Htein Ta Pin(VT) | C23: 746 | D23: 357 | E23: 389
A24: 7 | B24: Sar Hpyu Su(VT) | C24: 3943 | D24: 1982 | E24: 1961
A25: 8 | B25: Yae Twin Kone/Ywar Pon(VT) | C25: 2587 | D25: 1337 | E25: 1250
A26: 9 | B26: Tu Chaung Gyi(VT) | C26: 3122 | D26: 1594 | E26: 1528
A27: 10 | B27: Ma Wun(VT) | C27: 1515 | D27: 748 | E27: 767
A28: 11 | B28: Kyi Seik(VT) | C28: 516 | D28: 248 | E28: 268
A29: 12 | B29: Tet Thit(VT) | C29: 964 | D29: 483 | E29: 481
... A82: 65 | B82: Yangon Rubber Chan/pada(VT) | C82: 3687 | D82: 1814 | E82: 1873

Sheet Kawhmu 
A1: Yangon Region, South District, Kawhmu Township
E2: 29-3-2014
A3: Sr | B3: Ward/Village Tract | C3: Population
C4: Total | D4: Male | E4: Female
B5: Total | C5: =C7+C16 -> 119050 | D5: =D7+D16 -> 58299 | E5: =E7+E16 -> 60751
B7: Ward | C7: =SUM(C8:C14) -> 8600 | D7: =SUM(D8:D14) -> 4119 | E7: =SUM(E8:E14) -> 4481
A8: 1 | B8: Myo Thit(W) | C8: 1512 | D8: 721 | E8: 791
A9: 2 | B9: Myo Ma Paing(W) | C9: 1459 | D9: 692 | E9: 767
A10: 3 | B10: Ma Gyi Tan(W) | C10: 758 | D10: 353 | E10: 405
A11: 4 | B11: Tar Lan Thit(W) | C11: 1062 | D11: 542 | E11: 520
A12: 5 | B12: Pyi Taw Thar(W) | C12: 824 | D12: 375 | E12: 449
A13: 6 | B13: Taung Paing(W) | C13: 1032 | D13: 498 | E13: 534
A14: 7 | B14: Hpa Yar Lan(W) | C14: 1953 | D14: 938 | E14: 1015
B16: Village Tract | C16: =SUM(C17:C71) -> 110450 | D16: =SUM(D17:D71) -> 54180 | E16: =SUM(E17:E71) -> 56270
A17: 1 | B17: Htan Pin Chaung(VT) | C17: 689 | D17: 363 | E17: 326
A18: 2 | B18: Yae Kyaw(VT) | C18: 3034 | D18: 1433 | E18: 1601
A19: 3 | B19: Pyin Ka Toe(VT) | C19: 1291 | D19: 619 | E19: 672
A20: 4 | B20: Nyaung Kone(VT) | C20: 2281 | D20: 1152 | E20: 1129
A21: 5 | B21: Kyaik Htaw (North)(VT) | C21: 3918 | D21: 1928 | E21: 1990
A22: 6 | B22: Kyaik Htaw (South)(VT) | C22: 2394 | D22: 1185 | E22: 1209
A23: 7 | B23: Auk Kyaung(VT) | C23: 2379 | D23: 1138 | E23: 1241
A24: 8 | B24: Tha Meit(VT) | C24: 1723 | D24: 892 | E24: 831
A25: 9 | B25: Kyon La Tar(VT) | C25: 1026 | D25: 493 | E25: 533
A26: 10 | B26: Popa(VT) | C26: 1828 | D26: 904 | E26: 924
A27: 11 | B27: Hmaw Taw(VT) | C27: 2191 | D27: 1054 | E27: 1137
A28: 12 | B28: War Thein Kha(VT) | C28: 2331 | D28: 1167 | E28: 1164
... A71: 55 | B71: Tha Yet Taw(VT) | C71: 1267 | D71: 631 | E71: 636

Sheet Kungyangon 
A1: Yangon Region, South District, Kungyangon Township
E2: 29-3-2014
A3: Sr | B3: Ward/Village Tract | C3: Population
C4: Total | D4: Male | E4: Female
B5: Total | C5: =C7+C16 -> 111632 | D5: =D7+D16 -> 54107 | E5: =E7+E16 -> 57525
B7: Ward | C7: =SUM(C8:C14) -> 16627 | D7: =SUM(D8:D14) -> 7931 | E7: =SUM(E8:E14) -> 8696
A8: 1 | B8: Myo Ma(W) | C8: 3283 | D8: 1509 | E8: 1774
A9: 2 | B9: Kan Gyi -Ma Gyi Tan(W) | C9: 3343 | D9: 1647 | E9: 1696
A10: 3 | B10: Zay Paing(W) | C10: 629 | D10: 294 | E10: 335
A11: 4 | B11: Taung Bet Paing(W) | C11: 4038 | D11: 1932 | E11: 2106
A12: 5 | B12: Min Paing(W) | C12: 1443 | D12: 673 | E12: 770
A13: 6 | B13: Taw Pu Lwea(W) | C13: 1208 | D13: 595 | E13: 613
A14: 7 | B14: San Pya(W) | C14: 2683 | D14: 1281 | E14: 1402
B16: Village Tract | C16: =SUM(C17:C59) -> 95005 | D16: =SUM(D17:D59) -> 46176 | E16: =SUM(E17:E59) -> 48829
A17: 1 | B17: Ka Mar Bar(VT) | C17: 4913 | D17: 2356 | E17: 2557
A18: 2 | B18: Kawt Dun(VT) | C18: 1392 | D18: 665 | E18: 727
A19: 3 | B19: Kan Yar Shey(VT) | C19: 3436 | D19: 1651 | E19: 1785
A20: 4 | B20: Kayin Chaung(VT) | C20: 1188 | D20: 601 | E20: 587
A21: 5 | B21: Ka Nyin Kone(VT) | C21: 3825 | D21: 1932 | E21: 1893
A22: 6 | B22: Kya Khat Kone Gyi(VT) | C22: 2348 | D22: 1115 | E22: 1233
A23: 7 | B23: Kya Khat Kone Lay(VT) | C23: 2172 | D23: 1108 | E23: 1064
A24: 8 | B24: Kant Ma lar(VT) | C24: 1335 | D24: 638 | E24: 697
A25: 9 | B25: Kha Lauk Ta Yar(VT) | C25: 3423 | D25: 1676 | E25: 1747
A26: 10 | B26: Hnget Gyi Daung(VT) | C26: 1181 | D26: 579 | E26: 602
A27: 11 | B27: Taik Gyi(VT) | C27: 2043 | D27: 992 | E27: 1051
A28: 12 | B28: Su Ka Lat(VT) | C28: 1033 | D28: 495 | E28: 538
... A59: 43 | B59: In Ga Lone(VT) | C59: 3166 | D59: 1483 | E59: 1683

Sheet Dala 
A1: Yangon Region, South District, Dala Township
E2: 29-3-2014
A3: Sr | B3: Ward/Village Tract | C3: Population
C4: Total | D4: Male | E4: Female
B5: Total | C5: =C7+C32 -> 172857 | D5: =D7+D32 -> 84671 | E5: =E7+E32 -> 88186
B7: Ward | C7: =SUM(C8:C30) -> 119366 | D7: =SUM(D8:D30) -> 58358 | E7: =SUM(E8:E30) -> 61008
A8: 1 | B8: Tha Ma Ta Kan Chay(W) | C8: 4149 | D8: 2002 | E8: 2147
A9: 2 | B9: Ant Gyi Ah Shey(W) | C9: 5324 | D9: 2513 | E9: 2811
A10: 3 | B10: Ant Gyi Ah Nauk(W) | C10: 5623 | D10: 2727 | E10: 2896
A11: 4 | B11: No(6)(W) | C11: 2139 | D11: 1044 | E11: 1095
A12: 5 | B12: No(11/14)(W) | C12: 5610 | D12: 2687 | E12: 2923
A13: 6 | B13: Nyaung Kone(W) | C13: 5847 | D13: 2862 | E13: 2985
A14: 7 | B14: Myo Ma(1)(W) | C14: 1067 | D14: 487 | E14: 580
A15: 8 | B15: Myo Ma(2)(W) | C15: 1423 | D15: 641 | E15: 782
A16: 9 | B16: Myo Ma(3)(W) | C16: 571 | D16: 277 | E16: 294
A17: 10 | B17: Myo Ma(4)(W) | C17: 4901 | D17: 2357 | E17: 2544
A18: 11 | B18: Aung Min Ga Lar(W) | C18: 3025 | D18: 1436 | E18: 1589
A19: 12 | B19: Set Myay(W) | C19: 3699 | D19: 1788 | E19: 1911
... A30: 23 | B30: Bo Yan Pyay(W) | C30: 4192 | D30: 2086 | E30: 2106
B32: Village Tract | C32: =SUM(C33:C55) -> 53491 | D32: =SUM(D33:D55) -> 26313 | E32: =SUM(E33:E55) -> 27178
A33: 1 | B33: Rakhine Chaung (South)(VT) | C33: 1725 | D33: 856 | E33: 869
A34: 2 | B34: Rakhine Chaung (North)(VT) | C34: 1911 | D34: 912 | E34: 999
A35: 3 | B35: Da Noke (San Pya)(VT) | C35: 1871 | D35: 913 | E35: 958
A36: 4 | B36: Nyaung Chaung(VT) | C36: 1474 | D36: 741 | E36: 733
A37: 5 | B37: Tone Tin Gan (South)(VT) | C37: 2887 | D37: 1470 | E37: 1417
A38: 6 | B38: Tone Tin Gan (North)(VT) | C38: 425 | D38: 199 | E38: 226
A39: 7 | B39: Boe Hpyu Chaung(VT) | C39: 1152 | D39: 560 | E39: 592
A40: 8 | B40: Kha Naung (Ywar Ma)(VT) | C40: 3042 | D40: 1513 | E40: 1529
A41: 9 | B41: Kha Naung (Upper)(VT) | C41: 759 | D41: 389 | E41: 370
A42: 10 | B42: Kha Naung (Shan Su)(VT) | C42: 623 | D42: 312 | E42: 311
A43: 11 | B43: Ta Dar Chaung(VT) | C43: 7240 | D43: 3536 | E43: 3704
A44: 12 | B44: Ye Chaung(VT) | C44: 1424 | D44: 708 | E44: 716
... A55: 23 | B55: Tha Yaw Tan(VT) | C55: 1673 | D55: 817 | E55: 856

Sheet Seikkyi- Khanaungto 
A1: Yangon Region, South District, Seikkyi/ Khanaungto Township
E2: 29-3-2014
A3: Sr | B3: Ward/Village Tract | C3: Population
C4: Total | D4: Male | E4: Female
B5: Total | C5: 34003 | D5: 17068 | E5: 16935
B7: Ward | C7: =SUM(C8:C16) -> 34003 | D7: =SUM(D8:D16) -> 17068 | E7: =SUM(E8:E16) -> 16935
A8: 1 | B8: Seik Gyi (East)(W) | C8: 7238 | D8: 3726 | E8: 3512
A9: 2 | B9: Seik Gyi (West)(W) | C9: 6252 | D9: 3103 | E9: 3149
A10: 3 | B10: Kha Naung To (East)(W) | C10: 7204 | D10: 3637 | E10: 3567
A11: 4 | B11: Kha Naung To (West)(W) | C11: 2780 | D11: 1387 | E11: 1393
A12: 5 | B12: U Htun Oh(W) | C12: 2101 | D12: 1043 | E12: 1058
A13: 6 | B13: Pan Pin Chaung(W) | C13: 1618 | D13: 784 | E13: 834
A14: 7 | B14: Samar Du War(W) | C14: 4176 | D14: 2082 | E14: 2094
A15: 8 | B15: Chaung Waing Lay(W) | C15: 1245 | D15: 596 | E15: 649
A16: 9 | B16: Tha Khin Ba Thaung(W) | C16: 1389 | D16: 710 | E16: 679

Sheet Cocogyun 
A1: Yangon Region, South District, Cocogyun Township
E2: 29-3-2014
A3: Sr | B3: Ward/Village Tract | C3: Population
C4: Total | D4: Male | E4: Female
B5: Total | C5: 1940 | D5: 1294 | E5: 646
B7: Ward | C7: =SUM(C8:C9) -> 1940 | D7: =SUM(D8:D9) -> 1294 | E7: =SUM(E8:E9) -> 646
A8: 1 | B8: No(1)(W) | C8: 1552 | D8: 1093 | E8: 459
A9: 2 | B9: No(2)(W) | C9: 388 | D9: 201 | E9: 187

Sheet Tada (Sub- Tsp)
A1: Yangon Region, South District, Tada (Sub- Township)
E2: 29-3-2014
A3: Sr | B3: Ward/Village Tract | C3: Population
C4: Total | D4: Male | E4: Female
B5: Total | C5: =C7+C13 -> 34683 | D5: =D7+D13 -> 17078 | E5: =E7+E13 -> 17605
B7: Ward | C7: =SUM(C8:C11) -> 8834 | D7: =SUM(D8:D11) -> 4302 | E7: =SUM(E8:E11) -> 4532
A8: 1 | B8: No(1)(W) | C8: 2009 | D8: 986 | E8: 1023
A9: 2 | B9: No(2)(W) | C9: 2813 | D9: 1340 | E9: 1473
A10: 3 | B10: No(3)(W) | C10: 1790 | D10: 880 | E10: 910
A11: 4 | B11: No(4)(W) | C11: 2222 | D11: 1096 | E11: 1126
B13: Village Tract | C13: =SUM(C14:C25) -> 25849 | D13: =SUM(D14:D25) -> 12776 | E13: =SUM(E14:E25) -> 13073
A14: 1 | B14: Sin Ma Kaw(VT) | C14: 1582 | D14: 798 | E14: 784
A15: 2 | B15: Pan Chaung(VT) | C15: 874 | D15: 431 | E15: 443
A16: 3 | B16: Tar Pat(VT) | C16: 2186 | D16: 1060 | E16: 1126
A17: 4 | B17: Ka Dat Pa Na(VT) | C17: 1685 | D17: 803 | E17: 882
A18: 5 | B18: Win Gyi(VT) | C18: 1953 | D18: 945 | E18: 1008
A19: 6 | B19: Sit Tan(VT) | C19: 2979 | D19: 1432 | E19: 1547
A20: 7 | B20: Poke Ta Loke(VT) | C20: 3770 | D20: 1775 | E20: 1995
A21: 8 | B21: Ma Yan Bay(VT) | C21: 2495 | D21: 1210 | E21: 1285
A22: 9 | B22: Shan Chaung(VT) | C22: 2541 | D22: 1228 | E22: 1313
A23: 10 | B23: Tu Myaung(VT) | C23: 1155 | D23: 591 | E23: 564
A24: 11 | B24: Ta Man Gyi Kone(VT) | C24: 2752 | D24: 1380 | E24: 1372
A25: 12 | B25: Aung Chan Thar(VT) | C25: 1877 | D25: 1123 | E25: 754

Sheet Kyauktada 
A1: Yangon Region, West District, KyauktadaTownship
E2: 29-3-2014
A3: Sr | B3: Ward/Village Tract | C3: Population
C4: Total | D4: Male | E4: Female
B5: Total | C5: 29853 | D5: 13777 | E5: 16076
B7: Ward | C7: =SUM(C8:C16) -> 29853 | D7: =SUM(D8:D16) -> 13777 | E7: =SUM(E8:E16) -> 16076
A8: 1 | B8: No(1)(W) | C8: 2773 | D8: 1371 | E8: 1402
A9: 2 | B9: No(2)(W) | C9: 3494 | D9: 1748 | E9: 1746
A10: 3 | B10: No(3)(W) | C10: 3429 | D10: 1537 | E10: 1892
A11: 4 | B11: No(4)(W) | C11: 1601 | D11: 792 | E11: 809
A12: 5 | B12: No(5)(W) | C12: 2666 | D12: 1249 | E12: 1417
A13: 6 | B13: No(6)(W) | C13: 3293 | D13: 1507 | E13: 1786
A14: 7 | B14: No(7)(W) | C14: 3645 | D14: 1697 | E14: 1948
A15: 8 | B15: No(8)(W) | C15: 4057 | D15: 1792 | E15: 2265
A16: 9 | B16: No(9)(W) | C16: 4895 | D16: 2084 | E16: 2811

Sheet Pabedan 
A1: Yangon Region, West District, Pabedan Township
E2: 29-3-2014
A3: Sr | B3: Ward/Village Tract | C3: Population
C4: Total | D4: Male | E4: Female
B5: Total | C5: 33336 | D5: 15171 | E5: 18165
B7: Ward | C7: =SUM(C8:C18) -> 33336 | D7: =SUM(D8:D18) -> 15171 | E7: =SUM(E8:E18) -> 18165
A8: 1 | B8: No(1)(W) | C8: 2834 | D8: 1210 | E8: 1624
A9: 2 | B9: No(2)(W) | C9: 2680 | D9: 1193 | E9: 1487
A10: 3 | B10: No(3)(W) | C10: 3783 | D10: 1717 | E10: 2066
A11: 4 | B11: No(4)(W) | C11: 3312 | D11: 1420 | E11: 1892
A12: 5 | B12: No(5)(W) | C12: 2820 | D12: 1214 | E12: 1606
A13: 6 | B13: No(6)(W) | C13: 2971 | D13: 1450 | E13: 1521
A14: 7 | B14: No(7)(W) | C14: 4207 | D14: 1980 | E14: 2227
A15: 8 | B15: No(8)(W) | C15: 3944 | D15: 1825 | E15: 2119
A16: 9 | B16: No(9)(W) | C16: 1688 | D16: 790 | E16: 898
A17: 10 | B17: No(10)(W) | C17: 2599 | D17: 1161 | E17: 1438
A18: 11 | B18: No(11)(W) | C18: 2498 | D18: 1211 | E18: 1287

Sheet Lanmadaw 
A1: Yangon Region, West District, LanmadawTownship
E2: 29-3-2014
A3: Sr | B3: Ward/Village Tract | C3: Population
C4: Total | D4: Male | E4: Female
B5: Total | C5: 47160 | D5: 20180 | E5: 26980
B7: Ward | C7: =SUM(C8:C19) -> 47160 | D7: =SUM(D8:D19) -> 20180 | E7: =SUM(E8:E19) -> 26980
A8: 1 | B8: No(1)(W) | C8: 4059 | D8: 1775 | E8: 2284
A9: 2 | B9: No(2)(W) | C9: 4962 | D9: 1985 | E9: 2977
A10: 3 | B10: No(3)(W) | C10: 4082 | D10: 1708 | E10: 2374
A11: 4 | B11: No(4)(W) | C11: 4156 | D11: 1629 | E11: 2527
A12: 5 | B12: No(5)(W) | C12: 4199 | D12: 1766 | E12: 2433
A13: 6 | B13: No(6)(W) | C13: 5549 | D13: 2272 | E13: 3277
A14: 7 | B14: No(7)(W) | C14: 7626 | D14: 3149 | E14: 4477
A15: 8 | B15: No(8)(W) | C15: 2612 | D15: 1104 | E15: 1508
A16: 9 | B16: No(9)(W) | C16: 3788 | D16: 1757 | E16: 2031
A17: 10 | B17: No(10)(W) | C17: 1589 | D17: 583 | E17: 1006
A18: 11 | B18: No(11)(W) | C18: 1838 | D18: 754 | E18: 1084
A19: 12 | B19: No(12)(W) | C19: 2700 | D19: 1698 | E19: 1002

Sheet Latha 
A1: Yangon Region, West District, Latha Township
E2: 29-3-2014
A3: Sr | B3: Ward/Village Tract | C3: Population
C4: Total | D4: Male | E4: Female
B5: Total | C5: 25057 | D5: 10728 | E5: 14329
B7: Ward | C7: =SUM(C8:C17) -> 25057 | D7: =SUM(D8:D17) -> 10728 | E7: =SUM(E8:E17) -> 14329
A8: 1 | B8: No(1)(W) | C8: 2488 | D8: 1104 | E8: 1384
A9: 2 | B9: No(2)(W) | C9: 3520 | D9: 1513 | E9: 2007
A10: 3 | B10: No(3)(W) | C10: 2438 | D10: 988 | E10: 1450
A11: 4 | B11: No(4)(W) | C11: 3367 | D11: 1479 | E11: 1888
A12: 5 | B12: No(5)(W) | C12: 2758 | D12: 1181 | E12: 1577
A13: 6 | B13: No(6)(W) | C13: 2567 | D13: 1158 | E13: 1409
A14: 7 | B14: No(7)(W) | C14: 2428 | D14: 957 | E14: 1471
A15: 8 | B15: No(8)(W) | C15: 2596 | D15: 1104 | E15: 1492
A16: 9 | B16: No(9)(W) | C16: 2237 | D16: 976 | E16: 1261
A17: 10 | B17: No(10)(W) | C17: 658 | D17: 268 | E17: 390

Sheet Ahlon 
A1: Yangon Region, West District, Ahlon Township
E2: 29-3-2014
A3: Sr | B3: Ward/Village Tract | C3: Population
C4: Total | D4: Male | E4: Female
B5: Total | C5: 55482 | D5: 25551 | E5: 29931
B7: Ward | C7: =SUM(C8:C18) -> 55482 | D7: =SUM(D8:D18) -> 25551 | E7: =SUM(E8:E18) -> 29931
A8: 1 | B8: Aye Yar Wa Di(W) | C8: 882 | D8: 579 | E8: 303
A9: 2 | B9: Saw Ran Paing(West)/Sayar Hmat Gyi(West)(W) | C9: 10839 | D9: 5173 | E9: 5666
A10: 3 | B10: Saw Ran Paing(East)/Sayar Hmat Gyi (East)(W) | C10: 4171 | D10: 1873 | E10: 2298
A11: 4 | B11: Saw Ran Paing(South)/Super Pin (South)(W) | C11: 5241 | D11: 2348 | E11: 2893
A12: 5 | B12: Htar Nar(W) | C12: 7660 | D12: 3243 | E12: 4417
A13: 6 | B13: Saw Ran Paing(North)/Super Pin (North)(W) | C13: 2347 | D13: 1045 | E13: 1302
A14: 7 | B14: Sin Min Ward(W) | C14: 8257 | D14: 3664 | E14: 4593
A15: 8 | B15: Ga Lon(W) | C15: 4336 | D15: 1867 | E15: 2469
A16: 9 | B16: Lut Lat Yay(W) | C16: 3020 | D16: 1411 | E16: 1609
A17: 10 | B17: Kayin Chan(W) | C17: 3936 | D17: 1845 | E17: 2091
A18: 11 | B18: Thit Taw(W) | C18: 4793 | D18: 2503 | E18: 2290

Sheet Kyimyindine 
A1: Yangon Region, West District, Kyimyindine Township
E2: 29-3-2014
A3: Sr | B3: Ward/Village Tract | C3: Population
C4: Total | D4: Male | E4: Female
B5: Total | C5: 111514 | D5: 52627 | E5: 58887
B7: Ward | C7: =SUM(C8:C29) -> 111514 | D7: =SUM(D8:D29) -> 52627 | E7: =SUM(E8:E29) -> 58887
A8: 1 | B8: Tha Yet Taw (North)(W) | C8: 2583 | D8: 1258 | E8: 1325
A9: 2 | B9: Tha Yet Taw (South)(W) | C9: 3456 | D9: 1647 | E9: 1809
A10: 3 | B10: Thar Du (East)(W) | C10: 2768 | D10: 1259 | E10: 1509
A11: 4 | B11: Thar Du (West)(W) | C11: 3155 | D11: 1626 | E11: 1529
A12: 5 | B12: Ma Gyi Tan (North/East)(W) | C12: 5295 | D12: 2577 | E12: 2718
A13: 6 | B13: Ma Gyi Tan (North/West)(W) | C13: 1441 | D13: 915 | E13: 526
A14: 7 | B14: Ma Gyi Tan (South/East)(W) | C14: 2139 | D14: 977 | E14: 1162
A15: 8 | B15: Ma Gyi Tan (South/West)(W) | C15: 3478 | D15: 1583 | E15: 1895
A16: 9 | B16: Zay Gyi (East)(W) | C16: 4914 | D16: 2073 | E16: 2841
A17: 10 | B17: Zay Gyi (West)(W) | C17: 6018 | D17: 2614 | E17: 3404
A18: 11 | B18: Oe Bo(W) | C18: 5379 | D18: 2552 | E18: 2827
A19: 12 | B19: Baw Kar(W) | C19: 2835 | D19: 1233 | E19: 1602
... A29: 22 | B29: Pan Hlaing(W) | C29: 4498 | D29: 1924 | E29: 2574

Sheet Sangyoung 
A1: Yangon Region, West District, Sangyoung Township
E2: 29-3-2014
A3: Sr | B3: Ward/Village Tract | C3: Population
C4: Total | D4: Male | E4: Female
B5: Total | C5: 99619 | D5: 43993 | E5: 55626
B7: Ward | C7: =SUM(C8:C25) -> 99619 | D7: =SUM(D8:D25) -> 43993 | E7: =SUM(E8:E25) -> 55626
A8: 1 | B8: Way Lu Wun (North)(W) | C8: 4396 | D8: 2027 | E8: 2369
A9: 2 | B9: Way Lu Wun (South)(W) | C9: 2724 | D9: 1332 | E9: 1392
A10: 3 | B10: Mont Loke Saung Kone (North)(W) | C10: 3759 | D10: 1743 | E10: 2016
A11: 4 | B11: Mont Loke Saung Kone (South)(W) | C11: 9555 | D11: 4626 | E11: 4929
A12: 5 | B12: Kyun Taw (North)(W) | C12: 2975 | D12: 1293 | E12: 1682
A13: 6 | B13: Kyun Taw (Middle)(W) | C13: 4244 | D13: 1687 | E13: 2557
A14: 7 | B14: Kyun Taw (South)(W) | C14: 8186 | D14: 3484 | E14: 4702
A15: 8 | B15: Than Ta Dar(W) | C15: 4294 | D15: 1859 | E15: 2435
A16: 9 | B16: Lin Lun( North)(W) | C16: 6674 | D16: 2754 | E16: 3920
A17: 10 | B17: Lin Lun( South)(W) | C17: 6248 | D17: 3090 | E17: 3158
A18: 11 | B18: San Chaung (North)(W) | C18: 7099 | D18: 2873 | E18: 4226
A19: 12 | B19: San Chaung (South)(W) | C19: 7040 | D19: 2868 | E19: 4172
... A25: 18 | B25: Myay Ni Kone (South)(W) | C25: 9578 | D25: 4243 | E25: 5335

Sheet Hline 
A1: Yangon Region,West District, Hline Township
E2: 29-3-2014
A3: Sr | B3: Ward/Village Tract | C3: Population
C4: Total | D4: Male | E4: Female
B5: Total | C5: 160307 | D5: 75029 | E5: 85278
B7: Ward | C7: =SUM(C8:C23) -> 160307 | D7: =SUM(D8:D23) -> 75029 | E7: =SUM(E8:E23) -> 85278
A8: 1 | B8: No(1)(W) | C8: 13693 | D8: 6489 | E8: 7204
A9: 2 | B9: No(2)(W) | C9: 13251 | D9: 6486 | E9: 6765
A10: 3 | B10: No(3)(W) | C10: 6396 | D10: 3144 | E10: 3252
A11: 4 | B11: No(4)(W) | C11: 5387 | D11: 2558 | E11: 2829
A12: 5 | B12: No(5)(W) | C12: 8179 | D12: 3768 | E12: 4411
A13: 6 | B13: No(6)(W) | C13: 4817 | D13: 2284 | E13: 2533
A14: 7 | B14: No(7)(W) | C14: 15497 | D14: 7182 | E14: 8315
A15: 8 | B15: No(8)(W) | C15: 4501 | D15: 2044 | E15: 2457
A16: 9 | B16: No(9)(W) | C16: 9601 | D16: 4559 | E16: 5042
A17: 10 | B17: No(10)(W) | C17: 7681 | D17: 3414 | E17: 4267
A18: 11 | B18: No(11)(W) | C18: 9782 | D18: 4427 | E18: 5355
A19: 12 | B19: No(12)(W) | C19: 14471 | D19: 6822 | E19: 7649
... A23: 16 | B23: No(16)(W) | C23: 17170 | D23: 7827 | E23: 9343

Sheet Kamayut 
A1: Yangon Region,West District, Kamayut Township
E2: 29-3-2014
A3: Sr | B3: Ward/Village Tract | C3: Population
