Workbook

Sheet Link of Township
A2: 1 | B2: =Taunggyi!A1 -> Shan State,Taunggyi District,Taunggyi Township
A3: 2 | B3: =' Nyaungshwe'!A1 -> Shan State,Taunggyi District,Nyaungshwe Township
A4: 3 | B4: =Hopong!A1 -> Shan State,Taunggyi District, Hopong Township
A5: 4 | B5: =Hsihseng!A1 -> Shan State,Taunggyi District, Hsihseng Township
A6: 5 | B6: =Kalaw!A1 -> Shan State,Taunggyi District, Kalaw Township
A7: 6 | B7: =Pindaya!A1 -> Shan State,Taunggyi District, Pindaya Township
A8: 7 | B8: =Ywangan!A1 -> Shan State,Taunggyi District, Ywarngan Township
A9: 8 | B9: =Yatsauk!A1 -> Shan State,Taunggyi District, Yatsauk Township
A10: 9 | B10: =Pinlaung!A1 -> Shan State,Taunggyi District, Pinlaung Township
A11: 10 | B11: =Phekon!A1 -> Shan State,Taunggyi District, Phekon Township
A12: 11 | B12: ='Kyauktalongyi (Sub-Tsp)'!A1 -> Shan State,Taunggyi District,Kyauktalongyi (Sub-Township)
A13: 12 | B13: ='Indaw (Sub-Tsp)'!A1 -> Shan State,Taunggyi District,Indaw(Sub-Township)
A14: 13 | B14: ='Naungtayar (Sub-Tsp)'!A1 -> Shan State,Taunggyi District, Naungtayar(Sub-Township)
A15: 14 | B15: =Loilem!A1 -> Shan State, Loilem District, Loilem Township
A16: 15 | B16: =Lahecha!A1 -> Shan State, Loilem District, Le`char Township
A17: 16 | B17: ='Nanhsam(South)'!A1 -> Shan State, Loilem District, Nanhsam(South) Township
A18: 17 | B18: =Kunhing!A1 -> Shan State, Loilem District, Kunhing Township
A19: 18 | B19: =Kehsi!A1 -> Shan State, Loilem District, Kehsi Township
A20: 19 | B20: =Mongkai!A1 -> Shan State, Loilem District, Mongkai Township
A21: 20 | B21: =Mineshu!A1 -> Shan State, Loilem District, Mineshu Township
A22: 21 | B22: ='Panglong (Sub-Tsp)'!A1 -> Shan State, Loilem District, Panglong(Sub-Township)
A23: 22 | B23: ='Kholan(Sub-Tsp)'!A1 -> Shan State, Loilem District, Kholan(Sub-Township)
A24: 23 | B24: ='Karli(sub-Tsp)'!A1 -> Shan State, Loilem District, Karli(Sub-Township)
A25: 24 | B25: ='Minenaung(Sub-Tsp)'!A1 -> Shan State, Loilem District, Minenaung(Sub-Township)
A26: 25 | B26: ='Minesan(Monsan)(Sub-Tsp)'!A1 -> Shan State, Loilem District, Minesan (Monsan)Sub-Township
A27: 26 | B27: =Linkhe!A1 -> Shan State, Linkhe` District, Linkhe` Township
A28: 27 | B28: =Mone!A1 -> Shan State, Linkhe` District, Mone Township
A29: 28 | B29: =Maukme!A1 -> Shan State, Linkhe` District, Maukme Township
A30: 29 | B30: =Minepan!A1 -> Shan State, Linkhe` District, Minepan Township
A31: 30 | B31: ='Homane (Sub-Tsp)'!A1 -> Shan State, Linkhe` District, Homane(Sub- Township)
A32: 31 | B32: ='Kengtaung(Sub-Tsp)'!A1 -> Shan State, Linkhe` District, Kengtaung(Sub--Township)
A33: 32 | B33: =Lashio!A1 -> Shan State, Lashio District, Lashio Township
A34: 33 | B34: =Theinni!A1 -> Shan State, Lashio District, Theinni Township
A35: 34 | B35: =Mineye!A1 -> Shan State, Lashio District, Mineye` Township
A36: 35 | B36: =Tantyan!A1 -> Shan State, Lashio District,Tantyan Township
A37: 36 | B37: =Muse!A1 -> Shan State, MuSe District, MuSe Township
A38: 37 | B38: =Namkham!A1 -> Shan State, MuSe District, Namkham Township
A39: 38 | B39: =Kukai!A1 -> Shan State, MuSe District, Kukai Township
A40: 39 | B40: ='Monekoe(Sub-Tsp)'!A1 -> Shan State, MuSe District, Monekoe(Sub-Township)
A41: 40 | B41: ='Manhero (Manhyo)(Sub-Tsp)'!A1 -> Shan State, MuSe District, Manhero(Manhyo)Sub-Township
...

Sheet Taunggyi
A1: Shan State,Taunggyi District,Taunggyi Township
E2: 29-3-2014
A4: Sr | B4: Ward/Village Tract | C4: Population
C5: Total | D5: Male | E5: Female
B6: Total | C6: 381639 | D6: 185954 | E6: 195685
B8: Ward | C8: =C10+C34+C48 -> 264804 | D8: =D10+D34+D48 -> 126928 | E8: =E10+E34+E48 -> 137876
B10: Taunggyi Town | C10: =SUM(C11:C32) -> 168393 | D10: =SUM(D11:D32) -> 80087 | E10: =SUM(E11:E32) -> 88306
A11: 1 | B11: Nyaung Hpyu Sa Khan(W) | C11: 16839 | D11: 7938 | E11: 8901
A12: 2 | B12: Min Ga Lar U(W) | C12: 6397 | D12: 2832 | E12: 3565
A13: 3 | B13: Pyi Taw Thar(W) | C13: 2941 | D13: 1341 | E13: 1600
A14: 4 | B14: Ya Da Nar Thi Ri(W) | C14: 8969 | D14: 4107 | E14: 4862
A15: 5 | B15: Nyaung Shwe Haw Kone(W) | C15: 2313 | D15: 1012 | E15: 1301
A16: 6 | B16: Yae Aye Kwin(W) | C16: 10504 | D16: 4802 | E16: 5702
A17: 7 | B17: Kan Auk(W) | C17: 2463 | D17: 1153 | E17: 1310
A18: 8 | B18: Chan Mya Thar Zi(W) | C18: 6380 | D18: 3048 | E18: 3332
A19: 9 | B19: Zay Paing(W) | C19: 1508 | D19: 746 | E19: 762
A20: 10 | B20: Shwe Taung(W) | C20: 9607 | D20: 4631 | E20: 4976
A21: 11 | B21: Kan (East)(W) | C21: 3141 | D21: 1358 | E21: 1783
A22: 12 | B22: Lan Ma Taw(W) | C22: 2114 | D22: 1022 | E22: 1092
... A32: 22 | B32: Kan Gyi(W) | C32: 4144 | D32: 2138 | E32: 2006
B34: Aye Thar Yar Town | C34: =SUM(C35:C46) -> 56555 | D34: =SUM(D35:D46) -> 27547 | E34: =SUM(E35:E46) -> 29008
A35: 23 | B35: No(1)(W) | C35: 3619 | D35: 1968 | E35: 1651
A36: 24 | B36: No(2)(W) | C36: 2092 | D36: 1013 | E36: 1079
A37: 25 | B37: No(3)(W) | C37: 4038 | D37: 2032 | E37: 2006
A38: 26 | B38: No(4)(W) | C38: 3540 | D38: 1744 | E38: 1796
A39: 27 | B39: No(5)(W) | C39: 2650 | D39: 1286 | E39: 1364
A40: 28 | B40: No(6)(W) | C40: 8364 | D40: 3961 | E40: 4403
A41: 29 | B41: No(7)(W) | C41: 4652 | D41: 2163 | E41: 2489
A42: 30 | B42: No(8)(W) | C42: 6456 | D42: 3016 | E42: 3440
A43: 31 | B43: No(9)(W) | C43: 6869 | D43: 3174 | E43: 3695
A44: 32 | B44: No(10)(W) | C44: 6468 | D44: 3015 | E44: 3453
A45: 33 | B45: No(11)(W) | C45: 1469 | D45: 688 | E45: 781
A46: 34 | B46: No(12)(W) | C46: 6338 | D46: 3487 | E46: 2851
B48: Shwe Nyaung Town | C48: =SUM(C49:C59) -> 39856 | D48: =SUM(D49:D59) -> 19294 | E48: =SUM(E49:E59) -> 20562
A49: 35 | B49: Hlaing Bon Thar(W) | C49: 4358 | D49: 2184 | E49: 2174
A50: 36 | B50: Thu Kha Chan Thar(W) | C50: 2685 | D50: 1353 | E50: 1332
A51: 37 | B51: Shwe Bon Thar(W) | C51: 5000 | D51: 2394 | E51: 2606
A52: 38 | B52: Dana Thei Di(W) | C52: 2172 | D52: 996 | E52: 1176
A53: 39 | B53: Ya Da Nar(W) | C53: 2739 | D53: 1261 | E53: 1478
A54: 40 | B54: Min Ga Lar Shwe Baho(W) | C54: 3530 | D54: 1653 | E54: 1877
...

Sheet  Nyaungshwe
A1: Shan State,Taunggyi District,Nyaungshwe Township
E2: 29-3-2014
A4: Sr | B4: Ward/Village Tract | C4: Population
C5: Total | D5: Male | E5: Female
B6: Total | C6: 189407 | D6: 94537 | E6: 94870
B8: Ward | C8: =SUM(C9:C16) -> 16208 | D8: =SUM(D9:D16) -> 8174 | E8: =SUM(E9:E16) -> 8034
A9: 1 | B9: Kan Thar(W) | C9: 2287 | D9: 1100 | E9: 1187
A10: 2 | B10: Thar Si(W) | C10: 1343 | D10: 651 | E10: 692
A11: 3 | B11: Nan Da Wun(W) | C11: 6953 | D11: 3605 | E11: 3348
A12: 4 | B12: Myo Lel(W) | C12: 742 | D12: 375 | E12: 367
A13: 5 | B13: Win(W) | C13: 1310 | D13: 660 | E13: 650
A14: 6 | B14: Nang Pang(W) | C14: 1115 | D14: 574 | E14: 541
A15: 7 | B15: Min Ga Lar(W) | C15: 766 | D15: 384 | E15: 382
A16: 8 | B16: Mong Li(W) | C16: 1692 | D16: 825 | E16: 867
B17: Village Tract | C17: =SUM(C18:C52) -> 173199 | D17: =SUM(D18:D52) -> 86363 | E17: =SUM(E18:E52) -> 86836
A18: 1 | B18: Nan Thea(VT) | C18: 4736 | D18: 2380 | E18: 2356
A19: 2 | B19: Kyun Gyi(VT) | C19: 3603 | D19: 1751 | E19: 1852
A20: 3 | B20: Lin Kin(VT) | C20: 4822 | D20: 2411 | E20: 2411
A21: 4 | B21: Khaung Taing(VT) | C21: 3358 | D21: 1673 | E21: 1685
A22: 5 | B22: Let Maung Kway(VT) | C22: 2737 | D22: 1373 | E22: 1364
A23: 6 | B23: Taung Poet Gyi(VT) | C23: 4116 | D23: 2109 | E23: 2007
A24: 7 | B24: Taung Chay Myin Sa Hkunt(VT) | C24: 6890 | D24: 3527 | E24: 3363
A25: 8 | B25: Mong Thauk(VT) | C25: 7226 | D25: 3859 | E25: 3367
A26: 9 | B26: Ywar Thar(VT) | C26: 4583 | D26: 2261 | E26: 2322
A27: 10 | B27: Ti Law Sa Khan Gyi(VT) | C27: 13770 | D27: 6975 | E27: 6795
A28: 11 | B28: Min Chaung(VT) | C28: 8869 | D28: 4337 | E28: 4532
A29: 12 | B29: Nang Pang(VT) | C29: 4969 | D29: 2429 | E29: 2540
... A52: 35 | B52: Pont Mu(VT) | C52: 6070 | D52: 3081 | E52: 2989

Sheet Hopong
A1: Shan State,Taunggyi District, Hopong Township
E2: 29-3-2014
A4: Sr | B4: Ward/Village Tract | C4: Population
C5: Total | D5: Male | E5: Female
B6: Total | C6: 112348 | D6: 55535 | E6: 56813
B8: Ward | C8: =SUM(C9:C14) -> 22840 | D8: =SUM(D9:D14) -> 12106 | E8: =SUM(E9:E14) -> 10734
A9: 1 | B9: Myo U(W) | C9: 3916 | D9: 1820 | E9: 2096
A10: 2 | B10: Myo U Kwet Thit(W) | C10: 7942 | D10: 5002 | E10: 2940
A11: 3 | B11: Ah Shey(W) | C11: 673 | D11: 304 | E11: 369
A12: 4 | B12: Ah Nauk(W) | C12: 1426 | D12: 668 | E12: 758
A13: 5 | B13: Taung(W) | C13: 7113 | D13: 3445 | E13: 3668
A14: 6 | B14: Tong Hkam(W) | C14: 1770 | D14: 867 | E14: 903
B15: Village Tract | C15: =SUM(C16:C37) -> 89508 | D15: =SUM(D16:D37) -> 43429 | E15: =SUM(E16:E37) -> 46079
A16: 1 | B16: Nam Hkoke(VT) | C16: 4060 | D16: 2001 | E16: 2059
A17: 2 | B17: Kone Keng(VT) | C17: 2749 | D17: 1359 | E17: 1390
A18: 3 | B18: Long Hay(VT) | C18: 6050 | D18: 2932 | E18: 3118
A19: 4 | B19: Pawng Lin(VT) | C19: 9895 | D19: 4920 | E19: 4975
A20: 5 | B20: Sam Hpu (Me Nei Taung)(VT) | C20: 7443 | D20: 3529 | E20: 3914
A21: 6 | B21: Sa Ngaw(VT) | C21: 6538 | D21: 3112 | E21: 3426
A22: 7 | B22: Kyauk Tan(VT) | C22: 4458 | D22: 2093 | E22: 2365
A23: 8 | B23: Baw Kone(VT) | C23: 4859 | D23: 2341 | E23: 2518
A24: 9 | B24: Ti Long(VT) | C24: 4494 | D24: 2192 | E24: 2302
A25: 10 | B25: Loi Aun(VT) | C25: 6018 | D25: 2963 | E25: 3055
A26: 11 | B26: Le Thet(VT) | C26: 1184 | D26: 624 | E26: 560
A27: 12 | B27: Long Hkoke(VT) | C27: 3919 | D27: 1941 | E27: 1978
... A37: 22 | B37: Nawng Lai Mu Hpeik(VT) | C37: 3643 | D37: 1757 | E37: 1886

Sheet Hsihseng
A1: Shan State,Taunggyi District, Hsihseng Township
E2: 29-3-2014
A4: Sr | B4: Ward/Village Tract | C4: Population
C5: Total | D5: Male | E5: Female
B6: Total | C6: 153032 | D6: 74736 | E6: 78296
B8: Ward | C8: =SUM(C9:C14) -> 12073 | D8: =SUM(D9:D14) -> 6029 | E8: =SUM(E9:E14) -> 6044
A9: 1 | B9: Ho Hke(W) | C9: 2280 | D9: 1228 | E9: 1052
A10: 2 | B10: Min Ga Lar(W) | C10: 977 | D10: 468 | E10: 509
A11: 3 | B11: Thi Ri(W) | C11: 1110 | D11: 540 | E11: 570
A12: 4 | B12: Aung Tha Pyay(W) | C12: 1758 | D12: 834 | E12: 924
A13: 5 | B13: Aung Chan Thar(W) | C13: 3996 | D13: 1884 | E13: 2112
A14: 6 | B14: Mya Kan Thar(W) | C14: 1952 | D14: 1075 | E14: 877
B15: Village Tract | C15: =SUM(C16:C28) -> 140959 | D15: =SUM(D16:D28) -> 68707 | E15: =SUM(E16:E28) -> 72252
A16: 1 | B16: Hsihseng(VT) | C16: 18206 | D16: 8914 | E16: 9292
A17: 2 | B17: Ta Bet(VT) | C17: 7208 | D17: 3619 | E17: 3589
A18: 3 | B18: Taung (East)(VT) | C18: 12700 | D18: 6160 | E18: 6540
A19: 4 | B19: Pin Son(VT) | C19: 9077 | D19: 4473 | E19: 4604
A20: 5 | B20: Kone Hsut(VT) | C20: 4912 | D20: 2410 | E20: 2502
A21: 6 | B21: Bant Bwee(VT) | C21: 6164 | D21: 2974 | E21: 3190
A22: 7 | B22: Loi Yun Nar Than(VT) | C22: 7368 | D22: 3595 | E22: 3773
A23: 8 | B23: Par Law Par Kei(VT) | C23: 24654 | D23: 11770 | E23: 12884
A24: 9 | B24: Nar Hkaik(VT) | C24: 11832 | D24: 5876 | E24: 5956
A25: 10 | B25: Pong Inn(VT) | C25: 2025 | D25: 986 | E25: 1039
A26: 11 | B26: Nawng Mun(VT) | C26: 7836 | D26: 3823 | E26: 4013
A27: 12 | B27: Loi Put(VT) | C27: 15422 | D27: 7453 | E27: 7969
A28: 13 | B28: Ban Yin(VT) | C28: 13555 | D28: 6654 | E28: 6901

Sheet Kalaw
A1: Shan State,Taunggyi District, Kalaw Township
E2: 29-3-2014
A4: Sr | B4: Ward/Village Tract | C4: Population
C5: Total | D5: Male | E5: Female
B6: Total | C6: 186083 | D6: 93092 | E6: 92991
B8: Ward | C8: =C10+C23 -> 57797 | D8: =D10+D23 -> 28672 | E8: =E10+E23 -> 29125
B10: Kalaw Town | C10: =SUM(C11:C21) -> 19962 | D10: =SUM(D11:D21) -> 9933 | E10: =SUM(E11:E21) -> 10029
A11: 1 | B11: No(1)(W) | C11: 2727 | D11: 1341 | E11: 1386
A12: 2 | B12: No(2)(W) | C12: 1489 | D12: 716 | E12: 773
A13: 3 | B13: No(3)(W) | C13: 3757 | D13: 1878 | E13: 1879
A14: 4 | B14: No(4)(W) | C14: 1379 | D14: 614 | E14: 765
A15: 5 | B15: No(5)(W) | C15: 1101 | D15: 614 | E15: 487
A16: 6 | B16: No(6)(W) | C16: 1612 | D16: 760 | E16: 852
A17: 7 | B17: No(7)(W) | C17: 2318 | D17: 1144 | E17: 1174
A18: 8 | B18: No(8)(W) | C18: 1351 | D18: 643 | E18: 708
A19: 9 | B19: No(9)(W) | C19: 1216 | D19: 607 | E19: 609
A20: 10 | B20: No(10)(W) | C20: 2361 | D20: 1257 | E20: 1104
A21: 11 | B21: No(11)(W) | C21: 651 | D21: 359 | E21: 292
B23: Aung Pann Town | C23: =SUM(C24:C35) -> 37835 | D23: =SUM(D24:D35) -> 18739 | E23: =SUM(E24:E35) -> 19096
A24: 12 | B24: Nyaung Pin Htaung(W) | C24: 5959 | D24: 2891 | E24: 3068
A25: 13 | B25: Hle Yoe(W) | C25: 3430 | D25: 1758 | E25: 1672
A26: 14 | B26: Ywar Ngan Su(W) | C26: 2205 | D26: 1017 | E26: 1188
A27: 15 | B27: No(1)(W) | C27: 549 | D27: 255 | E27: 294
A28: 16 | B28: No(2)(W) | C28: 880 | D28: 386 | E28: 494
A29: 17 | B29: Moe Kaung(W) | C29: 2568 | D29: 1315 | E29: 1253
A30: 18 | B30: No(3)(W) | C30: 6357 | D30: 3163 | E30: 3194
A31: 19 | B31: No(4)(W) | C31: 831 | D31: 379 | E31: 452
A32: 20 | B32: Let Ma Pin(W) | C32: 1469 | D32: 668 | E32: 801
A33: 21 | B33: Myo Haung(W) | C33: 5728 | D33: 2854 | E33: 2874
A34: 22 | B34: Min Ga Lar(W) | C34: 3793 | D34: 1841 | E34: 1952
A35: 23 | B35: Ywar Thit(W) | C35: 4066 | D35: 2212 | E35: 1854
B36: Village Tract | C36: =SUM(C37:C61) -> 128286 | D36: =SUM(D37:D61) -> 64420 | E36: =SUM(E37:E61) -> 63866
A37: 1 | B37: La Mong(VT) | C37: 3350 | D37: 1700 | E37: 1650
A38: 2 | B38: Nang Naing(VT) | C38: 2701 | D38: 1435 | E38: 1266
A39: 3 | B39: Loi An(VT) | C39: 5254 | D39: 2783 | E39: 2471
A40: 4 | B40: Myin Ma Hti(VT) | C40: 4494 | D40: 2243 | E40: 2251
A41: 5 | B41: Taung Lar(VT) | C41: 2904 | D41: 1482 | E41: 1422
A42: 6 | B42: Taung Kwe(VT) | C42: 2141 | D42: 1118 | E42: 1023
A43: 7 | B43: Wet Hpyu Yae(VT) | C43: 2784 | D43: 1397 | E43: 1387
A44: 8 | B44: Shwe Min Hpone(VT) | C44: 9220 | D44: 5221 | E44: 3999
...

Sheet Pindaya
A1: Shan State,Taunggyi District, Pindaya Township
E2: 29-3-2014
A4: Sr | B4: Ward/Village Tract | C4: Population
C5: Total | D5: Male | E5: Female
B6: Total | C6: 79303 | D6: 38468 | E6: 40835
B8: Ward | C8: =SUM(C9:C20) -> 10762 | D8: =SUM(D9:D20) -> 5161 | E8: =SUM(E9:E20) -> 5601
A9: 1 | B9: Shan(W) | C9: 1011 | D9: 463 | E9: 548
A10: 2 | B10: Zay Tan(W) | C10: 1356 | D10: 649 | E10: 707
A11: 3 | B11: Sin Gaung(W) | C11: 1032 | D11: 510 | E11: 522
A12: 4 | B12: Aw Yaw(W) | C12: 1474 | D12: 691 | E12: 783
A13: 5 | B13: Sue Bo Kone(W) | C13: 810 | D13: 392 | E13: 418
A14: 6 | B14: Ywar Thit(W) | C14: 1315 | D14: 685 | E14: 630
A15: 7 | B15: Ywar Nge(W) | C15: 550 | D15: 260 | E15: 290
A16: 8 | B16: Haw Kone(W) | C16: 759 | D16: 387 | E16: 372
A17: 9 | B17: Ah Nauk(W) | C17: 560 | D17: 273 | E17: 287
A18: 10 | B18: Pauk Taw(W) | C18: 450 | D18: 202 | E18: 248
A19: 11 | B19: Hgnet Pyaw Taw(W) | C19: 1042 | D19: 463 | E19: 579
A20: 12 | B20: Pyi Taw Thar(W) | C20: 403 | D20: 186 | E20: 217
B21: Village Tract | C21: =SUM(C22:C48) -> 68541 | D21: =SUM(D22:D48) -> 33307 | E21: =SUM(E22:E48) -> 35234
A22: 1 | B22: Htwet Ni(VT) | C22: 1619 | D22: 782 | E22: 837
A23: 2 | B23: Thit Ae Pin(VT) | C23: 1809 | D23: 832 | E23: 977
A24: 3 | B24: Taung Paw Gyi(VT) | C24: 3225 | D24: 1568 | E24: 1657
A25: 4 | B25: Yae Hpyu(VT) | C25: 1900 | D25: 886 | E25: 1014
A26: 5 | B26: Kyauk Su(VT) | C26: 1481 | D26: 699 | E26: 782
A27: 6 | B27: Htei Thun(VT) | C27: 1384 | D27: 637 | E27: 747
A28: 7 | B28: Me Nei Taung(VT) | C28: 3025 | D28: 1496 | E28: 1529
A29: 8 | B29: Shwe Pu Htoe(VT) | C29: 2106 | D29: 1049 | E29: 1057
A30: 9 | B30: Pan Sit(VT) | C30: 3262 | D30: 1606 | E30: 1656
A31: 10 | B31: Thein Kone(VT) | C31: 1518 | D31: 727 | E31: 791
A32: 11 | B32: Pin Pyaw(VT) | C32: 2378 | D32: 1138 | E32: 1240
A33: 12 | B33: Taung Shey(VT) | C33: 2110 | D33: 1053 | E33: 1057
... A48: 27 | B48: Myay Char Chaint(VT) | C48: 1712 | D48: 823 | E48: 889

Sheet Ywangan
A1: Shan State,Taunggyi District, Ywarngan Township
E2: 29-3-2014
A4: Sr | B4: Ward/Village Tract | C4: Population
C5: Total | D5: Male | E5: Female
B6: Total | C6: 82532 | D6: 41049 | E6: 41483
B8: Ward | C8: =SUM(C9:C11) -> 4517 | D8: =SUM(D9:D11) -> 2220 | E8: =SUM(E9:E11) -> 2297
A9: 1 | B9: Zay Tan(W) | C9: 2587 | D9: 1238 | E9: 1349
A10: 2 | B10: Myo Kone(W) | C10: 666 | D10: 369 | E10: 297
A11: 3 | B11: Ywar Ma(W) | C11: 1264 | D11: 613 | E11: 651
B12: Village Tract | C12: =SUM(C13:C40) -> 78015 | D12: =SUM(D13:D40) -> 38829 | E12: =SUM(E13:E40) -> 39186
A13: 1 | B13: Nwar Ban Gyi(VT) | C13: 3203 | D13: 1558 | E13: 1645
A14: 2 | B14: Kyauk Hmyaung(VT) | C14: 4803 | D14: 2300 | E14: 2503
A15: 3 | B15: Kyauk Gu Pyin(VT) | C15: 2934 | D15: 1405 | E15: 1529
A16: 4 | B16: Doke Toe Yae(VT) | C16: 1682 | D16: 863 | E16: 819
A17: 5 | B17: Lin Way(VT) | C17: 2386 | D17: 1168 | E17: 1218
A18: 6 | B18: Ta Pin Pyaw(VT) | C18: 960 | D18: 481 | E18: 479
A19: 7 | B19: Myo Gyi(VT) | C19: 4511 | D19: 2356 | E19: 2155
A20: 8 | B20: Inn Kone Ngar Su(VT) | C20: 850 | D20: 423 | E20: 427
A21: 9 | B21: Kyun Gyi(VT) | C21: 2138 | D21: 1117 | E21: 1021
A22: 10 | B22: Se(VT) | C22: 2065 | D22: 1078 | E22: 987
A23: 11 | B23: Htee Hlaing(VT) | C23: 918 | D23: 454 | E23: 464
A24: 12 | B24: Thein Kone(VT) | C24: 5013 | D24: 2439 | E24: 2574
... A40: 28 | B40: Nan Hkon(VT) | C40: 1865 | D40: 906 | E40: 959

Sheet Yatsauk
A1: Shan State,Taunggyi District, Yatsauk Township
E2: 29-3-2014
A4: Sr | B4: Ward/Village Tract | C4: Population
C5: Total | D5: Male | E5: Female
B6: Total | C6: 126567 | D6: 64961 | E6: 61606
B8: Ward | C8: =SUM(C9:C16) -> 29533 | D8: =SUM(D9:D16) -> 16175 | E8: =SUM(E9:E16) -> 13358
A9: 1 | B9: Taung Kwet Thit(W) | C9: 2906 | D9: 1384 | E9: 1522
A10: 2 | B10: Myo Kone(W) | C10: 2594 | D10: 1237 | E10: 1357
A11: 3 | B11: Oke Ta Tar(W) | C11: 3837 | D11: 1795 | E11: 2042
A12: 4 | B12: Zay Tan(W) | C12: 2512 | D12: 1356 | E12: 1156
A13: 5 | B13: Myauk Kwet Thit(W) | C13: 1315 | D13: 617 | E13: 698
A14: 6 | B14: Ba Htu(W) | C14: 9357 | D14: 6288 | E14: 3069
A15: 7 | B15: Zaw Gyi(W) | C15: 2855 | D15: 1362 | E15: 1493
A16: 8 | B16: Myo Oo(W) | C16: 4157 | D16: 2136 | E16: 2021
B17: Village Tract | C17: =SUM(C18:C30) -> 97034 | D17: =SUM(D18:D30) -> 48786 | E17: =SUM(E18:E30) -> 48248
A18: 1 | B18: Loi Koe(VT) | C18: 2836 | D18: 1434 | E18: 1402
A19: 2 | B19: Hway(VT) | C19: 5688 | D19: 2889 | E19: 2799
A20: 3 | B20: Yan Twin Ngar Kyaung(VT) | C20: 36918 | D20: 18451 | E20: 18467
A21: 4 | B21: Myin Taung(VT) | C21: 5030 | D21: 2459 | E21: 2571
A22: 5 | B22: Ma Gyi Kone(VT) | C22: 4344 | D22: 2176 | E22: 2168
A23: 6 | B23: Kaung Boet(VT) | C23: 8608 | D23: 4317 | E23: 4291
A24: 7 | B24: Ah Lel Chaung(VT) | C24: 5602 | D24: 2832 | E24: 2770
A25: 8 | B25: Hpawng Taw(VT) | C25: 3853 | D25: 1914 | E25: 1939
A26: 9 | B26: Kyauk Taw(VT) | C26: 6498 | D26: 3286 | E26: 3212
A27: 10 | B27: Nan Lwe(VT) | C27: 318 | D27: 166 | E27: 152
A28: 11 | B28: Par Me(VT) | C28: 8872 | D28: 4469 | E28: 4403
A29: 12 | B29: Mar Thea(VT) | C29: 5424 | D29: 2771 | E29: 2653
A30: 13 | B30: Keng Hkam(VT) | C30: 3043 | D30: 1622 | E30: 1421

Sheet Pinlaung
A1: Shan State,Taunggyi District, Pinlaung Township
E2: 29-3-2014
A4: Sr | B4: Ward/Village Tract | C4: Population
C5: Total | D5: Male | E5: Female
B6: Total | C6: 115047 | D6: 57411 | E6: 57636
B8: Ward | C8: =SUM(C9:C18) -> 12629 | D8: =SUM(D9:D18) -> 6531 | E8: =SUM(E9:E18) -> 6098
A9: 1 | B9: Bant Hpei(W) | C9: 605 | D9: 283 | E9: 322
A10: 2 | B10: Hpa Yar(North)(W) | C10: 243 | D10: 136 | E10: 107
A11: 3 | B11: Ah Shey(W) | C11: 1755 | D11: 887 | E11: 868
A12: 4 | B12: Ah Nauk(W) | C12: 935 | D12: 423 | E12: 512
A13: 5 | B13: Zay Tan(W) | C13: 813 | D13: 383 | E13: 430
A14: 6 | B14: Yone Win(W) | C14: 1450 | D14: 731 | E14: 719
A15: 7 | B15: Kan Thar Oo(W) | C15: 1045 | D15: 496 | E15: 549
A16: 8 | B16: Min Ga Lar Kwet Thit(W) | C16: 1064 | D16: 541 | E16: 523
A17: 9 | B17: Koe Khaung(W) | C17: 987 | D17: 537 | E17: 450
A18: 10 | B18: Yinn Hme(W) | C18: 3732 | D18: 2114 | E18: 1618
B19: Village Tract | C19: =SUM(C20:C32) -> 102418 | D19: =SUM(D20:D32) -> 50880 | E19: =SUM(E20:E32) -> 51538
A20: 1 | B20: Pinlaung Gyi(VT) | C20: 2071 | D20: 1055 | E20: 1016
A21: 2 | B21: Bant Bar(VT) | C21: 10337 | D21: 5074 | E21: 5263
A22: 3 | B22: Min Bu(VT) | C22: 5792 | D22: 2852 | E22: 2940
A23: 4 | B23: Taung Hti Bwar(VT) | C23: 6486 | D23: 3123 | E23: 3363
A24: 5 | B24: Hti Pawng(VT) | C24: 10568 | D24: 5186 | E24: 5382
A25: 6 | B25: Tha Pyay Kone(VT) | C25: 7169 | D25: 3805 | E25: 3364
A26: 7 | B26: Sin Taung(VT) | C26: 8766 | D26: 4378 | E26: 4388
A27: 8 | B27: Long Pyin(VT) | C27: 12126 | D27: 5998 | E27: 6128
A28: 9 | B28: Htein Pin(VT) | C28: 9805 | D28: 5255 | E28: 4550
A29: 10 | B29: Pin Mun(VT) | C29: 5761 | D29: 2692 | E29: 3069
A30: 11 | B30: Leint Nyar(VT) | C30: 9649 | D30: 4712 | E30: 4937
A31: 12 | B31: Myauk Hti Bwar(VT) | C31: 6710 | D31: 3208 | E31: 3502
A32: 13 | B32: Nang Toke(VT) | C32: 7178 | D32: 3542 | E32: 3636

Sheet Phekon
A1: Shan State,Taunggyi District, Phekon Township
E2: 29-3-2014
A4: Sr | B4: Ward/Village Tract | C4: Population
C5: Total | D5: Male | E5: Female
B6: Total | C6: 103590 | D6: 52293 | E6: 51297
B8: Ward | C8: =SUM(C9:C15) -> 16546 | D8: =SUM(D9:D15) -> 8357 | E8: =SUM(E9:E15) -> 8189
A9: 1 | B9: Hein Dhamma(W) | C9: 4476 | D9: 2357 | E9: 2119
A10: 2 | B10: Nang Hu(W) | C10: 615 | D10: 300 | E10: 315
A11: 3 | B11: Nyaung Kone(W) | C11: 4973 | D11: 2510 | E11: 2463
A12: 4 | B12: Zay(West)(W) | C12: 2097 | D12: 1038 | E12: 1059
A13: 5 | B13: Zay(East)(W) | C13: 1563 | D13: 762 | E13: 801
A14: 6 | B14: Zay Tan(W) | C14: 420 | D14: 214 | E14: 206
A15: 7 | B15: Myo Kone(W) | C15: 2402 | D15: 1176 | E15: 1226
B16: Village Tract | C16: =SUM(C17:C28) -> 87044 | D16: =SUM(D17:D28) -> 43936 | E16: =SUM(E17:E28) -> 43108
A17: 1 | B17: Moe Bye(VT) | C17: 27262 | D17: 13587 | E17: 13675
A18: 2 | B18: Hkawng Ei(VT) | C18: 7042 | D18: 3520 | E18: 3522
A19: 3 | B19: Kone Hson(VT) | C19: 4420 | D19: 2191 | E19: 2229
A20: 4 | B20: Loi Paw(VT) | C20: 4256 | D20: 2112 | E20: 2144
A21: 5 | B21: Nar Hee(VT) | C21: 2493 | D21: 1278 | E21: 1215
A22: 6 | B22: Ku Yin(VT) | C22: 3581 | D22: 1791 | E22: 1790
A23: 7 | B23: Yi Nwe(VT) | C23: 17640 | D23: 9034 | E23: 8606
A24: 8 | B24: Yi Long Yi Kan(VT) | C24: 5601 | D24: 2779 | E24: 2822
A25: 9 | B25: Thi Kyeik(VT) | C25: 4732 | D25: 2502 | E25: 2230
A26: 10 | B26: Ah Lel Pa Daung/Ah lel Kayan(VT) | C26: 6937 | D26: 3538 | E26: 3399
A27: 11 | B27: Byea Taik/Ka yaw(VT) | C27: 1047 | D27: 537 | E27: 510
A28: 12 | B28: Pekon(Naung Hlaing)(VT) | C28: 2033 | D28: 1067 | E28: 966

Sheet Kyauktalongyi (Sub-Tsp)
A1: Shan State,Taunggyi District,Kyauktalongyi (Sub-Township)
E2: 29-3-2014
A4: Sr | B4: Ward/Village Tract | C4: Population
C5: Total | D5: Male | E5: Female
B6: Total | C6: 56417 | D6: 27246 | E6: 29171
B8: Ward | C8: =SUM(C9:C14) -> 3166 | D8: =SUM(D9:D14) -> 1454 | E8: =SUM(E9:E14) -> 1712
A9: 1 | B9: Ta Pu Yway(W) | C9: 86 | D9: 42 | E9: 44
A10: 2 | B10: Don Ong(W) | C10: 1312 | D10: 602 | E10: 710
A11: 3 | B11: Nawng Long(W) | C11: 580 | D11: 274 | E11: 306
A12: 4 | B12: Hti Long(W) | C12: 438 | D12: 183 | E12: 255
A13: 5 | B13: Lin Hnar(W) | C13: 291 | D13: 138 | E13: 153
A14: 6 | B14: Kaung Wein(W) | C14: 459 | D14: 215 | E14: 244
B15: Village Tract | C15: =SUM(C16:C22) -> 53251 | D15: =SUM(D16:D22) -> 25792 | E15: =SUM(E16:E22) -> 27459
A16: 1 | B16: Nawng Kar(VT) | C16: 6724 | D16: 3321 | E16: 3403
A17: 2 | B17: Ah Thone Taw(VT) | C17: 2751 | D17: 1359 | E17: 1392
A18: 3 | B18: Nar Hee(VT) | C18: 8271 | D18: 3998 | E18: 4273
A19: 4 | B19: Nawng Hke(VT) | C19: 7598 | D19: 3598 | E19: 4000
A20: 5 | B20: Kat Ku(VT) | C20: 11293 | D20: 5473 | E20: 5820
A21: 6 | B21: Pin Tun(VT) | C21: 9614 | D21: 4661 | E21: 4953
A22: 7 | B22: Nawng Pyit(VT) | C22: 7000 | D22: 3382 | E22: 3618

Sheet Indaw (Sub-Tsp)
A1: Shan State,Taunggyi District,Indaw(Sub-Township)
E2: 29-3-2014
A4: Sr | B4: Ward/Village Tract | C4: Population
C5: Total | D5: Male | E5: Female
B6: Total | C6: 38163 | D6: 19365 | E6: 18798
B8: Ward | C8: =SUM(C9:C14) -> 8252 | D8: =SUM(D9:D14) -> 4171 | E8: =SUM(E9:E14) -> 4081
A9: 1 | B9: No(1)(W) | C9: 1490 | D9: 831 | E9: 659
A10: 2 | B10: No(2)(W) | C10: 653 | D10: 314 | E10: 339
A11: 3 | B11: No(3)(W) | C11: 1516 | D11: 727 | E11: 789
A12: 4 | B12: No(4)(W) | C12: 1211 | D12: 608 | E12: 603
A13: 5 | B13: No(5)(W) | C13: 1115 | D13: 539 | E13: 576
A14: 6 | B14: No(6)(W) | C14: 2267 | D14: 1152 | E14: 1115
B15: Village Tract | C15: =SUM(C16:C20) -> 29911 | D15: =SUM(D16:D20) -> 15194 | E15: =SUM(E16:E20) -> 14717
A16: 1 | B16: Ohn Kwe(VT) | C16: 3117 | D16: 1617 | E16: 1500
A17: 2 | B17: Nang Kaung Hmu(VT) | C17: 779 | D17: 409 | E17: 370
A18: 3 | B18: Kyauk Gu(VT) | C18: 15607 | D18: 7924 | E18: 7683
A19: 4 | B19: Nawng Woe(VT) | C19: 3084 | D19: 1589 | E19: 1495
A20: 5 | B20: Nawng Long(VT) | C20: 7324 | D20: 3655 | E20: 3669

Sheet Naungtayar (Sub-Tsp)
A1: Shan State,Taunggyi District, Naungtayar(Sub-Township)
E2: 29-3-2014
A4: Sr | B4: Ward/Village Tract | C4: Population
C5: Total | D5: Male | E5: Female
B6: Total | C6: 77210 | D6: 37947 | E6: 39263
B8: Ward | C8: =SUM(C9:C11) -> 4861 | D8: =SUM(D9:D11) -> 2425 | E8: =SUM(E9:E11) -> 2436
A9: 1 | B9: No(1)(W) | C9: 3326 | D9: 1609 | E9: 1717
A10: 2 | B10: No(2)(W) | C10: 328 | D10: 153 | E10: 175
A11: 3 | B11: No(3)(W) | C11: 1207 | D11: 663 | E11: 544
B12: Village Tract | C12: =SUM(C13:C24) -> 72349 | D12: =SUM(D13:D24) -> 35522 | E12: =SUM(E13:E24) -> 36827
A13: 1 | B13: Thi Kyit(VT) | C13: 11284 | D13: 5599 | E13: 5685
A14: 2 | B14: Nan Pu Lin(VT) | C14: 6621 | D14: 3226 | E14: 3395
A15: 3 | B15: Pawt In(VT) | C15: 9099 | D15: 4417 | E15: 4682
A16: 4 | B16: Myin Kwin(VT) | C16: 6019 | D16: 3134 | E16: 2885
A17: 5 | B17: Lel Maw(VT) | C17: 9512 | D17: 4492 | E17: 5020
A18: 6 | B18: Nawng Pi(VT) | C18: 5268 | D18: 2541 | E18: 2727
A19: 7 | B19: Pawt Yar(VT) | C19: 3901 | D19: 1862 | E19: 2039
A20: 8 | B20: Long Poe(VT) | C20: 1972 | D20: 1005 | E20: 967
A21: 9 | B21: Bant Pyin(VT) | C21: 3089 | D21: 1456 | E21: 1633
A22: 10 | B22: Hpa Yar Hpyu(VT) | C22: 6632 | D22: 3174 | E22: 3458
A23: 11 | B23: Hmway Pyin(VT) | C23: 3583 | D23: 1918 | E23: 1665
A24: 12 | B24: Pin Hkin(VT) | C24: 5369 | D24: 2698 | E24: 2671

Sheet Loilem
A1: Shan State, Loilem District, Loilem Township
E2: 29-3-2014
A4: Sr | B4: Ward/Village Tract | C4: Population
C5: Total | D5: Male | E5: Female
B6: Total | C6: 52371 | D6: 25231 | E6: 27140
B8: Ward | C8: =SUM(C9:C12) -> 13460 | D8: =SUM(D9:D12) -> 6417 | E8: =SUM(E9:E12) -> 7043
A9: 1 | B9: No(1)(W) | C9: 2206 | D9: 1060 | E9: 1146
A10: 2 | B10: No(2)(W) | C10: 3587 | D10: 1715 | E10: 1872
A11: 3 | B11: No(3)(W) | C11: 2391 | D11: 1121 | E11: 1270
A12: 4 | B12: No(4)(W) | C12: 5276 | D12: 2521 | E12: 2755
B13: Village Tract | C13: =SUM(C14:C24) -> 38911 | D13: =SUM(D14:D24) -> 18814 | E13: =SUM(E14:E24) -> 20097
A14: 1 | B14: Loilen (East)(VT) | C14: 2985 | D14: 1420 | E14: 1565
A15: 2 | B15: Pang Woe(VT) | C15: 1828 | D15: 878 | E15: 950
A16: 3 | B16: Taung Nauk(VT) | C16: 3901 | D16: 1872 | E16: 2029
A17: 4 | B17: Mong Pun(VT) | C17: 8124 | D17: 3974 | E17: 4150
A18: 5 | B18: Sin Chay Hpone(VT) | C18: 2594 | D18: 1240 | E18: 1354
A19: 6 | B19: Kone Yaw(VT) | C19: 2138 | D19: 1163 | E19: 975
A20: 7 | B20: Hkauk Nwet(VT) | C20: 3307 | D20: 1550 | E20: 1757
A21: 8 | B21: Hway Tauk(VT) | C21: 5452 | D21: 2608 | E21: 2844
A22: 9 | B22: Nar Yang(VT) | C22: 3017 | D22: 1427 | E22: 1590
A23: 10 | B23: Nawng Lai Mu Hpeik(VT) | C23: 3605 | D23: 1721 | E23: 1884
A24: 11 | B24: Nam Hta Mo(VT) | C24: 1960 | D24: 961 | E24: 999

Sheet Lahecha
A1: Shan State, Loilem District, Le`char Township
E2: 29-3-2014
A4: Sr | B4: Ward/Village Tract | C4: Population
C5: Total | D5: Male | E5: Female
B6: Total | C6: 48831 | D6: 23646 | E6: 25185
B8: Ward | C8: =SUM(C9:C12) -> 8001 | D8: =SUM(D9:D12) -> 3845 | E8: =SUM(E9:E12) -> 4156
A9: 1 | B9: Ho Wein Pauk Pwee(W) | C9: 1935 | D9: 988 | E9: 947
A10: 2 | B10: Hing Nawng (North)(W) | C10: 1160 | D10: 551 | E10: 609
A11: 3 | B11: Hing Nawng (South)(W) | C11: 1593 | D11: 778 | E11: 815
A12: 4 | B12: Ho Lein Pauk Pwe(W) | C12: 3313 | D12: 1528 | E12: 1785
B13: Village Tract | C13: =SUM(C14:C32) -> 40830 | D13: =SUM(D14:D32) -> 19801 | E13: =SUM(E14:E32) -> 21029
A14: 1 | B14: Laikha(Myoma)(VT) | C14: 9985 | D14: 4935 | E14: 5050
A15: 2 | B15: Nawng Kaw(VT) | C15: 1259 | D15: 598 | E15: 661
A16: 3 | B16: He Hseng(VT) | C16: 983 | D16: 480 | E16: 503
A17: 4 | B17: Pang Sang(VT) | C17: 2718 | D17: 1290 | E17: 1428
A18: 5 | B18: Wan Hai(VT) | C18: 2815 | D18: 1355 | E18: 1460
A19: 6 | B19: Pong Nay(VT) | C19: 1585 | D19: 768 | E19: 817
A20: 7 | B20: Wan Seit(VT) | C20: 1580 | D20: 756 | E20: 824
A21: 8 | B21: Pong Taik(VT) | C21: 2222 | D21: 1141 | E21: 1081
A22: 9 | B22: Nar Man(VT) | C22: 3340 | D22: 1699 | E22: 1641
A23: 10 | B23: Wan Hti(VT) | C23: 1594 | D23: 743 | E23: 851
A24: 11 | B24: Wan Sang(VT) | C24: 1420 | D24: 683 | E24: 737
A25: 12 | B25: Wan Lay(VT) | C25: 1705 | D25: 802 | E25: 903
... A32: 19 | B32: Pang Tan(VT) | C32: 1811 | D32: 853 | E32: 958

Sheet Nanhsam(South)
A1: Shan State, Loilem District, Nanhsam(South) Township
E2: 29-3-2014
A4: Sr | B4: Ward/Village Tract | C4: Population
C5: Total | D5: Male | E5: Female
B6: Total | C6: 92302 | D6: 46542 | E6: 45760
B8: Ward | C8: =SUM(C9:C13) -> 23792 | D8: =SUM(D9:D13) -> 11946 | E8: =SUM(E9:E13) -> 11846
A9: 1 | B9: No(1)(W) | C9: 5243 | D9: 2529 | E9: 2714
A10: 2 | B10: No(2)(W) | C10: 4726 | D10: 2499 | E10: 2227
A11: 3 | B11: No(3)(W) | C11: 2685 | D11: 1322 | E11: 1363
A12: 4 | B12: No(4)(W) | C12: 7756 | D12: 3914 | E12: 3842
A13: 5 | B13: No(5)(W) | C13: 3382 | D13: 1682 | E13: 1700
B14: Village Tract | C14: =SUM(C15:C29) -> 68510 | D14: =SUM(D15:D29) -> 34596 | E14: =SUM(E15:E29) -> 33914
A15: 1 | B15: Nansang/Wang Po(VT) | C15: 3879 | D15: 1932 | E15: 1947
A16: 2 | B16: Wan Nawng(VT) | C16: 3854 | D16: 1900 | E16: 1954
A17: 3 | B17: Loi La(VT) | C17: 1851 | D17: 892 | E17: 959
A18: 4 | B18: Mat Mon Mun(VT) | C18: 7547 | D18: 3920 | E18: 3627
A19: 5 | B19: Ah Hmat Ngar(VT) | C19: 5108 | D19: 2701 | E19: 2407
A20: 6 | B20: Wan Ping(VT) | C20: 2111 | D20: 1016 | E20: 1095
A21: 7 | B21: Hai Hpat(VT) | C21: 3901 | D21: 1897 | E21: 2004
A22: 8 | B22: Loi Ye(VT) | C22: 2797 | D22: 1416 | E22: 1381
A23: 9 | B23: Nawng Hee(VT) | C23: 7036 | D23: 3474 | E23: 3562
A24: 10 | B24: Mong Seik(VT) | C24: 3909 | D24: 1996 | E24: 1913
A25: 11 | B25: Nam Lit(VT) | C25: 6068 | D25: 3082 | E25: 2986
A26: 12 | B26: Hai Nar Gyi(VT) | C26: 8823 | D26: 4537 | E26: 4286
... A29: 15 | B29: Ho Yang(VT) | C29: 2137 | D29: 1050 | E29: 1087

Sheet Kunhing
A1: Shan State, Loilem District, Kunhing Township
E2: 29-3-2014
A4: Sr | B4: Ward/Village Tract | C4: Population
C5: Total | D5: Male | E5: Female
B6: Total | C6: 21823 | D6: 10872 | E6: 10951
B8: Ward | C8: =SUM(C9:C13) -> 7581 | D8: =SUM(D9:D13) -> 3767 | E8: =SUM(E9:E13) -> 3814
A9: 1 | B9: No(1)(W) | C9: 463 | D9: 208 | E9: 255
A10: 2 | B10: No(2)(W) | C10: 493 | D10: 227 | E10: 266
A11: 3 | B11: No(3)(W) | C11: 4296 | D11: 2188 | E11: 2108
A12: 4 | B12: No(4)(W) | C12: 1483 | D12: 707 | E12: 776
A13: 5 | B13: No(5)(W) | C13: 846 | D13: 437 | E13: 409
B14: Village Tract | C14: =SUM(C15:C23) -> 14242 | D14: =SUM(D15:D23) -> 7105 | E14: =SUM(E15:E23) -> 7137
A15: 1 | B15: Kunhing(Myoma)(VT) | C15: 5229 | D15: 2615 | E15: 2614
A16: 2 | B16: Laik Tat(VT) | C16: 5895 | D16: 2983 | E16: 2912
A17: 3 | B17: Kyein Hkam(VT) | C17: 193 | D17: 90 | E17: 103
A18: 4 | B18: Wan Law(VT) | C18: 1331 | D18: 628 | E18: 703
A19: 5 | B19: Ngar Ngai(VT) | C19: 303 | D19: 144 | E19: 159
A20: 6 | B20: Loi Keng(VT) | C20: 313 | D20: 139 | E20: 174
A21: 7 | B21: Nar Pwe(VT) | C21: 197 | D21: 102 | E21: 95
A22: 8 | B22: Kun Pu(VT) | C22: 204 | D22: 100 | E22: 104
A23: 9 | B23: Hseng Hkawng(VT) | C23: 577 | D23: 304 | E23: 273

Sheet Kehsi
A1: Shan State, Loilem District, Kehsi Township
E2: 29-3-2014
A4: Sr | B4: Ward/Village Tract | C4: Population
C5: Total | D5: Male | E5: Female
B6: Total | C6: 44500 | D6: 20905 | E6: 23595
B8: Ward | C8: =SUM(C9:C14) -> 4282 | D8: =SUM(D9:D14) -> 2105 | E8: =SUM(E9:E14) -> 2177
A9: 1 | B9: Wan Kang(W) | C9: 333 | D9: 146 | E9: 187
A10: 2 | B10: Kang Pang(W) | C10: 530 | D10: 271 | E10: 259
A11: 3 | B11: Zay(W) | C11: 1352 | D11: 643 | E11: 709
A12: 4 | B12: Haw Kone(W) | C12: 894 | D12: 439 | E12: 455
A13: 5 | B13: Long Pu(W) | C13: 1011 | D13: 525 | E13: 486
A14: 6 | B14: Ho Hko(W) | C14: 162 | D14: 81 | E14: 81
B15: Village Tract | C15: =SUM(C16:C32) -> 40218 | D15: =SUM(D16:D32) -> 18800 | E15: =SUM(E16:E32) -> 21418
A16: 1 | B16: Pang Se(VT) | C16: 2373 | D16: 1097 | E16: 1276
A17: 2 | B17: Hpet Nam(VT) | C17: 1506 | D17: 713 | E17: 793
A18: 3 | B18: Pang Lawt(VT) | C18: 1119 | D18: 547 | E18: 572
A19: 4 | B19: Wan Hpwee(VT) | C19: 2247 | D19: 1025 | E19: 1222
A20: 5 | B20: Wan Hkont(VT) | C20: 1151 | D20: 530 | E20: 621
A21: 6 | B21: Hseng Lai(VT) | C21: 2159 | D21: 992 | E21: 1167
A22: 7 | B22: Har Wan(VT) | C22: 3427 | D22: 1607 | E22: 1820
A23: 8 | B23: Mong Nin(VT) | C23: 1426 | D23: 669 | E23: 757
A24: 9 | B24: Wan Wa(VT) | C24: 1277 | D24: 603 | E24: 674
A25: 10 | B25: Keng Lin(VT) | C25: 1899 | D25: 917 | E25: 982
A26: 11 | B26: Wan Chin(VT) | C26: 1746 | D26: 797 | E26: 949
A27: 12 | B27: Wan Wut(VT) | C27: 5120 | D27: 2424 | E27: 2696
... A32: 17 | B32: Mong Kawng(VT) | C32: 2036 | D32: 924 | E32: 1112

Sheet Mongkai
A1: Shan State, Loilem District, Mongkai Township
E2: 29-3-2014
A4: Sr | B4: Ward/Village Tract | C4: Population
C5: Total | D5: Male | E5: Female
B6: Total | C6: 74294 | D6: 35122 | E6: 39172
B8: Ward | C8: =SUM(C9:C13) -> 10620 | D8: =SUM(D9:D13) -> 5156 | E8: =SUM(E9:E13) -> 5464
A9: 1 | B9: No(1)(W) | C9: 3042 | D9: 1442 | E9: 1600
A10: 2 | B10: No(2)(W) | C10: 1533 | D10: 776 | E10: 757
A11: 3 | B11: No(3)(W) | C11: 1460 | D11: 752 | E11: 708
A12: 4 | B12: No(4)(W) | C12: 3161 | D12: 1507 | E12: 1654
A13: 5 | B13: No(5)(W) | C13: 1424 | D13: 679 | E13: 745
B14: Village Tract | C14: =SUM(C15:C38) -> 63674 | D14: =SUM(D15:D38) -> 29966 | E14: =SUM(E15:E38) -> 33708
A15: 1 | B15: Myo Ma Sin Chay Hpone (North)(VT) | C15: 1041 | D15: 482 | E15: 559
A16: 2 | B16: Myo Ma Sin Chay Hpone (East)(VT) | C16: 1002 | D16: 499 | E16: 503
A17: 3 | B17: Wan Hway Aum(VT) | C17: 1129 | D17: 546 | E17: 583
A18: 4 | B18: Nam Hu(VT) | C18: 1381 | D18: 681 | E18: 700
A19: 5 | B19: Wan Long(VT) | C19: 1863 | D19: 865 | E19: 998
A20: 6 | B20: Wan Hway Long(VT) | C20: 2785 | D20: 1256 | E20: 1529
A21: 7 | B21: Hkay Ong Awayt(VT) | C21: 1311 | D21: 618 | E21: 693
A22: 8 | B22: Hsan Har(VT) | C22: 663 | D22: 315 | E22: 348
A23: 9 | B23: Yang Nang(VT) | C23: 1986 | D23: 961 | E23: 1025
A24: 10 | B24: Mong Hkun(VT) | C24: 3024 | D24: 1342 | E24: 1682
A25: 11 | B25: Kone Long(VT) | C25: 4236 | D25: 2069 | E25: 2167
A26: 12 | B26: Loke Tawng(VT) | C26: 1106 | D26: 517 | E26: 589
... A38: 24 | B38: Nar Hwei(VT) | C38: 2297 | D38: 1102 | E38: 1195

Sheet Mineshu
A1: Shan State, Loilem District, Mineshu Township
E2: 29-3-2014
A4: Sr | B4: Ward/Village Tract | C4: Population
C5: Total | D5: Male | E5: Female
B6: Total | C6: 42695 | D6: 20363 | E6: 22332
B8: Ward | C8: =SUM(C9:C12) -> 9809 | D8: =SUM(D9:D12) -> 4839 | E8: =SUM(E9:E12) -> 4970
A9: 1 | B9: No(1)(W) | C9: 1483 | D9: 755 | E9: 728
A10: 2 | B10: No(2)(W) | C10: 3142 | D10: 1575 | E10: 1567
A11: 3 | B11: No(3)(W) | C11: 753 | D11: 329 | E11: 424
A12: 4 | B12: No(4)(W) | C12: 4431 | D12: 2180 | E12: 2251
B14: Village Tract | C14: =SUM(C15:C27) -> 32886 | D14: =SUM(D15:D27) -> 15524 | E14: =SUM(E15:E27) -> 17362
A15: 1 | B15: Myoma Pang Swea(VT) | C15: 3413 | D15: 1683 | E15: 1730
A16: 2 | B16: Nar Sang(VT) | C16: 1127 | D16: 541 | E16: 586
A17: 3 | B17: Maw Mayt(VT) | C17: 2607 | D17: 1206 | E17: 1401
A18: 4 | B18: Loi Naing(VT) | C18: 1765 | D18: 798 | E18: 967
A19: 5 | B19: Nam Tawng(VT) | C19: 3025 | D19: 1449 | E19: 1576
A20: 6 | B20: He Par(VT) | C20: 3576 | D20: 1708 | E20: 1868
A21: 7 | B21: Wan Hsawt(VT) | C21: 4592 | D21: 2159 | E21: 2433
A22: 8 | B22: Hpar Ya(VT) | C22: 2334 | D22: 1102 | E22: 1232
A23: 9 | B23: Wan Loi(VT) | C23: 1671 | D23: 804 | E23: 867
A24: 10 | B24: Mong Awt(VT) | C24: 2082 | D24: 899 | E24: 1183
A25: 11 | B25: Nar Waun(VT) | C25: 1931 | D25: 933 | E25: 998
A26: 12 | B26: Nawng Et(VT) | C26: 2499 | D26: 1190 | E26: 1309
A27: 13 | B27: Kun Kyawng(VT) | C27: 2264 | D27: 1052 | E27: 1212

Sheet Panglong (Sub-Tsp)
A1: Shan State, Loilem District, Panglong(Sub-Township)
E2: 29-3-2014
A4: Sr | B4: Ward/Village Tract | C4: Population
C5: Total | D5: Male | E5: Female
B6: Total | C6: 72186 | D6: 35328 | E6: 36858
B8: Ward | C8: =SUM(C9:C12) -> 27115 | D8: =SUM(D9:D12) -> 13615 | E8: =SUM(E9:E12) -> 13500
A9: 1 | B9: No(1)(W) | C9: 5514 | D9: 2735 | E9: 2779
A10: 2 | B10: No(2)(W) | C10: 11199 | D10: 5616 | E10: 5583
A11: 3 | B11: No(3)(W) | C11: 4125 | D11: 1925 | E11: 2200
A12: 4 | B12: No(4)(W) | C12: 6277 | D12: 3339 | E12: 2938
B13: Village Tract | C13: =SUM(C14:C21) -> 45071 | D13: =SUM(D14:D21) -> 21713 | E13: =SUM(E14:E21) -> 23358
A14: 1 | B14: Pang Mont(VT) | C14: 4279 | D14: 2088 | E14: 2191
A15: 2 | B15: Nar Tit (VT) | C15: 5619 | D15: 2549 | E15: 3070
A16: 3 | B16: He Nang(VT) | C16: 6193 | D16: 3005 | E16: 3188
A17: 4 | B17: Hsa Nin(VT) | C17: 4830 | D17: 2338 | E17: 2492
A18: 5 | B18: Tant Ae(VT) | C18: 2319 | D18: 1123 | E18: 1196
A19: 6 | B19: Pinlon (East)(VT) | C19: 2879 | D19: 1480 | E19: 1399
A20: 7 | B20: Nawng Lai(VT) | C20: 6852 | D20: 3326 | E20: 3526
A21: 8 | B21: Hsa Hawng(VT) | C21: 12100 | D21: 5804 | E21: 6296

Sheet Kholan(Sub-Tsp)
A1: Shan State, Loilem District, Kholan(Sub-Township)
E2: 29-3-2014
A4: Sr | B4: Ward/Village Tract | C4: Population
C5: Total | D5: Male | E5: Female
B6: Total | C6: 24659 | D6: 12749 | E6: 11910
B8: Ward | C8: =SUM(C9:C14) -> 9470 | D8: =SUM(D9:D14) -> 4719 | E8: =SUM(E9:E14) -> 4751
A9: 1 | B9: No(1)(W) | C9: 2657 | D9: 1381 | E9: 1276
A10: 2 | B10: No(2)(W) | C10: 2039 | D10: 1043 | E10: 996
A11: 3 | B11: No(3)(W) | C11: 1581 | D11: 752 | E11: 829
A12: 4 | B12: No(4)(W) | C12: 1101 | D12: 515 | E12: 586
A13: 5 | B13: No(5)(W) | C13: 494 | D13: 206 | E13: 288
A14: 6 | B14: No(6)(W) | C14: 1598 | D14: 822 | E14: 776
B15: Village Tract | C15: =SUM(C16:C20) -> 15189 | D15: =SUM(D16:D20) -> 8030 | E15: =SUM(E16:E20) -> 7159
A16: 1 | B16: Ho Nawng (VT) | C16: 3139 | D16: 1546 | E16: 1593
A17: 2 | B17: Hai Laik(VT) | C17: 3581 | D17: 2220 | E17: 1361
A18: 3 | B18: Teng Huong(VT) | C18: 704 | D18: 368 | E18: 336
A19: 4 | B19: Nar Pwe(VT) | C19: 2683 | D19: 1291 | E19: 1392
A20: 5 | B20: Hko Aut(VT) | C20: 5082 | D20: 2605 | E20: 2477

Sheet Karli(sub-Tsp)
A1: Shan State, Loilem District, Karli(Sub-Township)
E2: 29-3-2014
A4: Sr | B4: Ward/Village Tract | C4: Population
C5: Total | D5: Male | E5: Female
B6: Total | C6: 31580 | D6: 15751 | E6: 15829
B8: Ward | C8: =SUM(C9:C14) -> 7779 | D8: =SUM(D9:D14) -> 3870 | E8: =SUM(E9:E14) -> 3909
A9: 1 | B9: No(1)(W) | C9: 1980 | D9: 944 | E9: 1036
A10: 2 | B10: No(2)(W) | C10: 1204 | D10: 564 | E10: 640
A11: 3 | B11: No(3)(W) | C11: 1827 | D11: 900 | E11: 927
A12: 4 | B12: No(4)(W) | C12: 1382 | D12: 755 | E12: 627
A13: 5 | B13: No(5)(W) | C13: 987 | D13: 504 | E13: 483
A14: 6 | B14: No(6)(W) | C14: 399 | D14: 203 | E14: 196
B15: Village Tract | C15: =SUM(C16:C20) -> 23801 | D15: =SUM(D16:D20) -> 11881 | E15: =SUM(E16:E20) -> 11920
A16: 1 | B16: Keng Lun(VT) | C16: 4518 | D16: 2117 | E16: 2401
A17: 2 | B17: Ho Pang(VT) | C17: 8552 | D17: 4427 | E17: 4125
A18: 3 | B18: Tar Kaw(VT) | C18: 4044 | D18: 2032 | E18: 2012
A19: 4 | B19: Wan Pat(VT) | C19: 6018 | D19: 2980 | E19: 3038
A20: 5 | B20: Wan Hpai (VT) | C20: 669 | D20: 325 | E20: 344

Sheet Minenaung(Sub-Tsp)
A1: Shan State, Loilem District, Minenaung(Sub-Township)
E2: 29-3-2014
A4: Sr | B4: Ward/Village Tract | C4: Population
C5: Total | D5: Male | E5: Female
B6: Total | C6: 29864 | D6: 14519 | E6: 15345
B8: Ward | C8: =SUM(C9:C13) -> 4048 | D8: =SUM(D9:D13) -> 1927 | E8: =SUM(E9:E13) -> 2121
A9: 1 | B9: No(1)(W) | C9: 1060 | D9: 500 | E9: 560
A10: 2 | B10: No(2)(W) | C10: 656 | D10: 290 | E10: 366
A11: 3 | B11: No(3)(W) | C11: 1076 | D11: 554 | E11: 522
A12: 4 | B12: No(4)(W) | C12: 788 | D12: 375 | E12: 413
A13: 5 | B13: No(5)(W) | C13: 468 | D13: 208 | E13: 260
B14: Village Tract | C14: =SUM(C15:C28) -> 25816 | D14: =SUM(D15:D28) -> 12592 | E14: =SUM(E15:E28) -> 13224
A15: 1 | B15: Nar Kan(VT) | C15: 2129 | D15: 1243 | E15: 886
A16: 2 | B16: Nawng Ae(VT) | C16: 985 | D16: 494 | E16: 491
A17: 3 | B17: Wein Kawng(VT) | C17: 1443 | D17: 785 | E17: 658
A18: 4 | B18: Tu Yar(VT) | C18: 1078 | D18: 500 | E18: 578
A19: 5 | B19: Mong Nang(VT) | C19: 2539 | D19: 1145 | E19: 1394
A20: 6 | B20: Hopong(VT) | C20: 1735 | D20: 768 | E20: 967
A21: 7 | B21: Mong Ye(VT) | C21: 2506 | D21: 1125 | E21: 1381
A22: 8 | B22: Wan Ton(VT) | C22: 539 | D22: 265 | E22: 274
A23: 9 | B23: Long Yang(VT) | C23: 1636 | D23: 765 | E23: 871
A24: 10 | B24: Wan Sein(VT) | C24: 6457 | D24: 3225 | E24: 3232
A25: 11 | B25: Mong Yang(VT) | C25: 1759 | D25: 842 | E25: 917
A26: 12 | B26: Mong Lin(VT) | C26: 1086 | D26: 544 | E26: 542
... A28: 14 | B28: Mong Hsaung(VT) | C28: 1095 | D28: 499 | E28: 596

Sheet Minesan(Monsan)(Sub-Tsp)
A1: Shan State, Loilem District, Minesan (Monsan)Sub-Township
E2: 29-3-2014
A4: Sr | B4: Ward/Village Tract | C4: Population
C5: Total | D5: Male | E5: Female
B6: Total | C6: 30057 | D6: 15879 | E6: 14178
B8: Ward | C8: =SUM(C9:C11) -> 2475 | D8: =SUM(D9:D11) -> 1331 | E8: =SUM(E9:E11) -> 1144
A9: 1 | B9: No(1)(W) | C9: 601 | D9: 318 | E9: 283
A10: 2 | B10: No(2)(W) | C10: 531 | D10: 264 | E10: 267
A11: 3 | B11: No(3)(W) | C11: 1343 | D11: 749 | E11: 594
B12: Village Tract | C12: =SUM(C13:C16) -> 27582 | D12: =SUM(D13:D16) -> 14548 | E12: =SUM(E13:E16) -> 13034
A13: 1 | B13: Mong Sam(VT) | C13: 4207 | D13: 2083 | E13: 2124
A14: 2 | B14: Ho Hseng(VT) | C14: 19367 | D14: 10475 | E14: 8892
A15: 3 | B15: Hopong(VT) | C15: 2073 | D15: 1030 | E15: 1043
A16: 4 | B16: Hway Hay(VT) | C16: 1935 | D16: 960 | E16: 975

Sheet Linkhe
A1: Shan State, Linkhe` District, Linkhe` Township
E2: 29-3-2014
A4: Sr | B4: Ward/Village Tract | C4: Population
C5: Total | D5: Male | E5: Female
B6: Total | C6: 33481 | D6: 16683 | E6: 16798
B8: Ward | C8: =SUM(C9:C16) -> 6484 | D8: =SUM(D9:D16) -> 3189 | E8: =SUM(E9:E16) -> 3295
A9: 1 | B9: Taung Ywar(W) | C9: 1736 | D9: 889 | E9: 847
A10: 2 | B10: Wan Loi(W) | C10: 1199 | D10: 598 | E10: 601
A11: 3 | B11: Zay Tan(W) | C11: 542 | D11: 244 | E11: 298
A12: 4 | B12: Ywar Ma Gyi (West)(W) | C12: 1047 | D12: 509 | E12: 538
A13: 5 | B13: Ywar Ma Gyi (East)(W) | C13: 506 | D13: 256 | E13: 250
A14: 6 | B14: Min Hone(W) | C14: 739 | D14: 334 | E14: 405
A15: 7 | B15: Wan Ma Pyin(W) | C15: 150 | D15: 74 | E15: 76
A16: 8 | B16: Pin Waon(W) | C16: 565 | D16: 285 | E16: 280
B17: Village Tract | C17: =SUM(C18:C28) -> 26997 | D17: =SUM(D18:D28) -> 13494 | E17: =SUM(E18:E28) -> 13503
A18: 1 | B18: Pong Htun(VT) | C18: 3011 | D18: 1682 | E18: 1329
A19: 2 | B19: Dar Seik(VT) | C19: 2545 | D19: 1300 | E19: 1245
A20: 3 | B20: Nawng Long(VT) | C20: 3185 | D20: 1496 | E20: 1689
A21: 4 | B21: Wan Sit(VT) | C21: 1201 | D21: 566 | E21: 635
A22: 5 | B22: Hai Kway(VT) | C22: 677 | D22: 311 | E22: 366
A23: 6 | B23: Wan Sa Lawng(VT) | C23: 1095 | D23: 546 | E23: 549
A24: 7 | B24: Loi Long(VT) | C24: 2022 | D24: 977 | E24: 1045
A25: 8 | B25: Wan Hat(VT) | C25: 2116 | D25: 1081 | E25: 1035
A26: 9 | B26: Nar Kone(VT) | C26: 6650 | D26: 3314 | E26: 3336
A27: 10 | B27: Ma Aun Lawng(VT) | C27: 1892 | D27: 943 | E27: 949
A28: 11 | B28: Wan Tein(VT) | C28: 2603 | D28: 1278 | E28: 1325

Sheet Mone
A1: Shan State, Linkhe` District, Mone Township
E2: 29-3-2014
A4: Sr | B4: Ward/Village Tract | C4: Population
C5: Total | D5: Male | E5: Female
B6: Total | C6: 28640 | D6: 14054 | E6: 14586
B8: Ward | C8: =SUM(C9:C13) -> 9767 | D8: =SUM(D9:D13) -> 4735 | E8: =SUM(E9:E13) -> 5032
A9: 1 | B9: U Yin(W) | C9: 2104 | D9: 962 | E9: 1142
A10: 2 | B10: Lwe Pyay(W) | C10: 3956 | D10: 2013 | E10: 1943
A11: 3 | B11: Pawt Mong(W) | C11: 1873 | D11: 876 | E11: 997
A12: 4 | B12: Nar Hawng(W) | C12: 952 | D12: 460 | E12: 492
A13: 5 | B13: Nawng Kyawt(W) | C13: 882 | D13: 424 | E13: 458
B14: Village Tract | C14: =SUM(C15:C25) -> 18873 | D14: =SUM(D15:D25) -> 9319 | E14: =SUM(E15:E25) -> 9554
A15: 1 | B15: Nam Maw Sum(VT) | C15: 1656 | D15: 893 | E15: 763
A16: 2 | B16: Nawng Myaing(VT) | C16: 1068 | D16: 516 | E16: 552
A17: 3 | B17: Wan Hay(VT) | C17: 262 | D17: 126 | E17: 136
A18: 4 | B18: Nawng Lai(VT) | C18: 1854 | D18: 882 | E18: 972
A19: 5 | B19: Nar Sang(VT) | C19: 3618 | D19: 1796 | E19: 1822
A20: 6 | B20: Maik Hai(VT) | C20: 4279 | D20: 2174 | E20: 2105
A21: 7 | B21: Kun Nar(VT) | C21: 1240 | D21: 577 | E21: 663
A22: 8 | B22: Wan Nar(VT) | C22: 1128 | D22: 540 | E22: 588
A23: 9 | B23: Kone Lun(VT) | C23: 1683 | D23: 728 | E23: 955
A24: 10 | B24: Pang Sein (Kar Ha)(VT) | C24: 1431 | D24: 766 | E24: 665
A25: 11 | B25: Kunlong(VT) | C25: 654 | D25: 321 | E25: 333

Sheet Maukme
A1: Shan State, Linkhe` District, Maukme Township
E2: 29-3-2014
A4: Sr | B4: Ward/Village Tract | C4: Population
C5: Total | D5: Male | E5: Female
B6: Total | C6: 33810 | D6: 16546 | E6: 17264
B8: Ward | C8: =SUM(C9:C15) -> 5222 | D8: =SUM(D9:D15) -> 2686 | E8: =SUM(E9:E15) -> 2536
A9: 1 | B9: Kun Keng(W) | C9: 342 | D9: 185 | E9: 157
A10: 2 | B10: Zay Tan(W) | C10: 1780 | D10: 903 | E10: 877
A11: 3 | B11: Mway Taw(W) | C11: 930 | D11: 467 | E11: 463
A12: 4 | B12: Taung Myo(W) | C12: 420 | D12: 221 | E12: 199
A13: 5 | B13: Si Son(W) | C13: 607 | D13: 302 | E13: 305
A14: 6 | B14: Maik Hone(W) | C14: 163 | D14: 76 | E14: 87
A15: 7 | B15: Kone Lan(W) | C15: 980 | D15: 532 | E15: 448
B16: Village Tract | C16: =SUM(C17:C24) -> 28588 | D16: =SUM(D17:D24) -> 13860 | E16: =SUM(E17:E24) -> 14728
A17: 1 | B17: Nam Lut(VT) | C17: 1927 | D17: 989 | E17: 938
A18: 2 | B18: Ho Loi(VT) | C18: 4240 | D18: 2008 | E18: 2232
A19: 3 | B19: Mong Poke(VT) | C19: 444 | D19: 208 | E19: 236
A20: 4 | B20: Sint Win(VT) | C20: 1560 | D20: 757 | E20: 803
A21: 5 | B21: Sint Hseng(VT) | C21: 932 | D21: 467 | E21: 465
A22: 6 | B22: Ho Nam(VT) | C22: 9460 | D22: 4575 | E22: 4885
A23: 7 | B23: Pang Tan(VT) | C23: 5816 | D23: 2763 | E23: 3053
A24: 8 | B24: Ka Du Gyi(VT) | C24: 4209 | D24: 2093 | E24: 2116

Sheet Minepan
A1: Shan State, Linkhe` District, Minepan Township
E2: 29-3-2014
A4: Sr | B4: Ward/Village Tract | C4: Population
C5: Total | D5: Male | E5: Female
B6: Total | C6: 25926 | D6: 13829 | E6: 12097
B8: Ward | C8: =SUM(C9:C12) -> 8972 | D8: =SUM(D9:D12) -> 4712 | E8: =SUM(E9:E12) -> 4260
A9: 1 | B9: Ywar Thit(W) | C9: 2465 | D9: 1491 | E9: 974
A10: 2 | B10: Ah Shey(W) | C10: 986 | D10: 495 | E10: 491
A11: 3 | B11: Ah Lel (W) | C11: 561 | D11: 280 | E11: 281
A12: 4 | B12: Ah Nauk(W) | C12: 4960 | D12: 2446 | E12: 2514
B13: Village Tract | C13: =SUM(C14:C23) -> 16954 | D13: =SUM(D14:D23) -> 9117 | E13: =SUM(E14:E23) -> 7837
A14: 1 | B14: Mongpan (East)(VT) | C14: 612 | D14: 343 | E14: 269
A15: 2 | B15: Kone Keng(VT) | C15: 666 | D15: 371 | E15: 295
A16: 3 | B16: Nam Tein(VT) | C16: 1398 | D16: 744 | E16: 654
A17: 4 | B17: Nawng Lum(VT) | C17: 108 | D17: 58 | E17: 50
A18: 5 | B18: Nawng Hee(VT) | C18: 351 | D18: 181 | E18: 170
A19: 6 | B19: Woe Laing(VT) | C19: 2316 | D19: 1344 | E19: 972
A20: 7 | B20: Nar Law(VT) | C20: 870 | D20: 490 | E20: 380
A21: 8 | B21: Hsar War(VT) | C21: 575 | D21: 331 | E21: 244
A22: 9 | B22: Nawng Yin(VT) | C22: 16 | D22: 13 | E22: 3
A23: 10 | B23: Nar Mun(VT) | C23: 10042 | D23: 5242 | E23: 4800

Sheet Homane (Sub-Tsp)
A1: Shan State, Linkhe` District, Homane(Sub- Township)
E2: 29-3-2014
A4: Sr | B4: Ward/Village Tract | C4: Population
C5: Total | D5: Male | E5: Female
B6: Total | C6: 6830 | D6: 3523 | E6: 3307
B8: Ward | C8: =SUM(C9:C11) -> 3446 | D8: =SUM(D9:D11) -> 1770 | E8: =SUM(E9:E11) -> 1676
A9: 1 | B9: No(1)(W) | C9: 1944 | D9: 990 | E9: 954
A10: 2 | B10: No(2)(W) | C10: 698 | D10: 362 | E10: 336
A11: 3 | B11: No(3)(W) | C11: 804 | D11: 418 | E11: 386
B12: Village Tract | C12: =SUM(C13:C15) -> 3384 | D12: =SUM(D13:D15) -> 1753 | E12: =SUM(E13:E15) -> 1631
A13: 1 | B13: Naw Aww(VT) | C13: 1305 | D13: 640 | E13: 665
A14: 2 | B14: Kho Lon(VT) | C14: 1311 | D14: 724 | E14: 587
A15: 3 | B15: Mae Aww(VT) | C15: 768 | D15: 389 | E15: 379

Sheet Kengtaung(Sub-Tsp)
A1: Shan State, Linkhe` District, Kengtaung(Sub--Township)
E2: 29-3-2014
A4: Sr | B4: Ward/Village Tract | C4: Population
C5: Total | D5: Male | E5: Female
B6: Total | C6: 10796 | D6: 5937 | E6: 4859
B8: Ward | C8: =SUM(C9:C15) -> 9991 | D8: =SUM(D9:D15) -> 5535 | E8: =SUM(E9:E15) -> 4456
A9: 1 | B9: No(1)(W) | C9: 1594 | D9: 869 | E9: 725
A10: 2 | B10: No(2)(W) | C10: 673 | D10: 337 | E10: 336
A11: 3 | B11: No(3)(W) | C11: 1087 | D11: 553 | E11: 534
A12: 4 | B12: No(4)(W) | C12: 2169 | D12: 1332 | E12: 837
A13: 5 | B13: No(5)(W) | C13: 2256 | D13: 1182 | E13: 1074
A14: 6 | B14: No(6)(W) | C14: 599 | D14: 370 | E14: 229
A15: 7 | B15: No(7)(W) | C15: 1613 | D15: 892 | E15: 721
B16: Village Tract | C16: =SUM(C17:C19) -> 805 | D16: =SUM(D17:D19) -> 402 | E16: =SUM(E17:E19) -> 403
A17: 1 | B17: Nawng Hee(VT) | C17: 277 | D17: 129 | E17: 148
A18: 2 | B18: Nar Pawt(VT) | C18: 121 | D18: 61 | E18: 60
A19: 3 | B19: Ho Ha(VT) | C19: 407 | D19: 212 | E19: 195

Sheet Lashio
A1: Shan State, Lashio District, Lashio Township
E2: 29-3-2014
A4: Sr | B4: Ward/Village Tract | C4: Population
C5: Total | D5: Male | E5: Female
B6: Total | C6: 323405 | D6: 158512 | E6: 164893
B8: Ward | C8: =SUM(C9:C20) -> 174335 | D8: =SUM(D9:D20) -> 84331 | E8: =SUM(E9:E20) -> 90004
A9: 1 | B9: No(1)/Thi Ri Ma Har(W) | C9: 28097 | D9: 13843 | E9: 14254
A10: 2 | B10: No(2)/Aung Myit Tar(W) | C10: 3689 | D10: 1750 | E10: 1939
A11: 3 | B11: No(3)/Shwe Bon Thar(W) | C11: 2167 | D11: 968 | E11: 1199
A12: 4 | B12: No(4)/Ahr Yon Taw(W) | C12: 10435 | D12: 5140 | E12: 5295
A13: 5 | B13: No(5)/Aung Min Ga Lar(W) | C13: 20667 | D13: 9643 | E13: 11024
A14: 6 | B14: No(6)/Shwe Li(W) | C14: 3361 | D14: 1504 | E14: 1857
A15: 7 | B15: No(7)/Than Lwin(W) | C15: 23076 | D15: 11087 | E15: 11989
A16: 8 | B16: No(8)/Aung Thi Dar(W) | C16: 9782 | D16: 4521 | E16: 5261
A17: 9 | B17: No(9)/Myanmar Khar Yoe Yar(W) | C17: 17080 | D17: 8507 | E17: 8573
A18: 10 | B18: No(10)/Myo Wan(W) | C18: 11309 | D18: 5319 | E18: 5990
A19: 11 | B19: No(11)/Nam Pa Hkyi(W) | C19: 4593 | D19: 2194 | E19: 2399
A20: 12 | B20: No(12)/Lashio Gyi(W) | C20: 40079 | D20: 19855 | E20: 20224
B21: Village Tract | C21: =SUM(C22:C96) -> 149070 | D21: =SUM(D22:D96) -> 74181 | E21: =SUM(E22:E96) -> 74889
A22: 1 | B22: Hu Mun(VT) | C22: 6925 | D22: 3491 | E22: 3434
A23: 2 | B23: Man Aing(VT) | C23: 4842 | D23: 2447 | E23: 2395
A24: 3 | B24: Mae Han(VT) | C24: 6568 | D24: 3299 | E24: 3269
A25: 4 | B25: Loi Tauk(VT) | C25: 1114 | D25: 584 | E25: 530
A26: 5 | B26: Nam Tun(VT) | C26: 2376 | D26: 1216 | E26: 1160
A27: 6 | B27: Wein Htang(VT) | C27: 1549 | D27: 748 | E27: 801
A28: 7 | B28: Kone Hsar(VT) | C28: 761 | D28: 362 | E28: 399
A29: 8 | B29: Tar Pong(VT) | C29: 3142 | D29: 1644 | E29: 1498
A30: 9 | B30: Ho Nam(VT) | C30: 1096 | D30: 525 | E30: 571
A31: 10 | B31: Man Kat(VT) | C31: 639 | D31: 340 | E31: 299
A32: 11 | B32: Man Pying(VT) | C32: 1046 | D32: 550 | E32: 496
A33: 12 | B33: Mak Hki Nu(VT) | C33: 770 | D33: 389 | E33: 381
... A96: 75 | B96: Nam Maw(VT) | C96: 1164 | D96: 564 | E96: 600

Sheet Theinni
A1: Shan State, Lashio District, Theinni Township
E2: 29-3-2014
A4: Sr | B4: Ward/Village Tract | C4: Population
C5: Total | D5: Male | E5: Female
B6: Total | C6: 56662 | D6: 28604 | E6: 28058
B8: Ward | C8: =SUM(C9:C12) -> 9152 | D8: =SUM(D9:D12) -> 4449 | E8: =SUM(E9:E12) -> 4703
A9: 1 | B9: No(1)(W) | C9: 1710 | D9: 803 | E9: 907
A10: 2 | B10: No(2)(W) | C10: 1321 | D10: 655 | E10: 666
A11: 3 | B11: No(3)(W) | C11: 3612 | D11: 1759 | E11: 1853
A12: 4 | B12: No(4)(W) | C12: 2509 | D12: 1232 | E12: 1277
B13: Village Tract | C13: =SUM(C14:C45) -> 47510 | D13: =SUM(D14:D45) -> 24155 | E13: =SUM(E14:E45) -> 23355
A14: 1 | B14: Hkam Tein(VT) | C14: 1807 | D14: 868 | E14: 939
A15: 2 | B15: Pang Lawt(VT) | C15: 2110 | D15: 1045 | E15: 1065
A16: 3 | B16: Kawng Haw(VT) | C16: 4449 | D16: 2370 | E16: 2079
A17: 4 | B17: U Yin Hmu(VT) | C17: 952 | D17: 442 | E17: 510
A18: 5 | B18: Pein Hsar(VT) | C18: 2916 | D18: 1556 | E18: 1360
A19: 6 | B19: Taing Yet(VT) | C19: 457 | D19: 219 | E19: 238
A20: 7 | B20: Mong Yang(VT) | C20: 496 | D20: 228 | E20: 268
A21: 8 | B21: Ho Ton(VT) | C21: 726 | D21: 369 | E21: 357
A22: 9 | B22: Ho Pang Myin(VT) | C22: 814 | D22: 432 | E22: 382
A23: 10 | B23: Nawng Kyawng(VT) | C23: 804 | D23: 404 | E23: 400
A24: 11 | B24: Mong Li(VT) | C24: 2556 | D24: 1317 | E24: 1239
A25: 12 | B25: Nar Hsawt(VT) | C25: 1425 | D25: 662 | E25: 763
... A45: 32 | B45: Man Kan(VT) | C45: 50 | D45: 27 | E45: 23

Sheet Mineye
A1: Shan State, Lashio District, Mineye` Township
E2: 29-3-2014
A4: Sr | B4: Ward/Village Tract | C4: Population
C5: Total | D5: Male | E5: Female
B6: Total | C6: 59376 | D6: 28391 | E6: 30985
B8: Ward | C8: =SUM(C9:C11) -> 7046 | D8: =SUM(D9:D11) -> 3594 | E8: =SUM(E9:E11) -> 3452
A9: 1 | B9: No(1)(W) | C9: 2466 | D9: 1257 | E9: 1209
A10: 2 | B10: No(2)(W) | C10: 1204 | D10: 559 | E10: 645
A11: 3 | B11: No(3)(W) | C11: 3376 | D11: 1778 | E11: 1598
B12: Village Tract | C12: =SUM(C13:C37) -> 52330 | D12: =SUM(D13:D37) -> 24797 | E12: =SUM(E13:E37) -> 27533
A13: 1 | B13: Nar Hpyaing(VT) | C13: 1913 | D13: 920 | E13: 993
A14: 2 | B14: Loi Hkaik(VT) | C14: 1787 | D14: 840 | E14: 947
A15: 3 | B15: Nar Hko(VT) | C15: 1257 | D15: 587 | E15: 670
A16: 4 | B16: Ho Ya Ywar Ma(VT) | C16: 2541 | D16: 1242 | E16: 1299
A17: 5 | B17: Nawng Mo(VT) | C17: 2094 | D17: 1028 | E17: 1066
A18: 6 | B18: Kawng Mawng(VT) | C18: 1788 | D18: 876 | E18: 912
A19: 7 | B19: Loi Ngin(VT) | C19: 2956 | D19: 1360 | E19: 1596
A20: 8 | B20: Man Kyawng Pang Sin(VT) | C20: 2286 | D20: 1078 | E20: 1208
A21: 9 | B21: Pong Htun(VT) | C21: 2837 | D21: 1407 | E21: 1430
A22: 10 | B22: Man Sant(VT) | C22: 3065 | D22: 1485 | E22: 1580
A23: 11 | B23: Nam Sum(VT) | C23: 1038 | D23: 494 | E23: 544
A24: 12 | B24: Kone Son(VT) | C24: 1041 | D24: 477 | E24: 564
... A37: 25 | B37: Man Kyu(VT) | C37: 4011 | D37: 1851 | E37: 2160

Sheet Tantyan
A1: Shan State, Lashio District,Tantyan Township
E2: 29-3-2014
A4: Sr | B4: Ward/Village Tract | C4: Population
C5: Total | D5: Male | E5: Female
B6: Total | C6: 172805 | D6: 84023 | E6: 88782
B8: Ward | C8: =SUM(C9:C18) -> 33603 | D8: =SUM(D9:D18) -> 16305 | E8: =SUM(E9:E18) -> 17298
A9: 1 | B9: No(1)(W) | C9: 1163 | D9: 533 | E9: 630
A10: 2 | B10: No(2)(W) | C10: 9585 | D10: 4575 | E10: 5010
A11: 3 | B11: No(3)(W) | C11: 2014 | D11: 972 | E11: 1042
A12: 4 | B12: No(4)(W) | C12: 3183 | D12: 1594 | E12: 1589
A13: 5 | B13: No(5)(W) | C13: 4009 | D13: 1881 | E13: 2128
A14: 6 | B14: Wein Lawng(W) | C14: 4827 | D14: 2375 | E14: 2452
A15: 7 | B15: Man Lwe(W) | C15: 2372 | D15: 1225 | E15: 1147
A16: 8 | B16: Nawng Mo(W) | C16: 1165 | D16: 550 | E16: 615
A17: 9 | B17: Man Hsan(W) | C17: 3114 | D17: 1420 | E17: 1694
A18: 10 | B18: Ho Nam(W) | C18: 2171 | D18: 1180 | E18: 991
B19: Village Tract | C19: =SUM(C20:C68) -> 139202 | D19: =SUM(D20:D68) -> 67718 | E19: =SUM(E20:E68) -> 71484
A20: 1 | B20: Mong Pat(VT) | C20: 4149 | D20: 1962 | E20: 2187
A21: 2 | B21: Ho Pat(VT) | C21: 1236 | D21: 580 | E21: 656
A22: 3 | B22: Kone Mon(VT) | C22: 848 | D22: 404 | E22: 444
A23: 4 | B23: Hko Yawng(VT) | C23: 2537 | D23: 1197 | E23: 1340
A24: 5 | B24: Man Kat(VT) | C24: 4014 | D24: 2061 | E24: 1953
A25: 6 | B25: Nar Ngway(VT) | C25: 1758 | D25: 815 | E25: 943
A26: 7 | B26: Ho Tar(VT) | C26: 2308 | D26: 1180 | E26: 1128
A27: 8 | B27: Long Mon(VT) | C27: 2198 | D27: 1086 | E27: 1112
A28: 9 | B28: Hway Kyein(VT) | C28: 3505 | D28: 1669 | E28: 1836
A29: 10 | B29: Ho Man(VT) | C29: 2772 | D29: 1291 | E29: 1481
A30: 11 | B30: Poke Lawng(VT) | C30: 735 | D30: 380 | E30: 355
A31: 12 | B31: Mong Keng(VT) | C31: 3040 | D31: 1381 | E31: 1659
... A68: 49 | B68: Loi Pyet(VT) | C68: 3985 | D68: 1879 | E68: 2106

Sheet Muse
A1: Shan State, MuSe District, MuSe Township
E2: 29-3-2014
A4: Sr | B4: Ward/Village Tract | C4: Population
C5: Total | D5: Male | E5: Female
B6: Total | C6: 117507 | D6: 60946 | E6: 56561
B8: Ward | C8: =SUM(C9:C17) -> 74313 | D8: =SUM(D9:D17) -> 38448 | E8: =SUM(E9:E17) -> 35865
A9: 1 | B9: Christan(W) | C9: 4316 | D9: 2137 | E9: 2179
A10: 2 | B10: Zay(W) | C10: 3981 | D10: 1978 | E10: 2003
A11: 3 | B11: Taung(W) | C11: 8388 | D11: 4231 | E11: 4157
A12: 4 | B12: Ho Mun(W) | C12: 19969 | D12: 10249 | E12: 9720
A13: 5 | B13: Myauk(W) | C13: 3770 | D13: 1928 | E13: 1842
A14: 6 | B14: Kawng Nawng(W) | C14: 3431 | D14: 1632 | E14: 1799
A15: 7 | B15: Swei Taw(W) | C15: 10739 | D15: 5648 | E15: 5091
A16: 8 | B16: Taw Ywet(W) | C16: 2619 | D16: 1314 | E16: 1305
A17: 9 | B17: Kaung Hmu Ton(W) | C17: 17100 | D17: 9331 | E17: 7769
B18: Village Tract | C18: =SUM(C19:C34) -> 43194 | D18: =SUM(D19:D34) -> 22498 | E18: =SUM(E19:E34) -> 20696
A19: 1 | B19: Nam Pang(VT) | C19: 2497 | D19: 1287 | E19: 1210
A20: 2 | B20: Se Lant(VT) | C20: 4318 | D20: 2092 | E20: 2226
A21: 3 | B21: Hpai Kyawng(VT) | C21: 575 | D21: 275 | E21: 300
A22: 4 | B22: Nawng Hseng(VT) | C22: 1134 | D22: 550 | E22: 584
A23: 5 | B23: Nawng Lawng(VT) | C23: 2983 | D23: 1422 | E23: 1561
A24: 6 | B24: Pang Hkam(VT) | C24: 2191 | D24: 1115 | E24: 1076
A25: 7 | B25: Teing Long (East)(VT) | C25: 1580 | D25: 758 | E25: 822
A26: 8 | B26: Mone Yu Tit Yar Ngar Maing(VT) | C26: 12336 | D26: 6949 | E26: 5387
A27: 9 | B27: Tont Hkan Nay(VT) | C27: 1763 | D27: 937 | E27: 826
A28: 10 | B28: Maw Tawng Ywar Ma(VT) | C28: 4230 | D28: 2174 | E28: 2056
A29: 11 | B29: Man Mai(VT) | C29: 330 | D29: 167 | E29: 163
A30: 12 | B30: Nam Aun(VT) | C30: 4020 | D30: 2121 | E30: 1899
... A34: 16 | B34: Hpar Hpeik(VT) | C34: 1110 | D34: 570 | E34: 540

Sheet Namkham
A1: Shan State, MuSe District, Namkham Township
E2: 29-3-2014
A4: Sr | B4: Ward/Village Tract | C4: Population
C5: Total | D5: Male | E5: Female
B6: Total | C6: 107034 | D6: 51315 | E6: 55719
B8: Ward | C8: =SUM(C9:C22) -> 30269 | D8: =SUM(D9:D22) -> 14171 | E8: =SUM(E9:E22) -> 16098
A9: 1 | B9: No(1)(W) | C9: 2188 | D9: 1032 | E9: 1156
A10: 2 | B10: No(2)(W) | C10: 1463 | D10: 696 | E10: 767
A11: 3 | B11: No(3)(W) | C11: 2327 | D11: 1055 | E11: 1272
A12: 4 | B12: No(4)(W) | C12: 2613 | D12: 1205 | E12: 1408
A13: 5 | B13: No(5)(W) | C13: 1892 | D13: 914 | E13: 978
A14: 6 | B14: No(6)(W) | C14: 1284 | D14: 595 | E14: 689
A15: 7 | B15: No(7)(W) | C15: 2289 | D15: 1094 | E15: 1195
A16: 8 | B16: No(8)(W) | C16: 3211 | D16: 1519 | E16: 1692
A17: 9 | B17: No(9)(W) | C17: 1853 | D17: 818 | E17: 1035
A18: 10 | B18: No(10)(W) | C18: 2411 | D18: 1067 | E18: 1344
A19: 11 | B19: No(11)(W) | C19: 1519 | D19: 660 | E19: 859
A20: 12 | B20: No(12)(W) | C20: 699 | D20: 355 | E20: 344
... A22: 14 | B22: No(14)(W) | C22: 4418 | D22: 2126 | E22: 2292
B23: Village Tract | C23: =SUM(C24:C66) -> 76765 | D23: =SUM(D24:D66) -> 37144 | E23: =SUM(E24:E66) -> 39621
A24: 1 | B24: Ho Nar(VT) | C24: 1244 | D24: 602 | E24: 642
A25: 2 | B25: Mant Nawng(VT) | C25: 683 | D25: 315 | E25: 368
A26: 3 | B26: Se Hai(VT) | C26: 2531 | D26: 1197 | E26: 1334
A27: 4 | B27: Nawng Hkan(VT) | C27: 1356 | D27: 634 | E27: 722
A28: 5 | B28: Hat Hin(VT) | C28: 1670 | D28: 792 | E28: 878
A29: 6 | B29: Kun Haing(VT) | C29: 1301 | D29: 622 | E29: 679
A30: 7 | B30: Nawng Hkam(VT) | C30: 1682 | D30: 791 | E30: 891
A31: 8 | B31: Man Sum(VT) | C31: 1979 | D31: 937 | E31: 1042
A32: 9 | B32: Man Hawng(VT) | C32: 2705 | D32: 1302 | E32: 1403
A33: 10 | B33: Kun Long(VT) | C33: 2474 | D33: 1170 | E33: 1304
A34: 11 | B34: Nam Tee(VT) | C34: 1977 | D34: 952 | E34: 1025
A35: 12 | B35: Hopong(VT) | C35: 2302 | D35: 1113 | E35: 1189
... A66: 43 | B66: Ho Pang(VT) | C66: 271 | D66: 141 | E66: 130

Sheet Kukai
A1: Shan State, MuSe District, Kukai Township
E2: 29-3-2014
A4: Sr | B4: Ward/Village Tract | C4: Population
C5: Total | D5: Male | E5: Female
B6: Total | C6: 101334 | D6: 50247 | E6: 51087
B8: Ward | C8: =SUM(C9:C16) -> 24963 | D8: =SUM(D9:D16) -> 12226 | E8: =SUM(E9:E16) -> 12737
A9: 1 | B9: No(1)(W) | C9: 4676 | D9: 2386 | E9: 2290
A10: 2 | B10: No(2)(W) | C10: 3521 | D10: 1748 | E10: 1773
