Workbook

Sheet List of Township
A1: List of Township
A2: 1 | B2: =Sagaing!B1 -> Sagaing Region, Sagaing District, Sagaing Township
A3: 2 | B3: =Myinmu!A1 -> Sagaing Region, Sagaing District, Myinmu Township
A4: 3 | B4: =Myaung!A1 -> Sagaing Region, Sagaing District, Myaung Township
A5: 4 | B5: =Shwebo!A1 -> Sagaing Region, Shwebo District, Shwebo Township
A6: 5 | B6: =KhinU!A1 -> Sagaing Region, Shwebo District, Khin U Township
A7: 6 | B7: =Wetlet!A1 -> Sagaing Region, Shwebo District, Wetlet Township
A8: 7 | B8: =Kambalu!A1 -> Sagaing Region, Shwebo District, Kambalu Township
A9: 8 | B9: =Kunhla!A1 -> Sagaing Region, Shwebo District, Kyunhla Township
A10: 9 | B10: ='Ye U'!A1 -> Sagaing Region, Shwebo District, Ye U Township
A11: 10 | B11: =Depayin!A1 -> Sagaing Region, Shwebo District, Depayin Township
A12: 11 | B12: =Tasei!A1 -> Sagaing Region, Shwebo District, Tasei Township
A13: 12 | B13: =Kyaukmyaung!A1 -> Sagaing Region, Shwebo District, Kyaukmyaung Sub -Township
A14: 13 | B14: =Momnywa!A1 -> Sagaing Region, Monywa District, Monywa Township
A15: 14 | B15: =Butalin!A1 -> Sagaing Region, Monywa District, Butalin Township
A16: 15 | B16: =Ayartaw!A1 -> Sagaing Region, Monywa District ,Ayartaw Township
A17: 16 | B17: ='Chaung Oo'!A1 -> Sagaing Region, Monywa District , Chaung Oo Township
A18: 17 | B18: =Katha!A1 -> Sagaing Region, Katha District , Katha Township
A19: 18 | B19: =Indaw!A1 -> Sagaing Region, Katha District ,Indaw Township
A20: 19 | B20: =Tigyaing!A1 -> Sagaing Region, Katha District ,Tigyaing Township
A21: 20 | B21: =Banmauk!A1 -> Sagaing Region, Katha District , Banmauk Township
A22: 21 | B22: =Kawlin!A1 -> Sagaing Region, Katha District , Kawlin Township
A23: 22 | B23: =Wuntho!A1 -> Sagaing Region, Katha District ,Wuntho Township
A24: 23 | B24: =Pinlebu!A1 -> Sagaing Region, Katha District , Pinlebu Township
A25: 24 | B25: =Kalay!A1 -> Sagaing Region, Kalay District , Kalay Township
A26: 25 | B26: =Kalewa!A1 -> Sagaing Region, Kalay District , Kalewa Township
A27: 26 | B27: =Mingin!A1 -> Sagaing Region, Kalay District , Mingin Township
A28: 27 | B28: =Tamu!A1 -> Sagaing Region, Tamu District , Tamu Township
A29: 28 | B29: ='Myothit(S)'!A1 -> Sagaing Region, Tamu District , Myothit Sub-Township
A30: 29 | B30: ='Khampat(S)'!A1 -> Sagaing Region, Tamu District , Khampat Sub-Township
A31: 30 | B31: =Mawlaik!A1 -> Sagaing Region, Mawlaik District , Mawlaik Township
A32: 31 | B32: =Phaungpyin!A1 -> Sagaing Region, Mawlaik District , Phaungpyin Township
A33: 32 | B33: =Hkamti!A1 -> Sagaing Region, Hkamti District , Hkamti Township
A34: 33 | B34: =Homalin!A1 -> Sagaing Region, Hkamti District , Homalin Township
A35: 34 | B35: =Leshi!A1 -> Sagaing Region, Hkamti District , Leshi Township
A36: 35 | B36: =Lahe!A1 -> Sagaing Region, Hkamti District , Lahe Township
A37: 36 | B37: =Nanyun!A1 -> Sagaing Region, Hkamti District , Nanyun Township
A38: 37 | B38: ='Mobaingluk(S)'!A1 -> Sagaing Region, Hkamti District , Mobaingluk Sub-Township
A39: 38 | B39: ='Sonemara(S)'!A1 -> Sagaing Region, Hkamti District , Sonemara Sub-Township
A40: 39 | B40: ='Htanparkway(S)'!A1 -> Sagaing Region, Hkamti District , Htanparkway Sub-Township
...

Sheet Sagaing
B1: Sagaing Region, Sagaing District, Sagaing Township
F2: 29-3-2014
B5: Sr | C5: Ward/Village Tract | D5: Population
D6: Total | E6: Male | F6: Female
C7: Total | D7: =D9+D28 -> 307194 | E7: =E9+E28 -> 143420 | F7: =F9+F28 -> 163774
C9: Ward | D9: =SUM(D10:D27) -> 81432 | E9: =SUM(E10:E27) -> 38551 | F9: =SUM(F10:F27) -> 42881
B10: 1 | C10: Dawei Zay(W) | D10: 5455 | E10: 2618 | F10: 2837
B11: 2 | C11: Aye Mya Wa Di(W) | D11: 3855 | E11: 1624 | F11: 2231
B12: 3 | C12: Nan Da Wun Kwet Thit (W) | D12: 4633 | E12: 2095 | F12: 2538
B13: 4 | C13: Moe Zar(W) | D13: 2717 | E13: 1214 | F13: 1503
B14: 5 | C14: Myo Thit(W) | D14: 4913 | E14: 2277 | F14: 2636
B15: 6 | C15: Pan Be Dan(W) | D15: 6265 | E15: 2974 | F15: 3291
B16: 7 | C16: Poe Tan(W) | D16: 4244 | E16: 1980 | F16: 2264
B17: 8 | C17: Min Lan(W) | D17: 2603 | E17: 1170 | F17: 1433
B18: 9 | C18: Ta Kaung (W) | D18: 4211 | E18: 2000 | F18: 2211
B19: 10 | C19: Sein Kone(W) | D19: 5432 | E19: 2575 | F19: 2857
B20: 11 | C20: Htone Bo (W) | D20: 3021 | E20: 1549 | F20: 1472
B21: 12 | C21: Zay Yar Kwet Thit(W) | D21: 7071 | E21: 3357 | F21: 3714
... B27: 18 | C27: Par Ra Mi(W) | D27: 2613 | E27: 1207 | F27: 1406
C28: Village Tract | D28: =SUM(D29:D109) -> 225762 | E28: =SUM(E29:E109) -> 104869 | F28: =SUM(F29:F109) -> 120893
B29: 1 | C29: Thaw Tar Pan(VT) | D29: 8706 | E29: 4085 | F29: 4621
B30: 2 | C30: Nyaung Pin Zin(VT) | D30: 3876 | E30: 1940 | F30: 1936
B31: 3 | C31: Pe Ka Toe(VT) | D31: 3925 | E31: 1868 | F31: 2057
B32: 4 | C32: Tin Teik(VT) | D32: 5682 | E32: 2738 | F32: 2944
B33: 5 | C33: Si Tee(VT) | D33: 3314 | E33: 1551 | F33: 1763
B34: 6 | C34: Sin Tat(VT) | D34: 2472 | E34: 1119 | F34: 1353
B35: 7 | C35: Byea Ta Yaw(VT) | D35: 1962 | E35: 911 | F35: 1051
B36: 8 | C36: Kywei Lu(VT) | D36: 3193 | E36: 1473 | F36: 1720
B37: 9 | C37: Nauk Kyi Kyun(VT) | D37: 2081 | E37: 997 | F37: 1084
B38: 10 | C38: Te Gyi Ah Shey Tar(VT) | D38: 7401 | E38: 3397 | F38: 4004
B39: 11 | C39: Zee Chaung(VT) | D39: 5483 | E39: 2731 | F39: 2752
B40: 12 | C40: Daung Ma(VT) | D40: 2901 | E40: 1405 | F40: 1496
... B109: 81 | C109: Htone Bo(VT) | D109: 1810 | E109: 816 | F109: 994

Sheet Myinmu
A1: Sagaing Region, Sagaing District, Myinmu Township
E2: 29-3-2014
A5: Sr | B5: Ward/Village Tract | C5: Population
C6: Total | D6: Male | E6: Female
B7: Total | C7: =C9+C14 -> 106986 | D7: =D9+D14 -> 48949 | E7: =E9+E14 -> 58037
B9: Ward | C9: =SUM(C10:C13) -> 16558 | D9: =SUM(D10:D13) -> 7719 | E9: =SUM(E10:E13) -> 8839
A10: 1 | B10: Ah Nauk Paing (W) | C10: 7220 | D10: 3368 | E10: 3852
A11: 2 | B11: Myauk Paing (W) | C11: 3146 | D11: 1466 | E11: 1680
A12: 3 | B12: Taung Paing (W) | C12: 3080 | D12: 1416 | E12: 1664
A13: 4 | B13: Ah Shey Paing (W) | C13: 3112 | D13: 1469 | E13: 1643
B14: Village Tract | C14: =SUM(C15:C62) -> 90428 | D14: =SUM(D15:D62) -> 41230 | E14: =SUM(E15:E62) -> 49198
A15: 1 | B15: Wan Pyayt(VT) | C15: 3460 | D15: 1477 | E15: 1983
A16: 2 | B16: Sat Pan Kone(VT) | C16: 1744 | D16: 803 | E16: 941
A17: 3 | B17: Kywe Yaik(VT) | C17: 2550 | D17: 1151 | E17: 1399
A18: 4 | B18: Kyawt Min(VT) | C18: 2201 | D18: 985 | E18: 1216
A19: 5 | B19: Chay Yar Taw(VT) | C19: 2011 | D19: 946 | E19: 1065
A20: 6 | B20: Gway Pin Taw(VT) | C20: 1321 | D20: 610 | E20: 711
A21: 7 | B21: Boe Min Gyi Kin(VT) | C21: 1177 | D21: 555 | E21: 622
A22: 8 | B22: Twin Gyi(VT) | C22: 951 | D22: 428 | E22: 523
A23: 9 | B23: Si Pin(VT) | C23: 2359 | D23: 1028 | E23: 1331
A24: 10 | B24: Ma Gyi Su(VT) | C24: 808 | D24: 381 | E24: 427
A25: 11 | B25: San Tin Kin(VT) | C25: 1298 | D25: 565 | E25: 733
A26: 12 | B26: Ahr Lar Kat Pa(VT) | C26: 6546 | D26: 2946 | E26: 3600
... A62: 48 | B62: Pale Tan(VT) | C62: 881 | D62: 399 | E62: 482

Sheet Myaung
A1: Sagaing Region, Sagaing District, Myaung Township
E2: 29-3-2014
A5: Sr | B5: Ward/Village Tract | C5: Population
C6: Total | D6: Male | E6: Female
B7: Total | C7: =C9+C14 -> 106411 | D7: =D9+D14 -> 47677 | E7: =E9+E14 -> 58734
B9: Ward | C9: =SUM(C10:C13) -> 7795 | D9: =SUM(D10:D13) -> 3523 | E9: =SUM(E10:E13) -> 4272
A10: 1 | B10: Myo Thit (W) | C10: 2176 | D10: 992 | E10: 1184
A11: 2 | B11: Myauk (W) | C11: 2343 | D11: 1048 | E11: 1295
A12: 3 | B12: Ah Lel (W) | C12: 1389 | D12: 596 | E12: 793
A13: 4 | B13: Taung(W) | C13: 1887 | D13: 887 | E13: 1000
B14: Village Tract | C14: =SUM(C15:C62) -> 98616 | D14: =SUM(D15:D62) -> 44154 | E14: =SUM(E15:E62) -> 54462
A15: 1 | B15: Hpwar Saw(VT) | C15: 2304 | D15: 1054 | E15: 1250
A16: 2 | B16: Let Yet Ma(VT) | C16: 1925 | D16: 907 | E16: 1018
A17: 3 | B17: Kyauk Yit(VT) | C17: 2394 | D17: 1131 | E17: 1263
A18: 4 | B18: Koe Pin(VT) | C18: 1068 | D18: 479 | E18: 589
A19: 5 | B19: Tha Nat Kone(VT) | C19: 1525 | D19: 684 | E19: 841
A20: 6 | B20: Na Gar Pauk(VT) | C20: 926 | D20: 412 | E20: 514
A21: 7 | B21: Mei Ma Thaw(VT) | C21: 1721 | D21: 690 | E21: 1031
A22: 8 | B22: Pan Nyo(VT) | C22: 2741 | D22: 1275 | E22: 1466
A23: 9 | B23: Nyaung Kar Yar(VT) | C23: 1138 | D23: 507 | E23: 631
A24: 10 | B24: Kyauk Tan(VT) | C24: 2878 | D24: 1343 | E24: 1535
A25: 11 | B25: Shwe Ta Chaung(VT) | C25: 1862 | D25: 761 | E25: 1101
A26: 12 | B26: Su Lay Kone(VT) | C26: 1344 | D26: 604 | E26: 740
... A62: 48 | B62: Myit Son(VT) | C62: 2758 | D62: 1240 | E62: 1518

Sheet Shwebo
A1: Sagaing Region, Shwebo District, Shwebo Township
E2: 29-3-2014
A5: Sr | B5: Ward/Village Tract | C5: Population
C6: Total | D6: Male | E6: Female
B7: Total | C7: =C9+C20 -> 235542 | D7: =D9+D20 -> 108955 | E7: =E9+E20 -> 126587
B9: Ward | C9: =SUM(C10:C19) -> 69036 | D9: =SUM(D10:D19) -> 32425 | E9: =SUM(E10:E19) -> 36611
A10: 1 | B10: No (1)(W) | C10: 9581 | D10: 4461 | E10: 5120
A11: 2 | B11: No (2)(W) | C11: 5722 | D11: 2659 | E11: 3063
A12: 3 | B12: No (3)(W) | C12: 4275 | D12: 1987 | E12: 2288
A13: 4 | B13: No (4)(W) | C13: 6555 | D13: 3079 | E13: 3476
A14: 5 | B14: No (5)(W) | C14: 6228 | D14: 2866 | E14: 3362
A15: 6 | B15: No (6)(W) | C15: 3999 | D15: 1935 | E15: 2064
A16: 7 | B16: No (7)(W) | C16: 7237 | D16: 3426 | E16: 3811
A17: 8 | B17: No (8)(W) | C17: 5512 | D17: 2477 | E17: 3035
A18: 9 | B18: No (9)(W) | C18: 4066 | D18: 1764 | E18: 2302
A19: 10 | B19: No (10)(W) | C19: 15861 | D19: 7771 | E19: 8090
B20: Village Tract | C20: =SUM(C21:C82) -> 166506 | D20: =SUM(D21:D82) -> 76530 | E20: =SUM(E21:E82) -> 89976
A21: 1 | B21: Ta Ga Nan(VT) | C21: 3279 | D21: 1541 | E21: 1738
A22: 2 | B22: Zee Taw(VT) | C22: 1541 | D22: 701 | E22: 840
A23: 3 | B23: Aung Chan Thar(VT) | C23: 1925 | D23: 880 | E23: 1045
A24: 4 | B24: Bone Bweit(VT) | C24: 1937 | D24: 913 | E24: 1024
A25: 5 | B25: Yin Bar(VT) | C25: 1849 | D25: 859 | E25: 990
A26: 6 | B26: Pa Daung(VT) | C26: 1461 | D26: 706 | E26: 755
A27: 7 | B27: Taung Tin(VT) | C27: 1126 | D27: 547 | E27: 579
A28: 8 | B28: Shar Taw(VT) | C28: 1540 | D28: 690 | E28: 850
A29: 9 | B29: Min Kone(VT) | C29: 3061 | D29: 1394 | E29: 1667
A30: 10 | B30: Oke Shit Kan(VT) | C30: 2738 | D30: 1269 | E30: 1469
A31: 11 | B31: Chi Par(VT) | C31: 6272 | D31: 2913 | E31: 3359
A32: 12 | B32: Lone Taw(VT) | C32: 2353 | D32: 1101 | E32: 1252
... A82: 62 | B82: Kyet Tet(VT) | C82: 1103 | D82: 526 | E82: 577

Sheet KhinU
A1: Sagaing Region, Shwebo District, Khin U Township
E2: 29-3-2014
A5: Sr | B5: Ward/Village Tract | C5: Population
C6: Total | D6: Male | E6: Female
B7: Total | C7: =C9+C14 -> 146457 | D7: =D9+D14 -> 67929 | E7: =E9+E14 -> 78528
B9: Ward | C9: =SUM(C10:C13) -> 11334 | D9: =SUM(D10:D13) -> 5194 | E9: =SUM(E10:E13) -> 6140
A10: 1 | B10: Mya Kan Thar(W) | C10: 4324 | D10: 2034 | E10: 2290
A11: 2 | B11: Aung Chan Thar(W) | C11: 1589 | D11: 706 | E11: 883
A12: 3 | B12: Aung Thi Ri Ward(W) | C12: 2529 | D12: 1151 | E12: 1378
A13: 4 | B13: Min Ga Lar Yan Aung(W) | C13: 2892 | D13: 1303 | E13: 1589
B14: Village Tract | C14: =SUM(C15:C73) -> 135123 | D14: =SUM(D15:D73) -> 62735 | E14: =SUM(E15:E73) -> 72388
A15: 1 | B15: Mon Hla(VT) | C15: 2274 | D15: 1026 | E15: 1248
A16: 2 | B16: Ngar Yon Gyi(VT) | C16: 1237 | D16: 570 | E16: 667
A17: 3 | B17: Shin Min Dway(VT) | C17: 1136 | D17: 521 | E17: 615
A18: 4 | B18: Tha Yet Kone(VT) | C18: 895 | D18: 431 | E18: 464
A19: 5 | B19: Thar Wut Hti(VT) | C19: 2449 | D19: 1074 | E19: 1375
A20: 6 | B20: Kin Pyit(VT) | C20: 430 | D20: 198 | E20: 232
A21: 7 | B21: In Daing Gyi(VT) | C21: 2259 | D21: 1022 | E21: 1237
A22: 8 | B22: Pyin Htaung(VT) | C22: 1489 | D22: 664 | E22: 825
A23: 9 | B23: Ma Gyi Oke(VT) | C23: 5657 | D23: 2685 | E23: 2972
A24: 10 | B24: In Daing Lay(VT) | C24: 2544 | D24: 1162 | E24: 1382
A25: 11 | B25: Inn Pat(VT) | C25: 5587 | D25: 2516 | E25: 3071
A26: 12 | B26: Mya Kan(VT) | C26: 496 | D26: 221 | E26: 275
... A73: 59 | B73: Koke Tet(VT) | C73: 1928 | D73: 966 | E73: 962

Sheet Wetlet
A1: Sagaing Region, Shwebo District, Wetlet Township
E2: 29-3-2014
A5: Sr | B5: Ward/Village Tract | C5: Population
C6: Total | D6: Male | E6: Female
B7: Total | C7: =C9+C13 -> 196216 | D7: =D9+D13 -> 90089 | E7: =E9+E13 -> 106127
B9: Ward | C9: =SUM(C10:C12) -> 10814 | D9: =SUM(D10:D12) -> 4931 | E9: =SUM(E10:E12) -> 5883
A10: 1 | B10: No (1)(W) | C10: 4121 | D10: 1862 | E10: 2259
A11: 2 | B11: No (2)(W) | C11: 2525 | D11: 1117 | E11: 1408
A12: 3 | B12: No (3)(W) | C12: 4168 | D12: 1952 | E12: 2216
B13: Village Tract | C13: =SUM(C14:C82) -> 185402 | D13: =SUM(D14:D82) -> 85158 | E13: =SUM(E14:E82) -> 100244
A14: 1 | B14: Myin Taw(VT) | C14: 2951 | D14: 1344 | E14: 1607
A15: 2 | B15: Ma Gyi Ton(VT) | C15: 975 | D15: 445 | E15: 530
A16: 3 | B16: Mu Gyi(VT) | C16: 1373 | D16: 637 | E16: 736
A17: 4 | B17: Lein Pin(VT) | C17: 825 | D17: 360 | E17: 465
A18: 5 | B18: Tha Khut Taw(VT) | C18: 4240 | D18: 1949 | E18: 2291
A19: 6 | B19: Yone Thar(VT) | C19: 1155 | D19: 515 | E19: 640
A20: 7 | B20: Pin Zin(VT) | C20: 3979 | D20: 1815 | E20: 2164
A21: 8 | B21: Ta Kaung Min(VT) | C21: 2646 | D21: 1211 | E21: 1435
A22: 9 | B22: Khaw Taw(VT) | C22: 3449 | D22: 1587 | E22: 1862
A23: 10 | B23: Min(VT) | C23: 1765 | D23: 757 | E23: 1008
A24: 11 | B24: Tha Yaing(VT) | C24: 2046 | D24: 949 | E24: 1097
A25: 12 | B25: Han Lin(VT) | C25: 6040 | D25: 2779 | E25: 3261
... A82: 69 | B82: Ma Gyi Hpyu(VT) | C82: 1755 | D82: 785 | E82: 970

Sheet Kambalu
A1: Sagaing Region, Shwebo District, Kambalu Township
E2: 29-3-2014
A5: Sr | B5: Ward/Village Tract | C5: Population
C6: Total | D6: Male | E6: Female
B7: Total | C7: =C9+C15 -> 295561 | D7: =D9+D15 -> 139944 | E7: =E9+E15 -> 155617
B9: Ward | C9: =SUM(C10:C14) -> 25022 | D9: =SUM(D10:D14) -> 11976 | E9: =SUM(E10:E14) -> 13046
A10: 1 | B10: No (1)(W) | C10: 3868 | D10: 1767 | E10: 2101
A11: 2 | B11: No (2)(W) | C11: 6395 | D11: 3001 | E11: 3394
A12: 3 | B12: No (3)(W) | C12: 7929 | D12: 3721 | E12: 4208
A13: 4 | B13: No (4)(W) | C13: 2457 | D13: 1121 | E13: 1336
A14: 5 | B14: No (5)(W) | C14: 4373 | D14: 2366 | E14: 2007
B15: Village Tract | C15: =SUM(C16:C101) -> 270539 | D15: =SUM(D16:D101) -> 127968 | E15: =SUM(E16:E101) -> 142571
A16: 1 | B16: Kya Khat Aing(Kya Khet Aik)(VT) | C16: 785 | D16: 384 | E16: 401
A17: 2 | B17: Koe Taung Boet(VT) | C17: 6226 | D17: 2888 | E17: 3338
A18: 3 | B18: Meik Tha Lin Kone(VT) | C18: 2399 | D18: 1146 | E18: 1253
A19: 4 | B19: Zee Ka Nar(VT) | C19: 5207 | D19: 2535 | E19: 2672
A20: 5 | B20: Thin Taw(VT) | C20: 3948 | D20: 1888 | E20: 2060
A21: 6 | B21: Kan Gyi(VT) | C21: 3195 | D21: 1565 | E21: 1630
A22: 7 | B22: Auk Te(VT) | C22: 1959 | D22: 996 | E22: 963
A23: 8 | B23: Chat Thin(VT) | C23: 5831 | D23: 2681 | E23: 3150
A24: 9 | B24: Tin Maw(VT) | C24: 2777 | D24: 1302 | E24: 1475
A25: 10 | B25: Sar Kyin(VT) | C25: 1693 | D25: 793 | E25: 900
A26: 11 | B26: Nyaung Kan Thar(VT) | C26: 2037 | D26: 919 | E26: 1118
A27: 12 | B27: Myauk Pay Kone(VT) | C27: 1634 | D27: 832 | E27: 802
... A101: 86 | B101: Dan Pin(VT) | C101: 1847 | D101: 844 | E101: 1003

Sheet Kunhla
A1: Sagaing Region, Shwebo District, Kyunhla Township
E2: 29-3-2014
A5: Sr | B5: Ward/Village Tract | C5: Population
C6: Total | D6: Male | E6: Female
B7: Total | C7: =C9+C14 -> 104087 | D7: =D9+D14 -> 51125 | E7: =E9+E14 -> 52962
B9: Ward | C9: =SUM(C10:C13) -> 12148 | D9: =SUM(D10:D13) -> 5621 | E9: =SUM(E10:E13) -> 6527
A10: 1 | B10: Pi Tauk Myaing(W) | C10: 3867 | D10: 1784 | E10: 2083
A11: 2 | B11: Thit Yar Myaing(W) | C11: 3752 | D11: 1767 | E11: 1985
A12: 3 | B12: In Gyin Myaing(W) | C12: 344 | D12: 157 | E12: 187
A13: 4 | B13: Pyin Ma Myaing(W) | C13: 4185 | D13: 1913 | E13: 2272
B14: Village Tract | C14: =SUM(C15:C48) -> 91939 | D14: =SUM(D15:D48) -> 45504 | E14: =SUM(E15:E48) -> 46435
A15: 1 | B15: In Daing(VT) | C15: 2430 | D15: 1135 | E15: 1295
A16: 2 | B16: Kyi Kone(VT) | C16: 1989 | D16: 938 | E16: 1051
A17: 3 | B17: Kyauk Aing(VT) | C17: 5835 | D17: 3086 | E17: 2749
A18: 4 | B18: Nyaung Kaing(VT) | C18: 2541 | D18: 1102 | E18: 1439
A19: 5 | B19: Ywar Thi(VT) | C19: 4899 | D19: 2270 | E19: 2629
A20: 6 | B20: Ma Gyi Inn(VT) | C20: 1779 | D20: 871 | E20: 908
A21: 7 | B21: Tin Tein Yan(VT) | C21: 1652 | D21: 791 | E21: 861
A22: 8 | B22: Lel Hla(VT) | C22: 1935 | D22: 895 | E22: 1040
A23: 9 | B23: Koke Ko Kone(VT) | C23: 2326 | D23: 1064 | E23: 1262
A24: 10 | B24: Inn Gaung(VT) | C24: 2747 | D24: 1289 | E24: 1458
A25: 11 | B25: Thet Kei Kyin(VT) | C25: 2904 | D25: 1348 | E25: 1556
A26: 12 | B26: Kone See(VT) | C26: 1856 | D26: 860 | E26: 996
... A48: 34 | B48: Myintharoo(VT) | C48: 1458 | D48: 760 | E48: 698

Sheet Ye U
A1: Sagaing Region, Shwebo District, Ye U Township
E2: 29-3-2014
A5: Sr | B5: Ward/Village Tract | C5: Population
C6: Total | D6: Male | E6: Female
B7: Total | C7: =C9+C15 -> 118290 | D7: =D9+D15 -> 51422 | E7: =E9+E15 -> 66868
B9: Ward | C9: =SUM(C10:C14) -> 20458 | D9: =SUM(D10:D14) -> 9580 | E9: =SUM(E10:E14) -> 10878
A10: 1 | B10: Aung Min Ga Lar(W) | C10: 2749 | D10: 1408 | E10: 1341
A11: 2 | B11: Bo Aung Zay Ya(W) | C11: 4111 | D11: 1785 | E11: 2326
A12: 3 | B12: Aung Chan Thar(W) | C12: 5868 | D12: 2980 | E12: 2888
A13: 4 | B13: Aung San (W) | C13: 5770 | D13: 2521 | E13: 3249
A14: 5 | B14: Shwe Pyi Thar (W) | C14: 1960 | D14: 886 | E14: 1074
B15: Village Tract | C15: =SUM(C16:C77) -> 97832 | D15: =SUM(D16:D77) -> 41842 | E15: =SUM(E16:E77) -> 55990
A16: 1 | B16: Hnaw Kone(VT) | C16: 2080 | D16: 851 | E16: 1229
A17: 2 | B17: Me Oe(VT) | C17: 584 | D17: 230 | E17: 354
A18: 3 | B18: Myin Pauk(VT) | C18: 1532 | D18: 641 | E18: 891
A19: 4 | B19: Hpa Lan Khon(VT) | C19: 887 | D19: 376 | E19: 511
A20: 5 | B20: Ywar Nge(VT) | C20: 827 | D20: 404 | E20: 423
A21: 6 | B21: Yae Myet(VT) | C21: 2636 | D21: 1161 | E21: 1475
A22: 7 | B22: Nyaung Lel(VT) | C22: 1047 | D22: 405 | E22: 642
A23: 8 | B23: Nay Pu Kone(VT) | C23: 849 | D23: 300 | E23: 549
A24: 9 | B24: Aung Keit Zin(VT) | C24: 1631 | D24: 586 | E24: 1045
A25: 10 | B25: Ywar Meik Thar(VT) | C25: 2222 | D25: 975 | E25: 1247
A26: 11 | B26: Aung Thar(VT) | C26: 803 | D26: 369 | E26: 434
A27: 12 | B27: Moke Si(VT) | C27: 1533 | D27: 714 | E27: 819
... A77: 62 | B77: Chaung Shey(VT) | C77: 925 | D77: 380 | E77: 545

Sheet Depayin
A1: Sagaing Region, Shwebo District, Depayin Township
E2: 29-3-2014
A5: Sr | B5: Ward/Village Tract | C5: Population
C6: Total | D6: Male | E6: Female
B7: Total | C7: =C9+C12 -> 140815 | D7: =D9+D12 -> 64396 | E7: =E9+E12 -> 76419
B9: Ward | C9: =SUM(C10:C11) -> 4308 | D9: =SUM(D10:D11) -> 2001 | E9: =SUM(E10:E11) -> 2307
A10: 1 | B10: Tabayin (W) | C10: 2521 | D10: 1175 | E10: 1346
A11: 2 | B11: Taung Pyin(W) | C11: 1787 | D11: 826 | E11: 961
B12: Village Tract | C12: =SUM(C13:C68) -> 136507 | D12: =SUM(D13:D68) -> 62395 | E12: =SUM(E13:E68) -> 74112
A13: 1 | B13: Ywar Shey(VT) | C13: 1940 | D13: 850 | E13: 1090
A14: 2 | B14: Khun Taung(VT) | C14: 2194 | D14: 992 | E14: 1202
A15: 3 | B15: Ta Nei(VT) | C15: 1336 | D15: 602 | E15: 734
A16: 4 | B16: Pauk Taw(VT) | C16: 278 | D16: 121 | E16: 157
A17: 5 | B17: Bagan(VT) | C17: 1280 | D17: 621 | E17: 659
A18: 6 | B18: Let Tee(VT) | C18: 1258 | D18: 577 | E18: 681
A19: 7 | B19: Yin Dway(VT) | C19: 1200 | D19: 530 | E19: 670
A20: 8 | B20: Kyi(VT) | C20: 2944 | D20: 1384 | E20: 1560
A21: 9 | B21: Wa Bar(VT) | C21: 1770 | D21: 823 | E21: 947
A22: 10 | B22: Taw Kyaung(VT) | C22: 1066 | D22: 481 | E22: 585
A23: 11 | B23: In Taing Lay(VT) | C23: 1573 | D23: 714 | E23: 859
A24: 12 | B24: Sat Pyar Kyin(VT) | C24: 4613 | D24: 2098 | E24: 2515
... A68: 56 | B68: Tha Yet Taw(VT) | C68: 1678 | D68: 794 | E68: 884

Sheet Tasei
A1: Sagaing Region, Shwebo District, Tasei Township
E2: 29-3-2014
A5: Sr | B5: Ward/Village Tract | C5: Population
C6: Total | D6: Male | E6: Female
B7: Total | C7: =C9+C14 -> 165110 | D7: =D9+D14 -> 72475 | E7: =E9+E14 -> 92635
B9: Ward | C9: =SUM(C10:C13) -> 14361 | D9: =SUM(D10:D13) -> 6472 | E9: =SUM(E10:E13) -> 7889
A10: 1 | B10: Bo Mya (W) | C10: 2197 | D10: 974 | E10: 1223
A11: 2 | B11: Paw-U (W) | C11: 2954 | D11: 1332 | E11: 1622
A12: 3 | B12: MahaMyaing(W) | C12: 3711 | D12: 1714 | E12: 1997
A13: 4 | B13: MittaMyaing(W) | C13: 5499 | D13: 2452 | E13: 3047
B14: Village Tract | C14: =SUM(C15:C69) -> 150749 | D14: =SUM(D15:D69) -> 66003 | E14: =SUM(E15:E69) -> 84746
A15: 1 | B15: Nyan Thar(VT) | C15: 508 | D15: 222 | E15: 286
A16: 2 | B16: Aung Swar(VT) | C16: 3051 | D16: 1454 | E16: 1597
A17: 3 | B17: Chaung Yoe(VT) | C17: 1363 | D17: 635 | E17: 728
A18: 4 | B18: Chaung Son (South)(VT) | C18: 2174 | D18: 1001 | E18: 1173
A19: 5 | B19: Chaung Son (North)(VT) | C19: 3406 | D19: 1652 | E19: 1754
A20: 6 | B20: Dei Yauk(VT) | C20: 888 | D20: 384 | E20: 504
A21: 7 | B21: Et Taw(VT) | C21: 2158 | D21: 972 | E21: 1186
A22: 8 | B22: Nga Tan(VT) | C22: 2564 | D22: 1127 | E22: 1437
A23: 9 | B23: In Taing(VT) | C23: 2096 | D23: 871 | E23: 1225
A24: 10 | B24: Daung Gyi(VT) | C24: 3635 | D24: 1612 | E24: 2023
A25: 11 | B25: In Koke Kar(VT) | C25: 2169 | D25: 944 | E25: 1225
A26: 12 | B26: Kyun Taw Kone(VT) | C26: 2059 | D26: 872 | E26: 1187
... A69: 55 | B69: Zee Pauk(VT) | C69: 3669 | D69: 1657 | E69: 2012

Sheet Kyaukmyaung
A1: Sagaing Region, Shwebo District, Kyaukmyaung Sub -Township
E2: 29-3-2014
A5: Sr | B5: Ward/Village Tract | C5: Population
C6: Total | D6: Male | E6: Female
B7: Total | C7: =C9+C14 -> 31265 | D7: =D9+D14 -> 14681 | E7: =E9+E14 -> 16584
B9: Ward | C9: =SUM(C10:C13) -> 10703 | D9: =SUM(D10:D13) -> 5056 | E9: =SUM(E10:E13) -> 5647
A10: 1 | B10: No(1)(W) | C10: 2007 | D10: 970 | E10: 1037
A11: 2 | B11: No(2)(W) | C11: 3068 | D11: 1459 | E11: 1609
A12: 3 | B12: No(3)(W) | C12: 2638 | D12: 1235 | E12: 1403
A13: 4 | B13: No(4)(W) | C13: 2990 | D13: 1392 | E13: 1598
B14: Village Tract | C14: =SUM(C15:C24) -> 20562 | D14: =SUM(D15:D24) -> 9625 | E14: =SUM(E15:E24) -> 10937
A15: 1 | B15: Ma Au(VT) | C15: 2326 | D15: 1156 | E15: 1170
A16: 2 | B16: Shwe Gun (VT) | C16: 822 | D16: 352 | E16: 470
A17: 3 | B17: Ma Lar(VT) | C17: 1871 | D17: 885 | E17: 986
A18: 4 | B18: Ma Khauk(VT) | C18: 1518 | D18: 697 | E18: 821
A19: 5 | B19: Se Pin Kyun(VT) | C19: 1309 | D19: 618 | E19: 691
A20: 6 | B20: Ku Lar Ma(VT) | C20: 2148 | D20: 991 | E20: 1157
A21: 7 | B21: Ohn Pauk(VT) | C21: 4532 | D21: 2099 | E21: 2433
A22: 8 | B22: Kan Gyi Taw(VT) | C22: 1683 | D22: 783 | E22: 900
A23: 9 | B23: Gway Pin Kone(VT) | C23: 1552 | D23: 717 | E23: 835
A24: 10 | B24: Tei Pin(VT) | C24: 2801 | D24: 1327 | E24: 1474

Sheet Momnywa
A1: Sagaing Region, Monywa District, Monywa Township
E2: 29-3-2014
A5: Sr | B5: Ward/Village Tract | C5: Population
C6: Total | D6: Male | E6: Female
B7: Total | C7: =C9+C36 -> 372095 | D7: =D9+D36 -> 171951 | E7: =E9+E36 -> 200144
B9: Ward | C9: =SUM(C10:C35) -> 207489 | D9: =SUM(D10:D35) -> 97076 | E9: =SUM(E10:E35) -> 110413
A10: 1 | B10: Kwayt Gyi(W) | C10: 7710 | D10: 3508 | E10: 4202
A11: 2 | B11: Aung Chan Thar(W) | C11: 9868 | D11: 4729 | E11: 5139
A12: 3 | B12: Daw Na Chan(W) | C12: 5881 | D12: 2467 | E12: 3414
A13: 4 | B13: Lel Di(W) | C13: 3834 | D13: 1658 | E13: 2176
A14: 5 | B14: Hpone Soe(W) | C14: 5887 | D14: 3049 | E14: 2838
A15: 6 | B15: Ya Da Nar Bon(W) | C15: 6743 | D15: 2960 | E15: 3783
A16: 7 | B16: Chan Mya Thar Zi(W) | C16: 4813 | D16: 2243 | E16: 2570
A17: 8 | B17: Aye Thar Yar(W) | C17: 4422 | D17: 2040 | E17: 2382
A18: 9 | B18: Yan Kin(W) | C18: 8507 | D18: 3867 | E18: 4640
A19: 10 | B19: Thar Lar(W) | C19: 21192 | D19: 9763 | E19: 11429
A20: 11 | B20: Ah Lel(W) | C20: 2207 | D20: 968 | E20: 1239
A21: 12 | B21: Htan Taw(W) | C21: 15538 | D21: 7192 | E21: 8346
... A35: 26 | B35: Inn Ywar Thit(W) | C35: 5780 | D35: 2702 | E35: 3078
B36: Village Tract | C36: =SUM(C37:C93) -> 164606 | D36: =SUM(D37:D93) -> 74875 | E36: =SUM(E37:E93) -> 89731
A37: 1 | B37: Koe Shin Kyun(VT) | C37: 1676 | D37: 753 | E37: 923
A38: 2 | B38: Su Lay Kone(VT) | C38: 875 | D38: 408 | E38: 467
A39: 3 | B39: Ma Au(VT) | C39: 3750 | D39: 1731 | E39: 2019
A40: 4 | B40: Lel Zin(VT) | C40: 6525 | D40: 3057 | E40: 3468
A41: 5 | B41: Nyaung Hpyu Pin(VT) | C41: 4957 | D41: 2238 | E41: 2719
A42: 6 | B42: Bu Taung Kan(VT) | C42: 1115 | D42: 489 | E42: 626
A43: 7 | B43: Bon Ma Noe(VT) | C43: 2331 | D43: 1069 | E43: 1262
A44: 8 | B44: Pon Nar Maw(VT) | C44: 1387 | D44: 660 | E44: 727
A45: 9 | B45: Kyun Ywar Thit(VT) | C45: 1303 | D45: 590 | E45: 713
A46: 10 | B46: Kya Paing(VT) | C46: 2828 | D46: 1316 | E46: 1512
A47: 11 | B47: Taw Pu(VT) | C47: 2831 | D47: 1287 | E47: 1544
A48: 12 | B48: Mon Yway(VT) | C48: 5556 | D48: 2496 | E48: 3060
... A93: 57 | B93: Kyun Gyi(VT) | C93: 1659 | D93: 816 | E93: 843

Sheet Butalin
A1: Sagaing Region, Monywa District, Butalin Township
E2: 29-3-2014
A5: Sr | B5: Ward/Village Tract | C5: Population
C6: Total | D6: Male | E6: Female
B7: Total | C7: =C9+C13 -> 123539 | D7: =D9+D13 -> 55106 | E7: =E9+E13 -> 68433
B9: Ward | C9: =SUM(C10:C12) -> 5210 | D9: =SUM(D10:D12) -> 2399 | E9: =SUM(E10:E12) -> 2811
A10: 1 | B10: Mya Wa Di(W) | C10: 1996 | D10: 919 | E10: 1077
A11: 2 | B11: Ma Har Ban Du La(W) | C11: 1769 | D11: 842 | E11: 927
A12: 3 | B12: Khon Min Gyi(W) | C12: 1445 | D12: 638 | E12: 807
B13: Village Tract | C13: =SUM(C14:C67) -> 118329 | D13: =SUM(D14:D67) -> 52707 | E13: =SUM(E14:E67) -> 65622
A14: 1 | B14: Kyee Pin Chaung(VT) | C14: 932 | D14: 416 | E14: 516
A15: 2 | B15: Son Kone(VT) | C15: 1743 | D15: 746 | E15: 997
A16: 3 | B16: Kan Thit(VT) | C16: 1217 | D16: 509 | E16: 708
A17: 4 | B17: Aung Chan Thar(VT) | C17: 2784 | D17: 1259 | E17: 1525
A18: 5 | B18: Hta Naung Kone(VT) | C18: 1804 | D18: 784 | E18: 1020
A19: 6 | B19: Myo Paw(VT) | C19: 1457 | D19: 623 | E19: 834
A20: 7 | B20: Taw Way(VT) | C20: 1294 | D20: 555 | E20: 739
A21: 8 | B21: Ma Gyi Oke(VT) | C21: 994 | D21: 446 | E21: 548
A22: 9 | B22: Ma Gway Pyin(VT) | C22: 594 | D22: 272 | E22: 322
A23: 10 | B23: Kone Thar(VT) | C23: 2459 | D23: 1128 | E23: 1331
A24: 11 | B24: Nay Pu Kone(VT) | C24: 1727 | D24: 776 | E24: 951
A25: 12 | B25: Hlwe Te(VT) | C25: 2020 | D25: 881 | E25: 1139
... A67: 54 | B67: Hnaw Pin Gyi(VT) | C67: 4006 | D67: 1917 | E67: 2089

Sheet Ayartaw
A1: Sagaing Region, Monywa District ,Ayartaw Township
E2: 29-3-2014
A5: Sr | B5: Ward/Village Tract | C5: Population
C6: Total | D6: Male | E6: Female
B7: Total | C7: =C9+C13 -> 155769 | D7: =D9+D13 -> 70734 | E7: =E9+E13 -> 85035
B9: Ward | C9: =SUM(C10:C12) -> 9516 | D9: =SUM(D10:D12) -> 4369 | E9: =SUM(E10:E12) -> 5147
A10: 1 | B10: No (1)(W) | C10: 4519 | D10: 2062 | E10: 2457
A11: 2 | B11: No (2)(W) | C11: 2429 | D11: 1052 | E11: 1377
A12: 3 | B12: No (3)(W) | C12: 2568 | D12: 1255 | E12: 1313
B13: Village Tract | C13: =SUM(C14:C51) -> 146253 | D13: =SUM(D14:D51) -> 66365 | E13: =SUM(E14:E51) -> 79888
A14: 1 | B14: Kan Thar(VT) | C14: 3451 | D14: 1908 | E14: 1543
A15: 2 | B15: Kan Hpyu(VT) | C15: 4899 | D15: 2208 | E15: 2691
A16: 3 | B16: War Tan(VT) | C16: 8925 | D16: 3995 | E16: 4930
A17: 4 | B17: Kyauk Pyauk(VT) | C17: 2899 | D17: 1372 | E17: 1527
A18: 5 | B18: War Yaung(VT) | C18: 9300 | D18: 4317 | E18: 4983
A19: 6 | B19: Tha Khut Pin Lel(VT) | C19: 2880 | D19: 1340 | E19: 1540
A20: 7 | B20: Ma Le Thar(VT) | C20: 8027 | D20: 3642 | E20: 4385
A21: 8 | B21: Naung Gyi Aing(VT) | C21: 5068 | D21: 2275 | E21: 2793
A22: 9 | B22: War Taw Ma(VT) | C22: 5048 | D22: 2063 | E22: 2985
A23: 10 | B23: Hmaw Taw(VT) | C23: 3901 | D23: 1702 | E23: 2199
A24: 11 | B24: Thit Kyin Gyi(VT) | C24: 2435 | D24: 1130 | E24: 1305
A25: 12 | B25: Hgnet Pyaw Chan(VT) | C25: 3963 | D25: 1808 | E25: 2155
... A51: 38 | B51: Kaing(VT) | C51: 2357 | D51: 1036 | E51: 1321

Sheet Chaung Oo
A1: Sagaing Region, Monywa District , Chaung Oo Township
E2: 29-3-2014
A5: Sr | B5: Ward/Village Tract | C5: Population
C6: Total | D6: Male | E6: Female
B7: Total | C7: =C9+C16 -> 105955 | D7: =D9+D16 -> 48456 | E7: =E9+E16 -> 57499
B9: Ward | C9: =SUM(C10:C15) -> 21929 | D9: =SUM(D10:D15) -> 10145 | E9: =SUM(E10:E15) -> 11784
A10: 1 | B10: Myo Thit(W) | C10: 5008 | D10: 2335 | E10: 2673
A11: 2 | B11: Myo Ma(W) | C11: 3070 | D11: 1456 | E11: 1614
A12: 3 | B12: Yan Aung Myay(W) | C12: 3676 | D12: 1689 | E12: 1987
A13: 4 | B13: Chaung-U (North)(W) | C13: 3274 | D13: 1428 | E13: 1846
A14: 5 | B14: Ta Mar Myaing(W) | C14: 2404 | D14: 1097 | E14: 1307
A15: 6 | B15: Chaung-U (South)(W) | C15: 4497 | D15: 2140 | E15: 2357
B16: Village Tract | C16: =SUM(C17:C42) -> 84026 | D16: =SUM(D17:D42) -> 38311 | E16: =SUM(E17:E42) -> 45715
A17: 1 | B17: Aung Chan Thar(VT) | C17: 1773 | D17: 812 | E17: 961
A18: 2 | B18: Kyi Kone(VT) | C18: 3772 | D18: 1691 | E18: 2081
A19: 3 | B19: Ngar Shan(VT) | C19: 4175 | D19: 1931 | E19: 2244
A20: 4 | B20: Bu Tar(VT) | C20: 1759 | D20: 790 | E20: 969
A21: 5 | B21: War Yar(VT) | C21: 2919 | D21: 1308 | E21: 1611
A22: 6 | B22: Khin Mun(VT) | C22: 8450 | D22: 3831 | E22: 4619
A23: 7 | B23: Nwe Khway(VT) | C23: 2496 | D23: 1136 | E23: 1360
A24: 8 | B24: Nat Yae Kan(VT) | C24: 1427 | D24: 646 | E24: 781
A25: 9 | B25: Than Pin Kan(VT) | C25: 1258 | D25: 593 | E25: 665
A26: 10 | B26: Ba Lway(VT) | C26: 1105 | D26: 485 | E26: 620
A27: 11 | B27: Nga Lone Tin(VT) | C27: 7493 | D27: 3493 | E27: 4000
A28: 12 | B28: Ma Gyi Gwa(VT) | C28: 6100 | D28: 2712 | E28: 3388
... A42: 26 | B42: Kyauk Sit Kan(VT) | C42: 905 | D42: 453 | E42: 452

Sheet Katha
A1: Sagaing Region, Katha District , Katha Township
E2: 29-3-2014
A5: Sr | B5: Ward/Village Tract | C5: Population
C6: Total | D6: Male | E6: Female
B7: Total | C7: =C9+C20 -> 167734 | D7: =D9+D20 -> 82325 | E7: =E9+E20 -> 85409
B9: Ward | C9: =SUM(C10:C19) -> 26732 | D9: =SUM(D10:D19) -> 12932 | E9: =SUM(E10:E19) -> 13800
A10: 1 | B10: Myauk Paing(W) | C10: 1400 | D10: 724 | E10: 676
A11: 2 | B11: Ah Lel Paing(W) | C11: 927 | D11: 451 | E11: 476
A12: 3 | B12: Taung Paing(W) | C12: 2006 | D12: 1151 | E12: 855
A13: 4 | B13: Thu Htay Gone(W) | C13: 2645 | D13: 1195 | E13: 1450
A14: 5 | B14: Zay Yar Chaung(W) | C14: 4491 | D14: 2095 | E14: 2396
A15: 6 | B15: Set Pan(W) | C15: 3140 | D15: 1462 | E15: 1678
A16: 7 | B16: Hlyat Sit Kone(W) | C16: 2417 | D16: 1107 | E16: 1310
A17: 8 | B17: Pein Hne Kone(W) | C17: 1630 | D17: 784 | E17: 846
A18: 9 | B18: Pa Da Myar(W) | C18: 5902 | D18: 2876 | E18: 3026
A19: 10 | B19: Tha Hpan Saing(W) | C19: 2174 | D19: 1087 | E19: 1087
B20: Village Tract | C20: =SUM(C21:C52) -> 141002 | D20: =SUM(D21:D52) -> 69393 | E20: =SUM(E21:E52) -> 71609
A21: 1 | B21: Auk Wea Gyi(VT) | C21: 4738 | D21: 2341 | E21: 2397
A22: 2 | B22: Tone Paw(VT) | C22: 2148 | D22: 1125 | E22: 1023
A23: 3 | B23: Pa Lway Shwe(VT) | C23: 6397 | D23: 3173 | E23: 3224
A24: 4 | B24: Kyan Taw(VT) | C24: 3547 | D24: 1716 | E24: 1831
A25: 5 | B25: Lan Gwa(VT) | C25: 2310 | D25: 1121 | E25: 1189
A26: 6 | B26: Meik Tha Lin(VT) | C26: 4193 | D26: 1994 | E26: 2199
A27: 7 | B27: Sa Kar Kone(VT) | C27: 8410 | D27: 4264 | E27: 4146
A28: 8 | B28: Kyauk Htone Gyi(VT) | C28: 9510 | D28: 4669 | E28: 4841
A29: 9 | B29: Done Awt(VT) | C29: 2099 | D29: 1039 | E29: 1060
A30: 10 | B30: Kone Thar(VT) | C30: 5474 | D30: 2696 | E30: 2778
A31: 11 | B31: Chaung Wa(VT) | C31: 2237 | D31: 1129 | E31: 1108
A32: 12 | B32: Hmat Taing(VT) | C32: 2717 | D32: 1338 | E32: 1379
... A52: 32 | B52: Ku Kar(VT) | C52: 5655 | D52: 2751 | E52: 2904

Sheet Indaw
A1: Sagaing Region, Katha District ,Indaw Township
E2: 29-3-2014
A5: Sr | B5: Ward/Village Tract | C5: Population
C6: Total | D6: Male | E6: Female
B7: Total | C7: =C9+C14 -> 120266 | D7: =D9+D14 -> 56814 | E7: =E9+E14 -> 63452
B9: Ward | C9: =SUM(C10:C13) -> 8529 | D9: =SUM(D10:D13) -> 3898 | E9: =SUM(E10:E13) -> 4631
A10: 1 | B10: Aung Min Ga Lar(W) | C10: 1668 | D10: 749 | E10: 919
A11: 2 | B11: Aung Chan Thar(W) | C11: 1383 | D11: 605 | E11: 778
A12: 3 | B12: Aung Zay Yar(W) | C12: 1835 | D12: 838 | E12: 997
A13: 4 | B13: Aung Myit Tar(W) | C13: 3643 | D13: 1706 | E13: 1937
B14: Village Tract | C14: =SUM(C15:C53) -> 111737 | D14: =SUM(D15:D53) -> 52916 | E14: =SUM(E15:E53) -> 58821
A15: 1 | B15: Nant Khin(VT) | C15: 2820 | D15: 1360 | E15: 1460
A16: 2 | B16: Nat Ma Hoke(VT) | C16: 2807 | D16: 1325 | E16: 1482
A17: 3 | B17: Se(VT) | C17: 1213 | D17: 522 | E17: 691
A18: 4 | B18: Thet Kei Kyin(VT) | C18: 2170 | D18: 1030 | E18: 1140
A19: 5 | B19: Lel Pyin(VT) | C19: 3901 | D19: 1908 | E19: 1993
A20: 6 | B20: Na Bar(VT) | C20: 5763 | D20: 2778 | E20: 2985
A21: 7 | B21: Seik Thar(VT) | C21: 2249 | D21: 981 | E21: 1268
A22: 8 | B22: Kyan Taw(VT) | C22: 2025 | D22: 965 | E22: 1060
A23: 9 | B23: Ta Khun Taing(VT) | C23: 1934 | D23: 896 | E23: 1038
A24: 10 | B24: Myauk Kone (Man Lel)(VT) | C24: 4465 | D24: 2020 | E24: 2445
A25: 11 | B25: Me Zar(VT) | C25: 7354 | D25: 3441 | E25: 3913
A26: 12 | B26: Oke Shit Kone(VT) | C26: 1694 | D26: 803 | E26: 891
... A53: 39 | B53: Pin Wei(VT) | C53: 2955 | D53: 1425 | E53: 1530

Sheet Tigyaing
A1: Sagaing Region, Katha District ,Tigyaing Township
E2: 29-3-2014
A5: Sr | B5: Ward/Village Tract | C5: Population
C6: Total | D6: Male | E6: Female
B7: Total | C7: =C9+C14 -> 129955 | D7: =D9+D14 -> 63736 | E7: =E9+E14 -> 66219
B9: Ward | C9: =SUM(C10:C13) -> 13535 | D9: =SUM(D10:D13) -> 6395 | E9: =SUM(E10:E13) -> 7140
A10: 1 | B10: San Pya(Aun San San Pya )(W) | C10: 3677 | D10: 1722 | E10: 1955
A11: 2 | B11: Aung Zay Yar(W) | C11: 5215 | D11: 2446 | E11: 2769
A12: 3 | B12: Wi Thar Khar(W) | C12: 1926 | D12: 910 | E12: 1016
A13: 4 | B13: Ba Yint Naung(W) | C13: 2717 | D13: 1317 | E13: 1400
B14: Village Tract | C14: =SUM(C15:C43) -> 116420 | D14: =SUM(D15:D43) -> 57341 | E14: =SUM(E15:E43) -> 59079
A15: 1 | B15: Kun Baung (Kwin Baung)(VT) | C15: 2592 | D15: 1250 | E15: 1342
A16: 2 | B16: Kyauk Aik(VT) | C16: 2411 | D16: 1197 | E16: 1214
A17: 3 | B17: Ah Lel Taw(VT) | C17: 3846 | D17: 1865 | E17: 1981
A18: 4 | B18: Lay Thar(VT) | C18: 3303 | D18: 1603 | E18: 1700
A19: 5 | B19: Kan Pauk(VT) | C19: 2517 | D19: 1220 | E19: 1297
A20: 6 | B20: Zee Thaung(VT) | C20: 2149 | D20: 1070 | E20: 1079
A21: 7 | B21: Kwin Gyi(VT) | C21: 2973 | D21: 1411 | E21: 1562
A22: 8 | B22: Sin Hpyu Seik(VT) | C22: 3256 | D22: 1521 | E22: 1735
A23: 9 | B23: Tei Taw(VT) | C23: 3395 | D23: 1631 | E23: 1764
A24: 10 | B24: Me Hin(VT) | C24: 3451 | D24: 1731 | E24: 1720
A25: 11 | B25: Kyet Ta Kaung(VT) | C25: 6918 | D25: 3367 | E25: 3551
A26: 12 | B26: In Daung(VT) | C26: 5661 | D26: 2818 | E26: 2843
... A43: 29 | B43: Sit Tan(VT) | C43: 1722 | D43: 818 | E43: 904

Sheet Banmauk
A1: Sagaing Region, Katha District , Banmauk Township
E2: 29-3-2014
A5: Sr | B5: Ward/Village Tract | C5: Population
C6: Total | D6: Male | E6: Female
B7: Total | C7: =C9+C13 -> 112668 | D7: =D9+D13 -> 57195 | E7: =E9+E13 -> 55473
B9: Ward | C9: =SUM(C10:C12) -> 6165 | D9: =SUM(D10:D12) -> 2883 | E9: =SUM(E10:E12) -> 3282
A10: 1 | B10: Mya Nan Dar(W) | C10: 2043 | D10: 931 | E10: 1112
A11: 2 | B11: Myo Ma (W) | C11: 3129 | D11: 1466 | E11: 1663
A12: 3 | B12: Hlwa Sin Kone(W) | C12: 993 | D12: 486 | E12: 507
B13: Village Tract | C13: =SUM(C14:C61) -> 106503 | D13: =SUM(D14:D61) -> 54312 | E13: =SUM(E14:E61) -> 52191
A14: 1 | B14: Aung Thar Kone(VT) | C14: 2387 | D14: 1113 | E14: 1274
A15: 2 | B15: Let Net Gyi(VT) | C15: 1782 | D15: 692 | E15: 1090
A16: 3 | B16: Set Taw(VT) | C16: 1504 | D16: 655 | E16: 849
A17: 4 | B17: Kan(VT) | C17: 830 | D17: 373 | E17: 457
A18: 5 | B18: Kho Nan(VT) | C18: 945 | D18: 436 | E18: 509
A19: 6 | B19: Pin Hin Khar(VT) | C19: 2298 | D19: 1067 | E19: 1231
A20: 7 | B20: Lay Thi(VT) | C20: 1928 | D20: 920 | E20: 1008
A21: 8 | B21: Kywe Kaw Gyi(VT) | C21: 2542 | D21: 1311 | E21: 1231
A22: 9 | B22: Lone Kin Shwe Kyaung(VT) | C22: 2837 | D22: 1354 | E22: 1483
A23: 10 | B23: Tone Hlaw(VT) | C23: 1554 | D23: 746 | E23: 808
A24: 11 | B24: Kaing Gyi(VT) | C24: 1791 | D24: 897 | E24: 894
A25: 12 | B25: Ohn Hmin(VT) | C25: 1311 | D25: 684 | E25: 627
... A61: 48 | B61: Forest EA | C61: 448 | D61: 307 | E61: 141

Sheet Kawlin
A1: Sagaing Region, Katha District , Kawlin Township
E2: 29-3-2014
A5: Sr | B5: Ward/Village Tract | C5: Population
C6: Total | D6: Male | E6: Female
B7: Total | C7: =C9+C16 -> 145297 | D7: =D9+D16 -> 69782 | E7: =E9+E16 -> 75515
B9: Ward | C9: =SUM(C10:C15) -> 21431 | D9: =SUM(D10:D15) -> 9957 | E9: =SUM(E10:E15) -> 11474
A10: 1 | B10: Myauk Inn(W) | C10: 4838 | D10: 2299 | E10: 2539
A11: 2 | B11: Yae Kyaw(W) | C11: 7176 | D11: 3390 | E11: 3786
A12: 3 | B12: Zay Yon Bo Te(W) | C12: 2771 | D12: 1260 | E12: 1511
A13: 4 | B13: Myo Ma Myo Kone(W) | C13: 2346 | D13: 1055 | E13: 1291
A14: 5 | B14: Pyin Oo Lwin(W) | C14: 2046 | D14: 901 | E14: 1145
A15: 6 | B15: Set Yon Lel Pyin(W) | C15: 2254 | D15: 1052 | E15: 1202
B16: Village Tract | C16: =SUM(C17:C63) -> 123866 | D16: =SUM(D17:D63) -> 59825 | E16: =SUM(E17:E63) -> 64041
A17: 1 | B17: Lar Kar(VT) | C17: 2067 | D17: 998 | E17: 1069
A18: 2 | B18: Aing Gyi(VT) | C18: 4268 | D18: 2051 | E18: 2217
A19: 3 | B19: Kyoet Pin(VT) | C19: 3735 | D19: 1804 | E19: 1931
A20: 4 | B20: Ta Gaung Aing(VT) | C20: 1114 | D20: 508 | E20: 606
A21: 5 | B21: Moe Hnan(VT) | C21: 3010 | D21: 1557 | E21: 1453
A22: 6 | B22: Tha Yet Chin(VT) | C22: 3198 | D22: 1600 | E22: 1598
A23: 7 | B23: Yin Taik(VT) | C23: 2555 | D23: 1281 | E23: 1274
A24: 8 | B24: Pan Ma Ye(VT) | C24: 3781 | D24: 1847 | E24: 1934
A25: 9 | B25: Taung Kyar(VT) | C25: 5667 | D25: 2839 | E25: 2828
A26: 10 | B26: Oke Kan(VT) | C26: 4233 | D26: 2038 | E26: 2195
A27: 11 | B27: Shwe Twin(VT) | C27: 1196 | D27: 583 | E27: 613
A28: 12 | B28: Shan Ka Lone(VT) | C28: 3834 | D28: 1978 | E28: 1856
... A63: 47 | B63: Taung Boet Hla(VT) | C63: 3450 | D63: 1672 | E63: 1778

Sheet Wuntho
A1: Sagaing Region, Katha District ,Wuntho Township
E2: 29-3-2014
A5: Sr | B5: Ward/Village Tract | C5: Population
C6: Total | D6: Male | E6: Female
B7: Total | C7: =C9+C14 -> 73395 | D7: =D9+D14 -> 35465 | E7: =E9+E14 -> 37930
B9: Ward | C9: =SUM(C10:C13) -> 11972 | D9: =SUM(D10:D13) -> 5598 | E9: =SUM(E10:E13) -> 6374
A10: 1 | B10: Shwe Wun Thi Dar(W) | C10: 3927 | D10: 1885 | E10: 2042
A11: 2 | B11: Saw Bwar Gyi(W) | C11: 2607 | D11: 1188 | E11: 1419
A12: 3 | B12: Kya Maing(W) | C12: 1313 | D12: 600 | E12: 713
A13: 4 | B13: Sit Ke Gyi(W) | C13: 4125 | D13: 1925 | E13: 2200
B14: Village Tract | C14: =SUM(C15:C52) -> 61423 | D14: =SUM(D15:D52) -> 29867 | E14: =SUM(E15:E52) -> 31556
A15: 1 | B15: Met Ka Let(VT) | C15: 535 | D15: 258 | E15: 277
A16: 2 | B16: Pan Tein Kone(VT) | C16: 778 | D16: 349 | E16: 429
A17: 3 | B17: Na Maw Gyi(VT) | C17: 1184 | D17: 589 | E17: 595
A18: 4 | B18: Myauk Lel(VT) | C18: 1112 | D18: 500 | E18: 612
A19: 5 | B19: Yae Wai Myin Thar(VT) | C19: 1119 | D19: 499 | E19: 620
A20: 6 | B20: Tat Kone(VT) | C20: 1712 | D20: 813 | E20: 899
A21: 7 | B21: Kyauk Ma Sin(VT) | C21: 1199 | D21: 627 | E21: 572
A22: 8 | B22: Kyaing Khwin(VT) | C22: 533 | D22: 237 | E22: 296
A23: 9 | B23: Win Gyi(VT) | C23: 2086 | D23: 1019 | E23: 1067
A24: 10 | B24: Ma Gyi Kone(VT) | C24: 1666 | D24: 850 | E24: 816
A25: 11 | B25: Ahr Ma Khan(VT) | C25: 1213 | D25: 567 | E25: 646
A26: 12 | B26: Kyauk Pauk Khon(VT) | C26: 552 | D26: 254 | E26: 298
... A52: 38 | B52: Gyoe Taung(VT) | C52: 3462 | D52: 1623 | E52: 1839

Sheet Pinlebu
A1: Sagaing Region, Katha District , Pinlebu Township
E2: 29-3-2014
A5: Sr | B5: Ward/Village Tract | C5: Population
C6: Total | D6: Male | E6: Female
B7: Total | C7: =C9+C12 -> 111968 | D7: =D9+D12 -> 52393 | E7: =E9+E12 -> 59575
B9: Ward | C9: =SUM(C10:C11) -> 6963 | D9: =SUM(D10:D11) -> 3259 | E9: =SUM(E10:E11) -> 3704
A10: 1 | B10: Moe Kaung(W) | C10: 3648 | D10: 1699 | E10: 1949
A11: 2 | B11: Myo Ma(W) | C11: 3315 | D11: 1560 | E11: 1755
B12: Village Tract | C12: =SUM(C13:C64) -> 105005 | D12: =SUM(D13:D64) -> 49134 | E12: =SUM(E13:E64) -> 55871
A13: 1 | B13: Ka Thaw(VT) | C13: 2820 | D13: 1296 | E13: 1524
A14: 2 | B14: Pin Kyaing(VT) | C14: 4764 | D14: 2065 | E14: 2699
A15: 3 | B15: Sin Laung (Khin Laung)(VT) | C15: 1618 | D15: 782 | E15: 836
A16: 4 | B16: Kan Kone(VT) | C16: 1179 | D16: 521 | E16: 658
A17: 5 | B17: Kat Pan Tar(VT) | C17: 1730 | D17: 776 | E17: 954
A18: 6 | B18: Maw Lin(VT) | C18: 573 | D18: 270 | E18: 303
A19: 7 | B19: Maw Khar(VT) | C19: 984 | D19: 509 | E19: 475
A20: 8 | B20: Kyun Taw(VT) | C20: 875 | D20: 429 | E20: 446
A21: 9 | B21: Nan Tat(VT) | C21: 5206 | D21: 2487 | E21: 2719
A22: 10 | B22: Naung Pu Inn(VT) | C22: 2367 | D22: 1117 | E22: 1250
A23: 11 | B23: Pin Maung(VT) | C23: 2379 | D23: 1091 | E23: 1288
A24: 12 | B24: Yin Thar(VT) | C24: 2288 | D24: 1067 | E24: 1221
... A64: 52 | B64: War Yon Kone(VT) | C64: 1475 | D64: 654 | E64: 821

Sheet Kalay
A1: Sagaing Region, Kalay District , Kalay Township
E2: 29-3-2014
A5: Sr | B5: Ward/Village Tract | C5: Population
C6: Total | D6: Male | E6: Female
B7: Total | C7: =C9+C29 -> 348573 | D7: =D9+D29 -> 167558 | E7: =E9+E29 -> 181015
B9: Ward | C9: =SUM(C10:C28) -> 130506 | D9: =SUM(D10:D28) -> 60657 | E9: =SUM(E10:E28) -> 69849
A10: 1 | B10: Nyaung Pin Thar(W) | C10: 4845 | D10: 2196 | E10: 2649
A11: 2 | B11: Mingalar U Yin(W) | C11: 5141 | D11: 2434 | E11: 2707
A12: 3 | B12: Aung Min Ga Lar(W) | C12: 5040 | D12: 2370 | E12: 2670
A13: 4 | B13: Aung Myay Man(W) | C13: 5116 | D13: 2388 | E13: 2728
A14: 5 | B14: Aung Thit Sar(W) | C14: 7278 | D14: 3516 | E14: 3762
A15: 6 | B15: Aung Zaya(W) | C15: 3660 | D15: 1678 | E15: 1982
A16: 7 | B16: Pin Lon (W) | C16: 6075 | D16: 2864 | E16: 3211
A17: 8 | B17: Chan Myayt Aung Si(W) | C17: 12538 | D17: 6031 | E17: 6507
A18: 9 | B18: Tat U Thida(W) | C18: 8984 | D18: 4246 | E18: 4738
A19: 10 | B19: Thazin(W) | C19: 6598 | D19: 3006 | E19: 3592
A20: 11 | B20: Tar Han(W) | C20: 14876 | D20: 6841 | E20: 8035
A21: 12 | B21: San Myo(W) | C21: 8121 | D21: 3681 | E21: 4440
... A28: 19 | B28: Myo Thar(W) | C28: 2511 | D28: 1219 | E28: 1292
B29: Village Tract | C29: =SUM(C30:C70) -> 218067 | D29: =SUM(D30:D70) -> 106901 | E29: =SUM(E30:E70) -> 111166
A30: 1 | B30: Thar Si(VT) | C30: 11247 | D30: 5339 | E30: 5908
A31: 2 | B31: Kan Pale(VT) | C31: 3743 | D31: 1843 | E31: 1900
A32: 3 | B32: Kan Gyi(VT) | C32: 3979 | D32: 2012 | E32: 1967
A33: 4 | B33: Nan Saung Pu(VT) | C33: 2872 | D33: 1400 | E33: 1472
A34: 5 | B34: Sa Khan Gyi(VT) | C34: 8148 | D34: 3958 | E34: 4190
A35: 6 | B35: Pyin Taw U(VT) | C35: 15147 | D35: 7372 | E35: 7775
A36: 7 | B36: Maw Laik Ka Lay(VT) | C36: 3606 | D36: 2300 | E36: 1306
A37: 8 | B37: Pyin Khon Gyi(VT) | C37: 5832 | D37: 2722 | E37: 3110
A38: 9 | B38: Yar Za Gyo(VT) | C38: 6823 | D38: 3545 | E38: 3278
A39: 10 | B39: Saw Bwar Yae Shin(VT) | C39: 5996 | D39: 2976 | E39: 3020
A40: 11 | B40: Mauk Lin(VT) | C40: 19442 | D40: 9156 | E40: 10286
A41: 12 | B41: Nat Gyi Kone (Kyauk Kar)(VT) | C41: 3841 | D41: 1993 | E41: 1848
... A70: 41 | B70: Koke Ko(VT) | C70: 3006 | D70: 1490 | E70: 1516

Sheet Kalewa
A1: Sagaing Region, Kalay District , Kalewa Township
E2: 29-3-2014
A5: Sr | B5: Ward/Village Tract | C5: Population
C6: Total | D6: Male | E6: Female
B7: Total | C7: =C9+C13 -> 56432 | D7: =D9+D13 -> 27715 | E7: =E9+E13 -> 28717
B9: Ward | C9: =SUM(C10:C12) -> 8819 | D9: =SUM(D10:D12) -> 4168 | E9: =SUM(E10:E12) -> 4651
A10: 1 | B10: No (1) Ywar Thit(W) | C10: 3152 | D10: 1487 | E10: 1665
A11: 2 | B11: No (2) Aung Chan Thar(W) | C11: 3970 | D11: 1862 | E11: 2108
A12: 3 | B12: No (3) Aung Min Ga Lar(W) | C12: 1697 | D12: 819 | E12: 878
B13: Village Tract | C13: =SUM(C14:C49) -> 47613 | D13: =SUM(D14:D49) -> 23547 | E13: =SUM(E14:E49) -> 24066
A14: 1 | B14: Kyaw Zin(VT) | C14: 2548 | D14: 1228 | E14: 1320
A15: 2 | B15: Kya Khat Taw(VT) | C15: 517 | D15: 258 | E15: 259
A16: 3 | B16: Auk Taw Gyi(VT) | C16: 560 | D16: 265 | E16: 295
A17: 4 | B17: Se Gyi(VT) | C17: 1376 | D17: 649 | E17: 727
A18: 5 | B18: Kaing(VT) | C18: 1955 | D18: 936 | E18: 1019
A19: 6 | B19: Thit Chauk(VT) | C19: 3897 | D19: 2013 | E19: 1884
A20: 7 | B20: Thet Kei Kyin(VT) | C20: 3478 | D20: 1745 | E20: 1733
A21: 8 | B21: Khaung Tee(VT) | C21: 991 | D21: 497 | E21: 494
A22: 9 | B22: Sin Gaung(VT) | C22: 1052 | D22: 521 | E22: 531
A23: 10 | B23: Kywe Ku(VT) | C23: 745 | D23: 356 | E23: 389
A24: 11 | B24: Thin Gan(VT) | C24: 1095 | D24: 545 | E24: 550
A25: 12 | B25: Ga Zet(VT) | C25: 1196 | D25: 563 | E25: 633
... A49: 36 | B49: Khon Gyi(VT) | C49: 1575 | D49: 821 | E49: 754

Sheet Mingin
A1: Sagaing Region, Kalay District , Mingin Township
E2: 29-3-2014
A5: Sr | B5: Ward/Village Tract | C5: Population
C6: Total | D6: Male | E6: Female
B7: Total | C7: =SUM(C9+C13) -> 104363 | D7: =SUM(D9+D13) -> 50171 | E7: =SUM(E9+E13) -> 54192
B9: Ward | C9: =SUM(C10:C12) -> 3467 | D9: =SUM(D10:D12) -> 1579 | E9: =SUM(E10:E12) -> 1888
A10: 1 | B10: Myo Ma(W) | C10: 943 | D10: 435 | E10: 508
A11: 2 | B11: Zay Tan(W) | C11: 1255 | D11: 572 | E11: 683
A12: 3 | B12: Tha Yet Taw(W) | C12: 1269 | D12: 572 | E12: 697
B13: Village Tract | C13: =SUM(C14:C74) -> 100896 | D13: =SUM(D14:D74) -> 48592 | E13: =SUM(E14:E74) -> 52304
A14: 1 | B14: Au (Bu)(VT) | C14: 1985 | D14: 951 | E14: 1034
A15: 2 | B15: Chaung Wa(VT) | C15: 664 | D15: 320 | E15: 344
A16: 3 | B16: Tein(VT) | C16: 1892 | D16: 944 | E16: 948
A17: 4 | B17: Myin U(VT) | C17: 974 | D17: 463 | E17: 511
A18: 5 | B18: Myo Ma(VT) | C18: 1365 | D18: 656 | E18: 709
A19: 6 | B19: Myay Ni(VT) | C19: 1176 | D19: 580 | E19: 596
A20: 7 | B20: Peik Ka Yar(VT) | C20: 1565 | D20: 764 | E20: 801
A21: 8 | B21: Yin Mar(VT) | C21: 964 | D21: 459 | E21: 505
A22: 9 | B22: Kyar Pin(VT) | C22: 1279 | D22: 612 | E22: 667
A23: 10 | B23: Ah Nauk Taing(VT) | C23: 679 | D23: 335 | E23: 344
A24: 11 | B24: Mei Me(VT) | C24: 1440 | D24: 654 | E24: 786
A25: 12 | B25: Pyar Thone(VT) | C25: 997 | D25: 464 | E25: 533
... A74: 61 | B74: Kyauk Tan(VT) | C74: 982 | D74: 492 | E74: 490

Sheet Tamu
A1: Sagaing Region, Tamu District , Tamu Township
E2: 29-3-2014
A5: Sr | B5: Ward/Village Tract | C5: Population
C6: Total | D6: Male | E6: Female
B7: Total | C7: =SUM(C9+C14) -> 59343 | D7: =SUM(D9+D14) -> 29239 | E7: =SUM(E9+E14) -> 30104
B9: Ward | C9: =SUM(C10:C13) -> 43737 | D9: =SUM(D10:D13) -> 21295 | E9: =SUM(E10:E13) -> 22442
A10: 1 | B10: Tamu Myo Ma(W) | C10: 13801 | D10: 6853 | E10: 6948
A11: 2 | B11: Zay Tan(W) | C11: 11106 | D11: 5205 | E11: 5901
A12: 3 | B12: San Da Ku(W) | C12: 5806 | D12: 2810 | E12: 2996
A13: 4 | B13: Saw Bwar Inn(W) | C13: 13024 | D13: 6427 | E13: 6597
B14: Village Tract | C14: =SUM(C15:C21) -> 15606 | D14: =SUM(D15:D21) -> 7944 | E14: =SUM(E15:E21) -> 7662
A15: 1 | B15: Kun Taung(VT) | C15: 1989 | D15: 1105 | E15: 884
A16: 2 | B16: He Zin(VT) | C16: 1958 | D16: 977 | E16: 981
A17: 3 | B17: In Daing(VT) | C17: 4755 | D17: 2397 | E17: 2358
A18: 4 | B18: Ah Hlaw(VT) | C18: 797 | D18: 418 | E18: 379
A19: 5 | B19: Kha Meik(VT) | C19: 3346 | D19: 1704 | E19: 1642
A20: 6 | B20: Wi Toke(VT) | C20: 2009 | D20: 1003 | E20: 1006
A21: 7 | B21: Put Thar(VT) | C21: 752 | D21: 340 | E21: 412

Sheet Myothit(S)
A1: Sagaing Region, Tamu District , Myothit Sub-Township
E2: 29-3-2014
A5: Sr | B5: Ward/Village Tract | C5: Population
C6: Total | D6: Male | E6: Female
B7: Total | C7: =C9+C13 -> 16798 | D7: =D9+D13 -> 8760 | E7: =E9+E13 -> 8038
B9: Ward | C9: =SUM(C10:C12) -> 1642 | D9: =SUM(D10:D12) -> 917 | E9: =SUM(E10:E12) -> 725
A10: 1 | B10: No (1)(W) | C10: 227 | D10: 111 | E10: 116
A11: 2 | B11: No (2)(W) | C11: 548 | D11: 360 | E11: 188
A12: 3 | B12: No (3)(W) | C12: 867 | D12: 446 | E12: 421
B13: Village Tract | C13: =SUM(C14:C19) -> 15156 | D13: =SUM(D14:D19) -> 7843 | E13: =SUM(E14:E19) -> 7313
A14: 1 | B14: Hpaing Lin(VT) | C14: 3066 | D14: 1591 | E14: 1475
A15: 2 | B15: Tha Nan(VT) | C15: 1293 | D15: 708 | E15: 585
A16: 3 | B16: Ban Du La(VT) | C16: 2936 | D16: 1583 | E16: 1353
A17: 4 | B17: Min Thar(VT) | C17: 4030 | D17: 2022 | E17: 2008
A18: 5 | B18: Hle Seik(VT) | C18: 1167 | D18: 597 | E18: 570
A19: 6 | B19: Htone Ka Tin(VT) | C19: 2664 | D19: 1342 | E19: 1322

Sheet Khampat(S)
A1: Sagaing Region, Tamu District , Khampat Sub-Township
E2: 29-3-2014
A5: Sr | B5: Ward/Village Tract | C5: Population
C6: Total | D6: Male | E6: Female
B7: Total | C7: =C9+C15 -> 38728 | D7: =D9+D15 -> 19008 | E7: =E9+E15 -> 19720
B9: Ward | C9: =SUM(C10:C14) -> 14559 | D9: =SUM(D10:D14) -> 7004 | E9: =SUM(E10:E14) -> 7555
A10: 1 | B10: No (1)(W) | C10: 3575 | D10: 1636 | E10: 1939
A11: 2 | B11: No (2)(W) | C11: 3978 | D11: 1927 | E11: 2051
A12: 3 | B12: No (3)(W) | C12: 1833 | D12: 874 | E12: 959
A13: 4 | B13: No (4)(W) | C13: 3798 | D13: 1866 | E13: 1932
A14: 5 | B14: No (5)(W) | C14: 1375 | D14: 701 | E14: 674
B15: Village Tract | C15: =SUM(C16:C23) -> 24169 | D15: =SUM(D16:D23) -> 12004 | E15: =SUM(E16:E23) -> 12165
A16: 1 | B16: Auk Taung(VT) | C16: 4269 | D16: 2163 | E16: 2106
A17: 2 | B17: Sun Lel(VT) | C17: 1927 | D17: 961 | E17: 966
A18: 3 | B18: Ywar Thar(VT) | C18: 485 | D18: 256 | E18: 229
A19: 4 | B19: Min Tha Mee(VT) | C19: 1627 | D19: 840 | E19: 787
A20: 5 | B20: Ma Lu(VT) | C20: 1179 | D20: 604 | E20: 575
A21: 6 | B21: Htin Zin(VT) | C21: 4355 | D21: 2168 | E21: 2187
A22: 7 | B22: Ka Nan(VT) | C22: 6865 | D22: 3390 | E22: 3475
A23: 8 | B23: Kyun Taw Yae Shin(VT) | C23: 3462 | D23: 1622 | E23: 1840

Sheet Mawlaik
A1: Sagaing Region, Mawlaik District , Mawlaik Township
E2: 29-3-2014
A5: Sr | B5: Ward/Village Tract | C5: Population
C6: Total | D6: Male | E6: Female
B7: Total | C7: =C9+C12 -> 51314 | D7: =D9+D12 -> 25055 | E7: =E9+E12 -> 26259
B9: Ward | C9: =SUM(C10:C11) -> 8556 | D9: =SUM(D10:D11) -> 4401 | E9: =SUM(E10:E11) -> 4155
A10: 1 | B10: Myo Ma (1)(W) | C10: 3109 | D10: 1503 | E10: 1606
A11: 2 | B11: Myo Ma (2)(W) | C11: 5447 | D11: 2898 | E11: 2549
B12: Village Tract | C12: =SUM(C13:C40) -> 42758 | D12: =SUM(D13:D40) -> 20654 | E12: =SUM(E13:E40) -> 22104
A13: 1 | B13: Yu Wa(VT) | C13: 2025 | D13: 984 | E13: 1041
A14: 2 | B14: Khar Wea(VT) | C14: 2136 | D14: 1014 | E14: 1122
A15: 3 | B15: Khar Tun(VT) | C15: 1011 | D15: 492 | E15: 519
A16: 4 | B16: War Yon Thar(VT) | C16: 2260 | D16: 1059 | E16: 1201
A17: 5 | B17: Pan Thar(VT) | C17: 1431 | D17: 710 | E17: 721
A18: 6 | B18: Tat Kone(VT) | C18: 2729 | D18: 1358 | E18: 1371
A19: 7 | B19: Hpe Ka Zet(VT) | C19: 1089 | D19: 542 | E19: 547
A20: 8 | B20: Tein Thar(VT) | C20: 935 | D20: 450 | E20: 485
A21: 9 | B21: Nar Pin(VT) | C21: 865 | D21: 412 | E21: 453
A22: 10 | B22: Kin Tat(VT) | C22: 4335 | D22: 2013 | E22: 2322
A23: 11 | B23: Hmaw Ku(VT) | C23: 1471 | D23: 726 | E23: 745
A24: 12 | B24: Tun Pin(VT) | C24: 1369 | D24: 659 | E24: 710
... A40: 28 | B40: Law Thar(VT) | C40: 1077 | D40: 570 | E40: 507

Sheet Phaungpyin
A1: Sagaing Region, Mawlaik District , Phaungpyin Township
E2: 29-3-2014
A5: Sr | B5: Ward/Village Tract | C5: Population
C6: Total | D6: Male | E6: Female
B7: Total | C7: =C9+C12 -> 112694 | D7: =D9+D12 -> 53869 | E7: =E9+E12 -> 58825
B9: Ward | C9: =SUM(C10:C11) -> 10049 | D9: =SUM(D10:D11) -> 4905 | E9: =SUM(E10:E11) -> 5144
A10: 1 | B10: Kyun Shwe War(W) | C10: 3578 | D10: 1694 | E10: 1884
A11: 2 | B11: In Gyin Myaing(W) | C11: 6471 | D11: 3211 | E11: 3260
B12: Village Tract | C12: =SUM(C13:C52) -> 102645 | D12: =SUM(D13:D52) -> 48964 | E12: =SUM(E13:E52) -> 53681
A13: 1 | B13: Pin Thar(VT) | C13: 1464 | D13: 706 | E13: 758
A14: 2 | B14: He Hlaw(VT) | C14: 4481 | D14: 2116 | E14: 2365
A15: 3 | B15: Tha Yaung(VT) | C15: 4838 | D15: 2252 | E15: 2586
A16: 4 | B16: Kha Maing(VT) | C16: 1320 | D16: 646 | E16: 674
A17: 5 | B17: Ywar Tan Shey(VT) | C17: 3073 | D17: 1564 | E17: 1509
A18: 6 | B18: Shwe Nyaung Pin(VT) | C18: 2704 | D18: 1255 | E18: 1449
A19: 7 | B19: Maing Nwe(VT) | C19: 2180 | D19: 1006 | E19: 1174
A20: 8 | B20: Nan Bone(VT) | C20: 2253 | D20: 1113 | E20: 1140
A21: 9 | B21: Bar He(VT) | C21: 2580 | D21: 1264 | E21: 1316
A22: 10 | B22: Mauk Sa Hpar(VT) | C22: 2610 | D22: 1251 | E22: 1359
A23: 11 | B23: Mauk Pa Lin(VT) | C23: 2958 | D23: 1453 | E23: 1505
A24: 12 | B24: Yae Auk Taung(VT) | C24: 2797 | D24: 1362 | E24: 1435
... A52: 40 | B52: Myin Thar(VT) | C52: 1452 | D52: 662 | E52: 790

Sheet Hkamti
A1: Sagaing Region, Hkamti District , Hkamti Township
E2: 29-3-2014
A5: Sr | B5: Ward/Village Tract | C5: Population
C6: Total | D6: Male | E6: Female
B7: Total | C7: =C9+C13 -> 47658 | D7: =D9+D13 -> 26916 | E7: =E9+E13 -> 20742
B9: Ward | C9: =SUM(C10:C12) -> 11551 | D9: =SUM(D10:D12) -> 5881 | E9: =SUM(E10:E12) -> 5670
A10: 1 | B10: Paw Maing(W) | C10: 3358 | D10: 1615 | E10: 1743
A11: 2 | B11: Hkamti Myo Ma(W) | C11: 3233 | D11: 1568 | E11: 1665
A12: 3 | B12: Zee Hpyu Kone(W) | C12: 4960 | D12: 2698 | E12: 2262
B13: Village Tract | C13: =SUM(C14:C41) -> 36107 | D13: =SUM(D14:D41) -> 21035 | E13: =SUM(E14:E41) -> 15072
A14: 1 | B14: Taik Tee(VT) | C14: 1205 | D14: 758 | E14: 447
A15: 2 | B15: Hpaung Saing(VT) | C15: 723 | D15: 423 | E15: 300
A16: 3 | B16: Pa Du Mone(VT) | C16: 7996 | D16: 5360 | E16: 2636
A17: 4 | B17: Nant Hpar(VT) | C17: 2679 | D17: 1716 | E17: 963
A18: 5 | B18: Hman Pin(VT) | C18: 2616 | D18: 1479 | E18: 1137
A19: 6 | B19: Aung Myay(VT) | C19: 1366 | D19: 883 | E19: 483
A20: 7 | B20: Kin Taw(VT) | C20: 1408 | D20: 657 | E20: 751
A21: 8 | B21: Sin Thay(VT) | C21: 2611 | D21: 1280 | E21: 1331
A22: 9 | B22: Laung Sauk(VT) | C22: 443 | D22: 226 | E22: 217
A23: 10 | B23: Hat Ti(VT) | C23: 327 | D23: 181 | E23: 146
A24: 11 | B24: Par Saung(VT) | C24: 668 | D24: 376 | E24: 292
A25: 12 | B25: Kyauk Ywet(VT) | C25: 363 | D25: 197 | E25: 166
... A41: 28 | B41: Min Sin(VT) | C41: 1789 | D41: 1044 | E41: 745

Sheet Homalin
A1: Sagaing Region, Hkamti District , Homalin Township
E2: 29-3-2014
A5: Sr | B5: Ward/Village Tract | C5: Population
C6: Total | D6: Male | E6: Female
B7: Total | C7: =C9+C18 -> 258206 | D7: =D9+D18 -> 133750 | E7: =E9+E18 -> 124456
B9: Ward | C9: =SUM(C11:C17) -> 21220 | D9: =SUM(D11:D17) -> 10958 | E9: =SUM(E11:E17) -> 10262
A11: 1 | B11: Homalin(W) | C11: 5001 | D11: 2450 | E11: 2551
A12: 2 | B12: Naung Pa Kyit(W) | C12: 12537 | D12: 6599 | E12: 5938
B13: Shwe Pyi Aye Town
A14: 1 | B14: No(1)(W) | C14: 399 | D14: 198 | E14: 201
A15: 2 | B15: No(2)(W) | C15: 184 | D15: 101 | E15: 83
A16: 3 | B16: No(3)(W) | C16: 2168 | D16: 1121 | E16: 1047
A17: 4 | B17: No(4)(W) | C17: 931 | D17: 489 | E17: 442
B18: Village Tract | C18: =SUM(C19:C94) -> 236986 | D18: =SUM(D19:D94) -> 122792 | E18: =SUM(E19:E94) -> 114194
A19: 1 | B19: Khaung Khan(VT) | C19: 3620 | D19: 1662 | E19: 1958
A20: 2 | B20: Nyaung Pin Thar(VT) | C20: 3707 | D20: 1702 | E20: 2005
A21: 3 | B21: Ket Thar(VT) | C21: 5503 | D21: 2612 | E21: 2891
A22: 4 | B22: Laung Min(VT) | C22: 1848 | D22: 912 | E22: 936
A23: 5 | B23: Nan Khan(VT) | C23: 1334 | D23: 708 | E23: 626
A24: 6 | B24: Naung San Kyin(VT) | C24: 3613 | D24: 1772 | E24: 1841
A25: 7 | B25: Kho Taung(VT) | C25: 2760 | D25: 1327 | E25: 1433
A26: 8 | B26: Myin Thar(VT)) | C26: 4910 | D26: 2298 | E26: 2612
A27: 9 | B27: Auk Hman Kin(VT) | C27: 2456 | D27: 1151 | E27: 1305
A28: 10 | B28: Naung Po Aung(VT) | C28: 7549 | D28: 3561 | E28: 3988
A29: 11 | B29: Hlwa Zin Kone(VT) | C29: 1282 | D29: 620 | E29: 662
A30: 12 | B30: Sat Ka Yar(VT) | C30: 2083 | D30: 973 | E30: 1110
... A94: 76 | B94: Hmaing Taung(VT) | C94: 1556 | D94: 763 | E94: 793

Sheet Leshi
A1: Sagaing Region, Hkamti District , Leshi Township
E2: 29-3-2014
A5: Sr | B5: Ward/Village Tract | C5: Population
C6: Total | D6: Male | E6: Female
B7: Total | C7: =C9+C12 -> 9061 | D7: =D9+D12 -> 4491 | E7: =E9+E12 -> 4570
B9: Ward | C9: =SUM(C10:C11) -> 1705 | D9: =SUM(D10:D11) -> 885 | E9: =SUM(E10:E11) -> 820
A10: 1 | B10: Myo Ma(W) | C10: 484 | D10: 292 | E10: 192
A11: 2 | B11: Ah Hmu Htan(W) | C11: 1221 | D11: 593 | E11: 628
B12: Village Tract | C12: =SUM(C13:C24) -> 7356 | D12: =SUM(D13:D24) -> 3606 | E12: =SUM(E13:E24) -> 3750
A13: 1 | B13: Ma Thaw Ri(VT) | C13: 379 | D13: 202 | E13: 177
A14: 2 | B14: Raw Par Mee(VT) | C14: 295 | D14: 158 | E14: 137
A15: 3 | B15: Wan Be(VT) | C15: 356 | D15: 177 | E15: 179
A16: 4 | B16: Htaing HpaingYan(VT) | C16: 782 | D16: 377 | E16: 405
A17: 5 | B17: Hlan Hlaing Hla(VT) | C17: 630 | D17: 337 | E17: 293
A18: 6 | B18: Dein Ka Lein(VT) | C18: 853 | D18: 433 | E18: 420
A19: 7 | B19: Chei Yar(VT) | C19: 207 | D19: 110 | E19: 97
A20: 8 | B20: Yan Nway(VT) | C20: 959 | D20: 489 | E20: 470
A21: 9 | B21: Lay Tein(VT) | C21: 241 | D21: 125 | E21: 116
A22: 10 | B22: Ku Kee(VT) | C22: 1723 | D22: 747 | E22: 976
A23: 11 | B23: Na Mi Yu Pi(VT) | C23: 422 | D23: 207 | E23: 215
A24: 12 | B24: Hpway Lin(VT) | C24: 509 | D24: 244 | E24: 265

Sheet Lahe
A1: Sagaing Region, Hkamti District , Lahe Township
E2: 29-3-2014
A5: Sr | B5: Ward/Village Tract | C5: Population
C6: Total | D6: Male | E6: Female
B7: Total | C7: =C9+C14 -> 43191 | D7: =D9+D14 -> 21443 | E7: =E9+E14 -> 21748
B9: Ward | C9: =SUM(C10:C13) -> 3141 | D9: =SUM(D10:D13) -> 1700 | E9: =SUM(E10:E13) -> 1441
A10: 1 | B10: Lahe Ywar Ma(W) | C10: 781 | D10: 389 | E10: 392
A11: 2 | B11: Ah Hmu Htan Myar(W) | C11: 1549 | D11: 875 | E11: 674
A12: 3 | B12: No (1) Toe Chea(W) | C12: 420 | D12: 238 | E12: 182
A13: 4 | B13: No (2) Toe Chea(W) | C13: 391 | D13: 198 | E13: 193
B14: Village Tract | C14: =SUM(C15:C45) -> 40050 | D14: =SUM(D15:D45) -> 19743 | E14: =SUM(E15:E45) -> 20307
A15: 1 | B15: Kar Mway Law Ri(VT) | C15: 7477 | D15: 3796 | E15: 3681
A16: 2 | B16: Yan Kyone(VT) | C16: 4145 | D16: 2082 | E16: 2063
A17: 3 | B17: Nauk Nyu Khar San(VT) | C17: 986 | D17: 448 | E17: 538
A18: 4 | B18: Kar Yaw Nauk Nyo(VT) | C18: 1737 | D18: 877 | E18: 860
A19: 5 | B19: Htan Khaw Nauk Kone(VT) | C19: 1255 | D19: 591 | E19: 664
A20: 6 | B20: Khan Ma Lar(VT) | C20: 1457 | D20: 704 | E20: 753
A21: 7 | B21: Maw Hpun Nauk Inn(VT) | C21: 762 | D21: 353 | E21: 409
A22: 8 | B22: Ant Paw(VT) | C22: 501 | D22: 247 | E22: 254
A23: 9 | B23: Yan Kyein(VT) | C23: 2921 | D23: 1470 | E23: 1451
A24: 10 | B24: Law Nauk Kone(VT) | C24: 1051 | D24: 518 | E24: 533
A25: 11 | B25: Tway Htway Nauk Kone(VT) | C25: 673 | D25: 345 | E25: 328
A26: 12 | B26: La Kyan(VT) | C26: 659 | D26: 338 | E26: 321
... A45: 31 | B45: Lan Khin(VT) | C45: 795 | D45: 387 | E45: 408

Sheet Nanyun
A1: Sagaing Region, Hkamti District , Nanyun Township
E2: 29-3-2014
A5: Sr | B5: Ward/Village Tract | C5: Population
C6: Total | D6: Male | E6: Female
B7: Total | C7: =C9+C13 -> 10514 | D7: =D9+D13 -> 5794 | E7: =E9+E13 -> 4720
B9: Ward | C9: =SUM(C10:C12) -> 2444 | D9: =SUM(D10:D12) -> 1396 | E9: =SUM(E10:E12) -> 1048
A10: 1 | B10: Sha Ra(W) | C10: 1055 | D10: 640 | E10: 415
A11: 2 | B11: Myo Ma(W) | C11: 1118 | D11: 611 | E11: 507
A12: 3 | B12: Raw Kaw(W) | C12: 271 | D12: 145 | E12: 126
B13: Village Tract | C13: =SUM(C14:C29) -> 8070 | D13: =SUM(D14:D29) -> 4398 | E13: =SUM(E14:E29) -> 3672
A14: 1 | B14: Pi Naung Sut(VT) | C14: 1000 | D14: 501 | E14: 499
A15: 2 | B15: Kye Tha Yauk(Sun Par)(VT) | C15: 507 | D15: 271 | E15: 236
A16: 3 | B16: Tha Man Chaung Son(VT) | C16: 283 | D16: 147 | E16: 136
A17: 4 | B17: Kyaing Raing(VT) | C17: 269 | D17: 146 | E17: 123
A18: 5 | B18: Yaung Ngway(VT) | C18: 152 | D18: 69 | E18: 83
A19: 6 | B19: Har War(VT) | C19: 461 | D19: 231 | E19: 230
A20: 7 | B20: Lar Khu (1)(VT) | C20: 70 | D20: 34 | E20: 36
A21: 8 | B21: Ga Gaw Ka Bar(VT) | C21: 3201 | D21: 1893 | E21: 1308
A22: 9 | B22: Thar Man(VT) | C22: 150 | D22: 86 | E22: 64
A23: 10 | B23: Lein Hnoke (1)(VT) | C23: 151 | D23: 81 | E23: 70
A24: 11 | B24: Ah Htet Lu Lun(VT) | C24: 344 | D24: 187 | E24: 157
A25: 12 | B25: Hpar Kyet(VT) | C25: 463 | D25: 244 | E25: 219
... A29: 16 | B29: Chammakauntlonekaung(VT) | C29: 445 | D29: 219 | E29: 226

Sheet Mobaingluk(S)
A1: Sagaing Region, Hkamti District , Mobaingluk Sub-Township
E2: 29-3-2014
A5: Sr | B5: Ward/Village Tract | C5: Population
C6: Total | D6: Male | E6: Female
B7: Total | C7: =SUM(C9+C12) -> 1430 | D7: =SUM(D9+D12) -> 713 | E7: =SUM(E9+E12) -> 717
B9: Ward | C9: =SUM(C10:C11) -> 987 | D9: =SUM(D10:D11) -> 497 | E9: =SUM(E10:E11) -> 490
A10: 1 | B10: No (1)(W) | C10: 595 | D10: 276 | E10: 319
A11: 2 | B11: No (2)(W) | C11: 392 | D11: 221 | E11: 171
B12: Village Tract | C12: =SUM(C13:C15) -> 443 | D12: =SUM(D13:D15) -> 216 | E12: =SUM(E13:E15) -> 227
A13: 1 | B13: Maw Nwan(VT) | C13: 201 | D13: 98 | E13: 103
A14: 2 | B14: Hpaing Lin Kut(VT) | C14: 110 | D14: 57 | E14: 53
A15: 3 | B15: Dan Sa Ku(VT) | C15: 132 | D15: 61 | E15: 71

Sheet Sonemara(S)
A1: Sagaing Region, Hkamti District , Sonemara Sub-Township
E2: 29-3-2014
